Workbook

Sheet 摘要
A1: 三電系統 訂閱制 × BOM 分析｜結論摘要（數字全部連動模型）
A2: 達方 E-mobility 三電系統（電池／馬達／電控）產品定義與商業模式評估｜基準日 2026-09-21｜非投資建議
A4: 指標 | B4: A 都會 Hub | C4: B 自研中置 | D4: C 外購高階
A5: 三電系統總成本 NT$/套 | B5: =BOM分析!$B$36 -> 13622.88 | C5: =BOM分析!$C$36 -> 16801.65 | D5: =BOM分析!$D$36 -> 36551.465
A6: 對 OEM 目標售價 NT$/套 | B6: =BOM分析!$B$37 -> 18920.667 | C6: =BOM分析!$C$37 -> 23335.625 | D6: =BOM分析!$D$37 -> 50765.924
A7: 目標售價 US$/套 | B7: =BOM分析!$B$38 -> 610.34409 | C7: =BOM分析!$C$38 -> 752.7621 | D7: =BOM分析!$D$38 -> 1637.6104
A8: 市場對照 OEM 價 NT$/套 | B8: =BOM分析!$B$39 -> 8680 | C8: =BOM分析!$C$39 -> 15190 | D8: =BOM分析!$D$39 -> 33120
A9: 電池佔系統成本 | B9: =BOM分析!$B$21/BOM分析!$B$36 -> 0.24003735 | C9: =BOM分析!$C$21/BOM分析!$C$36 -> 0.27259228 | D9: =BOM分析!$D$21/BOM分析!$D$36 -> 0.36441768
A10: 馬達佔系統成本 | B10: =BOM分析!$B$13/BOM分析!$B$36 -> 0.20605041 | C10: =BOM分析!$C$13/BOM分析!$C$36 -> 0.29878018 | D10: =BOM分析!$D$13/BOM分析!$D$36 -> 0.39396506
A12: 商業模式（架構 B） | B12: 期間收入 NT$/套 | C12: 期間毛利 NT$/套 | D12: vs M0 毛利 | E12: 前期資本占用 NT$/套
A13: =訂閱模式!$A$69 -> M0 一次性銷售 | B13: =訂閱模式!$B$69 -> 23335.625 | C13: =訂閱模式!$C$69 -> 7133.975 | D13: =訂閱模式!$D$69 -> 1 | E13: =訂閱模式!$E$69 -> 0
A14: =訂閱模式!$A$70 -> M1 軟體訂閱 | B14: =訂閱模式!$B$70 -> 24487.337 | C14: =訂閱模式!$C$70 -> 7352.9302 | D14: =訂閱模式!$D$70 -> 1.0306919 | E14: =訂閱模式!$E$70 -> 1104
A15: =訂閱模式!$A$71 -> M2 電池訂閱 | B15: =訂閱模式!$B$71 -> 39326.194 | C15: =訂閱模式!$C$71 -> 19665.593 | D15: =訂閱模式!$D$71 -> 2.7566109 | E15: =訂閱模式!$E$71 -> 4580
A16: =訂閱模式!$A$72 -> M3 硬體租賃 | B16: =訂閱模式!$B$72 -> 32400 | C16: =訂閱模式!$C$72 -> 9622.3995 | D16: =訂閱模式!$D$72 -> 1.3488132 | E16: =訂閱模式!$E$72 -> 16801.65
A18: 關鍵讀法
A19: 1. 電池與馬達合計約六成系統成本，電芯 NT$/Wh 是 BOM 最敏感變數；『採用電芯來源』開關可切換進口/中系電芯。架構 A 以 BESV 現有採購價計算高出中系對照一倍，低價段必須經蘇州平台重新議價或整包外購。
A20: 2. 自研中置馬達的價值不在省成本（vs Bafang MAX 外購差額有限），而在把控制器、扭力感測、CAN 與 IoT 整合進驅動單元，取得訂閱制所需的資料入口。
A21: 3. M1 只有在 IoT 硬體隨售價轉嫁（Bosch ConnectModule 模式）時才是正貢獻，達方自行吸收則需轉換率 >40%；M2/M3 毛利倍數高但把達方變成資產持有者，需融資夥伴、逆物流與通路（GROFA）或車隊客戶。
A22: 4. 建議路徑：架構 B + IoT 標配 → M1 先行（品牌車 BESV/Mondraker/GROFA 通路），M3 針對歐洲 cargo/外送車隊試點，M2 待電池法規（2027 電池護照）與殘值市場成熟後再推。

Sheet 假設
A1: 三電系統 訂閱制 × BOM 分析模型｜全域假設
A2: 圖例：藍字＝可修改輸入；黑字＝公式；綠字＝跨表連結；黃底＝關鍵假設。金額單位 NT$，日期基準 2026-09-21。
A4: 參數 | B4: 數值 | C4: 單位 | D4: 說明 / 來源
A5: USD/NTD 匯率 | B5: 31 | C5: NT$/US$ | D5: 假設值（2026-09 附近匯率，請依財務部月結匯率更新）
A6: EUR/NTD 匯率 | B6: 36 | C6: NT$/€ | D6: 假設值（同上）
A7: 年產量（套） | B7: 10000 | C7: 套/年 | D7: 情境假設：第一階段三電系統年出貨量，用於認證/模具攤提
A8: 製造轉換成本率（組裝+測試） | B8: 0.08 | C8: % of 材料 | D8: 假設：蘇州/越南輕組裝，材料成本的 8%
A9: 報廢與良率損失率 | B9: 0.015 | C9: % of 材料 | D9: 假設
A10: 認證+模具一次性費用 | B10: 9000000 | C10: NT$ | D10: 假設：EN 15194 / UN38.3 / UL 2849 / CE-EMC + 馬達壓鑄與電池外殼模具，合計約 NT$9M
A11: 認證攤提年限 | B11: 3 | C11: 年 | D11: 假設
A12: 目標系統毛利率（對 OEM 售價） | B12: 0.28 | C12: % | D12: 假設：8/28 會議 Andy 要求「15% 或 12% 以上、比市場好才做」；三電系統設 28%（八方 2024 毛利率約 25–30% 區間）
A13: 資金成本（WACC / 訂閱折現率） | B13: 0.07 | C13: %/年 | D13: 假設
A14: 21700 電芯單價（進口／台系） | B14: 4 | C14: NT$/Wh | D14: 外部基準：見『外部基準』表
A15: 21700 電芯單價（中系） | B15: 2.8 | C15: NT$/Wh | D15: 外部基準：見『外部基準』表
A16: 採用電芯來源（1=進口，2=中系） | B16: 1 | C16: 選項 | D16: 切換電池 BOM 的電芯單價

Sheet 內部成本錨點
A1: BESV / 達方 E-mobility 內部零件單位成本錨點（NT$）
A2: 來源：確認呆料list-20260630.xlsx（BESV 2026/06 庫存單位成本；含舊世代與小量採購價，屬保守偏高之錨點，非最新量產報價）
A4: 類別 | B4: 品項（庫存描述節錄） | C4: 單位成本 NT$ | D4: 庫存量 | E4: 模型用途
A5: 中置馬達 | B5: Shimano STEPS E8000 (KDUE8000M) 250W 中置馬達 | C5: 14640 | D5: 1 | E5: 高階外購中置馬達成本上限
A6: 中置馬達 | B6: Bafang MAX Drive 250W 中置馬達 (8FUN) | C6: 8473 | D6: 7 | E6: 架構 B 外購中置馬達對照
A7: 輪轂馬達 | B7: AKM 後輪齒輪輪轂馬達 250W（卡式飛輪） | C7: 2807 | D7: 48 | E7: 架構 A 馬達
A8: 輪轂馬達 | B8: AKM 前輪齒輪輪轂馬達 250W（達方外殼） | C8: 2428 | D8: 43 | E8: 架構 A 馬達下限
A9: 輪轂馬達 | B9: Bafang 前輪齒輪輪轂 250W 含溫度感測 | C9: 2044 | D9: 202 | E9: 架構 A 馬達下限
A10: 電池 | B10: Shimano BT-E8010 36V 504Wh | C10: 8967 | D10: 2 | E10: 高階外購電池對照
A11: 電池 | B11: Darfon 720Wh 電池組（含握把）E4C0G | C11: 7428 | D11: 4 | E11: 架構 B 電池（自製）
A12: 電池 | B12: Darfon 630Wh 電池組（含握把） | C12: 6483 | D12: 5 | E12: 架構 B 電池（自製）
A13: 電池 | B13: Battery pack E4C0E-001（主力量產型） | C13: 4951 | D13: 1146 | E13: 架構 A 電池
A14: 電池 | B14: 36V 11.2Ah 403Wh 電池組 | C14: 3902 | D14: 3 | E14: 架構 A 電池下限
A15: 控制器 | B15: Controller cartridge 3G 版（RPM/扭力；達方自製） | C15: 2577 | D15: 309 | E15: 含通訊模組之控制器上限
A16: 控制器 | B16: Controller YCDT03 25km/h EU | C16: 2050 | D16: 146 | E16: 架構 A/B 分離式控制器
... A31: 充電器 | B31: 充電器電源板 B240-003 | C31: 978 | D31: 1603 | E31: 架構 B 4A 充電器基礎

Sheet 外部基準
A1: 外部市場基準（訂閱定價、系統售價、電芯成本）
A2: 藍字為輸入；每筆附來源。零售替換價為 OEM 價之上限，一般 OEM 採購價約為零售價 40–55%。
A4: 項目 | B4: 數值 | C4: 單位 | D4: 換算 NT$ | E4: 來源 / 備註
A5: Bosch CX 驅動單元 OEM 估價 | B5: 400 | C5: € | D5: =B5*假設!$B$6 -> 14400 | E5: 估計：零售替換價 US$1,027–1,051（Propel Bikes, smart system BDU3741）、二手 €480；OEM 移轉價通常為零售 40–60% → 取 €400。待驗證。
A6: Bosch PowerTube 800 OEM 估價 | B6: 370 | C6: € | D6: =B6*假設!$B$6 -> 13320 | E6: 估計：零售 €668.90（Bike-Discount, BBP3880 800Wh）、US$1,198–1,334；OEM 取零售 55%。
A7: Bosch Kiox 300 + LED Remote OEM 估價 | B7: 75 | C7: € | D7: =B7*假設!$B$6 -> 2700 | E7: 估計：Kiox 300 零售 €123.5（Bike24）、Purion 200 €110；加 LED Remote，OEM 取約 55%。
A8: Bosch ConnectModule OEM 估價 | B8: 45 | C8: € | D8: =B8*假設!$B$6 -> 1620 | E8: 估計：零售 €81.5（Bike24 套件）–€139（原廠加裝）；OEM 取約 45。內含 LTE/GPS/BLE。
A9: Bosch 4A 充電器 OEM 估價 | B9: 30 | C9: € | D9: =B9*假設!$B$6 -> 1080 | E9: 估計：原廠 4A 充電器零售約 €99；Alibaba 42V 2A 充電器批發 US$6.5–11。
A10: Bosch CX 全系統 OEM 估價 | B10: 920 | C10: € | D10: =B10*假設!$B$6 -> 33120 | E10: ＝DU 400 + PT800 370 + Kiox/Remote 75 + ConnectModule 45 + 充電器 30。對照零售替換總值 €1,500–2,300。
A11: Bafang M600 中置系統套件 OEM 估價 | B11: 490 | C11: US$ | D11: =B11*假設!$B$5 -> 15190 | E11: 估計：M600 裸馬達零售 US$700–899（Biktrix）、整套件 Alibaba <US$800；OEM 馬達+控制+顯示約 US$300 + 720Wh 電池 FOB 約 US$170 + 充電器 US$10 + 線束。Bafang 2025 中置出貨 17.04 萬台、e-bike 馬達毛利率 35.5%。
A12: Bafang H700 輪轂系統套件 OEM 估價 | B12: 280 | C12: US$ | D12: =B12*假設!$B$5 -> 8680 | E12: 估計：Bafang/安乃達齒輪輪轂 ASP 約 RMB 230–335（US$32–47）、通用 250W 輪轂 Alibaba 約 US$55；套件（控制器/顯示/感測）約 US$60；500Wh 電池 FOB 約 US$150；充電器 US$10。
A13: Bosch Flow+ 年費 | B13: 39.99 | C13: € | D13: =B13*假設!$B$6 -> 1439.64 | E13: Bosch 官網：€4.99/月或 €39.99/年（美國 US$5.99/月或 US$59.99/年）；ConnectModule 車款首年免費。Bosch 未揭露訂戶數與轉換率。
A14: e-bike 電池訂閱月費（假設） | B14: 19.9 | C14: € | D14: =B14*假設!$B$6 -> 716.4 | E14: 假設：Enyring（Yamaha，柏林/阿姆斯特丹）月費未公布；介於 Gogoro 單電池 NT$499/月（≈€14）與 Swapfiets 整車 Power 1 €49.90/月之間。
A15: DJI Avinox 800Wh 電池零售價 | B15: 999 | C15: CHF | E15: Intercycle 零售 CHF 999（約 €1,060）；600Wh US$869。Avinox M2 峰值 1,500W/150Nm，MY2027 逾 60 品牌採用。
A16: Shimano EP801 驅動單元零售價 | B16: 850 | C16: £ | E16: 英國經銷替換價 £700–1,000；美國定價 US$1,300–1,700、灰市 US$700–900。BT-EN806 630Wh 清倉價 €286–303。
A17: Samsung 50S 21700 電芯（客製包量產價） | B17: 0.1 | C17: US$/Wh | D17: =B17*假設!$B$5 -> 3.1 | E17: Alibaba 客製電池：US$1.45–2.20/顆（18Wh）＝US$0.08–0.12/Wh；中系 50E 級小批 US$1.98–3.50/顆。BNEF 2025 車用電芯均價 US$79/kWh、電池包 US$108/kWh。
A18: 720Wh 電池包 FOB 估價（Tier-1 電芯） | B18: 170 | C18: US$ | D18: =B18*假設!$B$5 -> 5270 | E18: 研究推估：電芯 US$85–115 + BMS 12–35 + 外殼/滑軌/鎖 15–40 + 組裝測試 10–20 ＝ US$130–210；電芯佔 55–65%。
A19: 250W/85Nm 中置馬達出廠成本估價 | B19: 135 | C19: US$ | D19: =B19*假設!$B$5 -> 4185 | E19: 研究推估 US$80–190：磁鋼 6–18、銅線 7–12、矽鋼 4–8、齒輪/軸承/離合 15–35、壓鑄殼 12–25、扭力感測 8–25、驅動板 12–25、組測 10–20。安乃達中置毛利率約 50%。
A20: NdFeB 燒結磁鋼價格 | B20: 92 | C20: US$/kg | D20: =B20*假設!$B$5 -> 2852 | E20: 2026 工業級 US$65–120/kg，N52/SH/UH US$130–175/kg；NdPr 氧化物 Q2-2026 約 US$123–126/kg（2022 以來最高）。含 Dy/Tb 磁鋼需中國出口許可（2025/4 起）。
A21: 2.4 吋 TFT CAN 顯示器（Alibaba） | B21: 42 | C21: US$ | D21: =B21*假設!$B$5 -> 1302 | E21: US$39–45（Bafang 相容）；單色 LCD 零售 US$24–54。
A22: 4G Cat.1 通訊模組（Quectel EC200S） | B22: 6.5 | C22: US$ | D22: =B22*假設!$B$5 -> 201.5 | E22: 1 萬顆以上 US$6.50；完整 4G+GPS 追蹤器零售 US$38。IoT 模組 BOM 推估 US$15–25。
A23: 中軸扭力感測器（中系批量） | B23: 28 | C23: US$ | D23: =B23*假設!$B$5 -> 868 | E23: US$15–40；NCTE/Thun 型售後約 US$150–160（達方 Thun 錨點 NT$4,576）。
A24: EN 15194 + EMC + 電池 新平台認證 | B24: 130000 | C24: US$ | D24: =B24*假設!$B$5 -> 4030000 | E24: US$80,000–180,000／新平台；沿用已認證電池可省 US$20–50k；UL 2849 每型 US$5–15k；UN38.3 每組 US$300–2,000。
A25: Swapfiets 2024 ARPM | B25: 341.41 | C25: €/年 | D25: =B25*假設!$B$6 -> 12290.76 | E25: 2024 營收 €91.1M（+7%）、成本 €61.1M（毛利率約 33%）、EBIT −€17.3M、淨損 €14.3M；會員 26.68 萬、e-bike 5.2 萬台；2026/5 併 Dance 後訂閱 e-bike >7.5 萬台。
A26: Swapfiets Power 7 月費（德國） | B26: 73 | C26: €/月 | D26: =B26*假設!$B$6 -> 2628 | E26: Power 1 €49.90–59.90/月；Power 7 €73（DE）–€109.90（巴黎）；失竊自付 €0–900、電池遺失 €175–500。
A27: Dance 2024 ARPU（推算） | B27: 59 | C27: €/月 | D27: =B27*假設!$B$6 -> 2124 | E27: 2024 營收 €8.0M（+29%）、EBITDA −€3.6M、>1.13 萬活躍用戶、77% 年約；定價 €69/月（促銷 €59）。
A28: Zoomo 美國 Flex 週租 | B28: 49 | C28: US$/週 | D28: =B28*假設!$B$5 -> 1519 | E28: 無合約、含維修耗材、失竊保障另計；澳洲 A$29–89/週。2023 兩度裁員求獲利。
A29: Gogoro 2025 換電 ARPU（推算） | B29: 19 | C29: US$/月 | D29: =B29*假設!$B$5 -> 589 | E29: 2025 換電營收 US$149.0M（+8.1%）、訂戶 66.5 萬、非 IFRS 毛利率 19.5%、Q2-26 毛利率 22.6%（五年新高）、淨損 US$80.8M；站點 >2,700、電池約 140 萬顆。方案 NT$499–1,199/月。
A30: Kymco Ionex 單電池最低月費 | B30: 188 | C30: NT$/月 | D30: =B30 -> 188 | E30: NT$188（63km）/221/421；雙電池 NT$518–2,018；2025/3 促銷 NT$498 吃到飽。
A31: 德國公司自行車租賃 2025 市場規模 | B31: 2.8 | C31: €十億 | E31: Deloitte／Zukunft Fahrrad：€2.8B（−4%）、新約約 72 萬、車隊 220 萬台、e-bike 佔 78%、平均租賃 e-bike €3,700 vs 市場均價 €2,550；JobRad 累計 200 萬台、2025 裁員 20%。
A32: Onomotion ONO cargo 月租 | B32: 589 | C32: €/月 | D32: =B32*假設!$B$6 -> 21204 | E32: 48 個月含貨箱與全服務（2022 上市價 €490）。Riese & Müller Business、Urban Arrow 提供車隊租賃但未公布價格。
A33: 歐洲 e-bike 失竊暴露率（GfK 2025） | B33: 0.13 | C33: % | E33: BE 16%、DE 13%、NL 11%（定義待驗證）；德國 2025 失竊 21.4 萬台、保險均賠 €1,270；荷蘭 2024 e-bike 失竊 7.3–11 萬台。
A34: 二手 e-bike 殘值（Upway） | B34: 0.45 | C34: % 折價 | E34: 第一年 −30–50%，之後每年 −10–20%；Upway 均價較新車低 45%；2025 年 Series C US$60M、銷量翻倍。
A35: 電池壽命（80% SoH） | B35: 1000 | C35: cycles | E35: Bosch smart system 經銷商稱 1,000 cycles 後 80%；ADAC 測試 1,515 cycles 至 30%；保固底線 Fazua 500 cycles/60%、Shimano 1,000 cycles/60%。
A36: EU 電池護照生效日 | B36: 20270218 | C36: 日期 | E36: EU 2023/1542：2027/2/18 起 LMT（≤25kg）電池須數位護照、可由專業人員更換；QR 碼三層存取。
A37: EU 對中國整車 AD+CVD | B37: 0.87 | C37: % 上限 | E37: AD 10.3–70.1% + CVD 3.9–17.2%，2025/1/25 起延長 5 年；中國馬達（8501）與鋰電池包（8507.60）不在範圍，MFN 約 1.8–2.7%；自行車零件反規避（60% 中國零件值）2025/10 延長。
A38: 美國 301 關稅：中國非車用鋰電池 | B38: 0.25 | C38: % | E38: 2026/1/1 起 7.5%→25%（+MFN 3.4%）；中國馬達 25%；中國整車 2026/7 約 35%（25% §301 + 10% §122）；台灣 15% all-in（2026/2 美台協議）；越南 20%。

Sheet BOM分析
A1: 三電系統 BOM 成本結構｜三種產品架構（NT$/套，年產 10,000 套）
A2: A＝都會/媽媽車 輪轂系統（外購馬達）；B＝自研中置系統 Cargo/e-MTB（馬達自製、電池達宇/自製）；C＝外購高階系統（Bosch CX 等級，OEM 估價）。
A4: BOM 項目 | B4: A 都會 Hub | C4: B 自研中置 | D4: C 外購高階 | E4: B 佔比 | F4: 依據 / 假設
A5: 1. 馬達（含減速機構） | E5: =IF($C$36=0,0,C5/$C$36) -> 0
A6: 釹鐵硼永磁 + 轉子 | C6: 420 | E6: =IF($C$36=0,0,C6/$C$36) -> 0.024997545 | F6: B：自製 PMSM；NdFeB 約 0.25kg，磁材價依外部基準
A7: 定子矽鋼片 + 銅線繞組 | C7: 700 | E7: =IF($C$36=0,0,C7/$C$36) -> 0.041662575 | F7: B：250W 連續／峰值 600–750W，85–90Nm
A8: 減速齒輪組（行星／二級）+ 軸承 + 離合 | C8: 850 | E8: =IF($C$36=0,0,C8/$C$36) -> 0.050590269 | F8: B：高扭矩塑鋼/鋼齒輪，離合單向軸承
A9: 鋁/鎂壓鑄外殼 + CNC + 塗裝 | C9: 750 | E9: =IF($C$36=0,0,C9/$C$36) -> 0.044638473 | F9: B：模具另列於認證+模具攤提
A10: 整合扭力感測器（中軸式） | C10: 900 | E10: =IF($C$36=0,0,C10/$C$36) -> 0.053566168 | F10: B：整合式；外購 Thun 為 NT$4,576、SR 為 NT$2,270（內部錨點）
A11: 驅動板（MCU + 三相 MOSFET + 閘極驅動 + CAN） | C11: 950 | E11: =IF($C$36=0,0,C11/$C$36) -> 0.056542066 | F11: B：整合於馬達殼內，取代分離式控制器；達方 controller cartridge 錨點 NT$1,126–2,577
A12: 組裝、測試、密封、配件 | C12: 450 | E12: =IF($C$36=0,0,C12/$C$36) -> 0.026783084 | F12: B：蘇州輕組裝；含 IP65 測試
A13: 馬達小計 | B13: =內部成本錨點!$C$7 -> 2807 | C13: =SUM(C6:C12) -> 5020 | D13: =外部基準!$D$5 -> 14400 | E13: =IF($C$36=0,0,C13/$C$36) -> 0.29878018 | F13: A：AKM 後輪轂錨點 NT$2,807；C：Bosch CX OEM 估價（零售價 × OEM 折扣）
A14: 對照：Bafang MAX Drive 外購價（內部錨點） | C14: =內部成本錨點!$C$6 -> 8473 | E14: =IF($C$36=0,0,C14/$C$36) -> 0.50429571 | F14: 自製 vs 外購差額 = B 自製節省空間
A15: 2. 電池組 | E15: =IF($C$36=0,0,C15/$C$36) -> 0
A16: 電池容量 (Wh) | B16: 500 | C16: 720 | D16: 800 | E16: =IF($C$36=0,0,C16/$C$36) -> 0.042852934 | F16: A：36V 13.9Ah；B：Darfon 720Wh 錨點；C：Bosch PowerTube 800
A17: 電芯（21700，依假設表選擇來源） | B17: =B16*IF(假設!$B$16=2,假設!$B$15,假設!$B$14) -> 2000 | C17: =C16*IF(假設!$B$16=2,假設!$B$15,假設!$B$14) -> 2880 | E17: =IF($C$36=0,0,C17/$C$36) -> 0.17141174 | F17: 電芯 NT$/Wh × 容量；C 直接用外購整包價
A18: BMS（含均衡、CAN、防盜鎖定） | B18: 320 | C18: 420 | E18: =IF($C$36=0,0,C18/$C$36) -> 0.024997545 | F18: B：含 CAN 通訊與 SoH 回報，訂閱制電池必備
A19: 外殼、滑軌、連接器、鎖具、線材 | B19: 650 | C19: 900 | E19: =IF($C$36=0,0,C19/$C$36) -> 0.053566168 | F19: B：downtube 內置可拆式；EU 電池法規要求可移除/可更換
A20: 組裝、測試（UN38.3 抽測）、包裝 | B20: 300 | C20: 380 | E20: =IF($C$36=0,0,C20/$C$36) -> 0.022616826
A21: 電池小計 | B21: =SUM(B17:B20) -> 3270 | C21: =SUM(C17:C20) -> 4580 | D21: =外部基準!$D$6 -> 13320 | E21: =IF($C$36=0,0,C21/$C$36) -> 0.27259228 | F21: 驗證：Darfon 720Wh 內部錨點 NT$7,428、E4C0E 主力電池 NT$4,951
A22: 對照：Darfon 720Wh / E4C0E 內部錨點 | B22: =內部成本錨點!$C$13 -> 4951 | C22: =內部成本錨點!$C$11 -> 7428 | D22: =內部成本錨點!$C$10 -> 8967 | E22: =IF($C$36=0,0,C22/$C$36) -> 0.44209944 | F22: C 欄對照為 Shimano 504Wh 外購價（僅 504Wh）
A23: 3. 電控、HMI、感測與連網 | E23: =IF($C$36=0,0,C23/$C$36) -> 0
A24: 分離式控制器 | B24: =內部成本錨點!$C$17 -> 1126 | C24: 0 | D24: 0 | E24: =IF($C$36=0,0,C24/$C$36) -> 0 | F24: A：YTMT02 錨點；B/C 已整合於驅動單元
A25: HMI 顯示器 + 把手遙控 | B25: =內部成本錨點!$C$20+150 -> 684 | C25: =內部成本錨點!$C$19+200 -> 1364 | D25: =外部基準!$D$7 -> 2700 | E25: =IF($C$36=0,0,C25/$C$36) -> 0.081182503 | F25: A：LCM；B：TFT；C：Kiox 300 + LED remote
A26: 扭力感測器（分離式） | B26: =內部成本錨點!$C$23 -> 1800 | C26: 0 | D26: 0 | E26: =IF($C$36=0,0,C26/$C$36) -> 0 | F26: A：中軸式；B/C 已整合
A27: 速度感測器 + 煞車感測 ×2 | B27: =內部成本錨點!$C$24+2*內部成本錨點!$C$25 -> 510 | C27: =內部成本錨點!$C$24+2*內部成本錨點!$C$25 -> 510 | D27: =內部成本錨點!$C$24+2*內部成本錨點!$C$25 -> 510 | E27: =IF($C$36=0,0,C27/$C$36) -> 0.030354162 | F27: 內部錨點
A28: IoT 連網模組（BLE + LTE-M/GSM + GPS） | B28: =內部成本錨點!$C$27 -> 804 | C28: =內部成本錨點!$C$27+300 -> 1104 | D28: =外部基準!$D$8 -> 1620 | E28: =IF($C$36=0,0,C28/$C$36) -> 0.065707832 | F28: 訂閱制之硬體前提；B 加 GNSS；C 為 Bosch ConnectModule
A29: 主線束 + 電源座 | B29: =內部成本錨點!$C$29 -> 771 | C29: =內部成本錨點!$C$28 -> 1264 | D29: =內部成本錨點!$C$28 -> 1264 | E29: =IF($C$36=0,0,C29/$C$36) -> 0.075230707 | F29: 內部錨點
A30: 充電器（2A / 4A） | B30: =內部成本錨點!$C$30 -> 532 | C30: =內部成本錨點!$C$31+250 -> 1228 | D30: =外部基準!$D$9 -> 1080 | E30: =IF($C$36=0,0,C30/$C$36) -> 0.07308806 | F30: B：4A 電源板 + 外殼
A31: 電控/HMI/感測/連網小計 | B31: =SUM(B24:B30) -> 6227 | C31: =SUM(C24:C30) -> 5470 | D31: =SUM(D24:D30) -> 7174 | E31: =IF($C$36=0,0,C31/$C$36) -> 0.32556326
A32: 4. 成本彙總 | E32: =IF($C$36=0,0,C32/$C$36) -> 0
A33: 材料成本合計 | B33: =B13+B21+B31 -> 12304 | C33: =C13+C21+C31 -> 15070 | D33: =D13+D21+D31 -> 34894 | E33: =IF($C$36=0,0,C33/$C$36) -> 0.89693572
A34: 製造轉換 + 報廢 | B34: =B33*(假設!$B$8+假設!$B$9) -> 1168.88 | C34: =C33*(假設!$B$8+假設!$B$9) -> 1431.65 | D34: =D33*(假設!$B$8+假設!$B$9)*0.5 -> 1657.465 | E34: =IF($C$36=0,0,C34/$C$36) -> 0.085208893 | F34: C 外購整套僅需系統整合測試，轉換率減半
A35: 認證 + 模具攤提（每套） | B35: =假設!$B$10/假設!$B$11/假設!$B$7*0.5 -> 150 | C35: =假設!$B$10/假設!$B$11/假設!$B$7 -> 300 | D35: 0 | E35: =IF($C$36=0,0,C35/$C$36) -> 0.017855389 | F35: A 共用一半模具；C 由供應商承擔
A36: 三電系統總成本（每套） | B36: =SUM(B33:B35) -> 13622.88 | C36: =SUM(C33:C35) -> 16801.65 | D36: =SUM(D33:D35) -> 36551.465 | E36: =IF($C$36=0,0,C36/$C$36) -> 1
A37: 對 OEM 目標售價（依目標毛利率） | B37: =B36/(1-假設!$B$12) -> 18920.667 | C37: =C36/(1-假設!$B$12) -> 23335.625 | D37: =D36/(1-假設!$B$12) -> 50765.924 | E37: =IF($C$40=0,0,C37/$C$40) -> 43516.384 | F37: 假設表毛利率
A38: 目標售價 (US$) | B38: =B37/假設!$B$5 -> 610.34409 | C38: =C37/假設!$B$5 -> 752.7621 | D38: =D37/假設!$B$5 -> 1637.6104 | E38: =IF($C$40=0,0,C38/$C$40) -> 1403.7543
A39: 市場對照：同級系統 OEM 價（外部基準） | B39: =外部基準!$D$12 -> 8680 | C39: =外部基準!$D$11 -> 15190 | D39: =外部基準!$D$10 -> 33120 | E39: =IF($C$40=0,0,C39/$C$40) -> 28326.384 | F39: A：Bafang H 系列輪轂套件；B：Bafang M600 中置套件；C：Bosch CX 全系統
A40: 本案售價 vs 市場對照 | B40: =IF(B39=0,0,B37/B39-1) -> 1.1798003 | C40: =IF(C39=0,0,C37/C39-1) -> 0.53624918 | D40: =IF(D39=0,0,D37/D39-1) -> 0.53278755 | E40: =IF($C$40=0,0,C40/$C$40) -> 1 | F40: 正值＝本案售價高於市場對照（需靠整合/訂閱價值支撐）
A41: 三電系統佔整車 BOM 比重（整車 BOM 假設） | B41: =B36/22000 -> 0.61922182 | C41: =C36/45000 -> 0.37337 | D41: =D36/80000 -> 0.45689331 | E41: =IF($C$40=0,0,C41/$C$40) -> 0.69626214 | F41: 整車 BOM 假設：A NT$22,000；B NT$45,000；C NT$80,000

Sheet 訂閱模式
A1: 三種訂閱模式 單位經濟（每套三電系統，NT$）
A2: M1 軟體/連網訂閱（Bosch Flow+ 型）｜M2 電池訂閱 BaaS（Enyring / Gogoro 型）｜M3 三電硬體租賃 HaaS（B2B 車隊 Zoomo 型）。與 M0 一次性銷售對照。
A4: M0｜一次性銷售（基準）
A5: 項目 | B5: 數值 | C5: 單位 | D5: 說明
A6: 系統成本（架構 B） | B6: =BOM分析!$C$36 -> 16801.65 | C6: NT$/套 | D6: 連結 BOM分析
A7: 對 OEM 售價 | B7: =BOM分析!$C$37 -> 23335.625 | C7: NT$/套 | D7: 連結 BOM分析
A8: ★毛利（每套，一次性） | B8: =$B$7-$B$6 -> 6533.975 | C8: NT$/套
A9: 售後零件與服務毛利（4 年累計） | B9: 600 | C9: NT$/套 | D9: 假設：保固外零件/服務；傳統 OEM 模式下多由通路取得
A10: ★4 年累計毛利 | B10: =$B$8+$B$9 -> 7133.975 | C10: NT$/套
A12: M1｜軟體 / 連網訂閱（Bosch Flow+ 型；隨系統出貨，選配訂閱）
A13: 項目 | B13: 數值 | C13: 單位 | D13: 說明
A14: 年費（含稅前） | B14: =外部基準!$D$13 -> 1439.64 | C14: NT$/年 | D14: 外部基準：Bosch Flow+ 年費 €39.99 換算
A15: 訂閱轉換率（出貨後啟用） | B15: 0.2 | C15: % | D15: 假設：連網 e-bike 付費轉換率；Bosch/Cowboy 未揭露，以 15–25% 情境
A16: 年流失率 | B16: 0.25 | C16: %/年 | D16: 假設
A17: 平均訂閱年數 | B17: =1/$B$16 -> 4 | C17: 年 | D17: ＝1/流失率
A18: App 商店/金流手續費 | B18: 0.15 | C18: % | D18: 假設：App Store/Google Play 15%（小型開發者費率）或自建金流 3%
A19: 電信 + 雲端 + 客服（每活躍用戶） | B19: 350 | C19: NT$/年 | D19: 假設：LTE-M 資費約 NT$150–250/年 + 雲端/客服
A20: IoT 模組增量 BOM（每套出貨，不論是否訂閱） | B20: =BOM分析!$C$28 -> 1104 | C20: NT$/套 | D20: 連結 BOM分析（若 IoT 模組已是標配，則此成本本就在 BOM 內）
A21: IoT 硬體成本隨系統售價轉嫁比例 | B21: 1 | C21: % | D21: 1＝IoT 模組如 Bosch ConnectModule 以售價轉嫁給 OEM/消費者；0＝達方自行吸收
A22: 軟體平台攤提基礎年量 | B22: 25000 | C22: 套/年 | D22: 假設：集團連網車年量（BESV + Mondraker 約 4 萬台 + GROFA 通路），平台共用
A23: 軟體開發/維護攤提（每套出貨） | B23: =12000000/$B$22 -> 480 | C23: NT$/套 | D23: 假設：年軟體團隊+雲端維運 NT$12,000,000／攤提年量
A24: ★每套出貨之訂閱 LTV（毛利） | B24: =$B$15*$B$17*($B$14*(1-$B$18)-$B$19) -> 698.9552 | C24: NT$/套 | D24: 轉換率 × 年數 ×（年費淨額 − 變動成本）
A25: ★每套淨增量毛利（扣 IoT 硬體與軟體攤提） | B25: =$B$24-(1-$B$21)*$B$20-$B$23 -> 218.9552 | C25: NT$/套
A26: ★損益兩平轉換率 | B26: =IF(($B$17*($B$14*(1-$B$18)-$B$19))=0,0,((1-$B$21)*$B$20+$B$23)/($B$17*($B$14*(1-$B$18)-$B$19))) -> 0.13734786 | C26: % | D26: 未轉嫁之 IoT + 軟體攤提 ÷ 單一訂戶終身毛利
A27: ★相對 M0 一次性毛利之增幅 | B27: =IF($B$8=0,0,$B$25/$B$8) -> 0.03351026 | C27: %
A29: M2｜電池訂閱 BaaS（電池不隨車售出，按月收費；含健康度保證與到期更換）
A30: 項目 | B30: 數值 | C30: 單位 | D30: 說明
A31: 電池成本（架構 B，720Wh） | B31: =BOM分析!$C$21 -> 4580 | C31: NT$/顆 | D31: 連結 BOM分析
A32: 月費 | B32: =外部基準!$D$14 -> 716.4 | C32: NT$/月 | D32: 外部基準：假設 €19.9/月換算（Enyring 未公布）；Gogoro NT$499–1,199/月、Ionex NT$188 起
A33: 通路分潤、金流與稅費（% of 月費） | B33: 0.35 | C33: % | D33: 假設：經銷商/通路 20–25% + VAT/金流 10–15%；達方實收 65%
A34: 車價折讓（不含電池售出，OEM 讓出電池售價） | B34: =$B$31/(1-假設!$B$12) -> 6361.1111 | C34: NT$/套 | D34: 電池不賣 → 系統售價下降此金額（電池成本/(1-毛利率)）
A35: 合約 + 續約平均使用月數 | B35: 48 | C35: 月 | D35: 假設：4 年（含續約）
A36: 電池壽命（循環） | B36: 800 | C36: cycles | D36: 外部基準：21700 NMC 80% SoH 約 600–1,000 cycles
A37: 年均充電循環 | B37: 150 | C37: cycles/年 | D37: 假設：通勤族每週 3 次
A38: 合約期內更換機率 | B38: =MIN(1,MAX(0,($B$35/12*$B$37-$B$36)/$B$36))+0.08 -> 0.08 | C38: % | D38: 超過壽命部分 + 8% 故障/意外更換
A39: 每月物流/檢測/客服 | B39: 60 | C39: NT$/月 | D39: 假設
A40: 到期殘值（二手/儲能再利用） | B40: 0.1 | C40: % of 成本 | D40: 假設
A41: 壞帳/流失損失率 | B41: 0.03 | C41: % of 收入 | D41: 假設
A42: ★合約期淨收入（達方實收） | B42: =$B$32*(1-$B$33)*$B$35 -> 22351.68 | C42: NT$
A43: ★合約期總成本 | B43: =$B$31*(1+$B$38)-$B$31*$B$40+$B$39*$B$35+$B$42*$B$41 -> 8038.9504 | C43: NT$ | D43: 電池 ×(1+更換率) − 殘值 + 月服務 + 壞帳
...

Sheet 敏感度
A1: 敏感度分析（公式即時連動）
A3: M2 電池訂閱 NPV（NT$）：月費（列）× 電池成本（欄）
A4: 月費 \ 電池成本 | B4: 4500 | C4: 5500 | D4: 6500 | E4: 7500 | F4: 8500
A5: 299 | B5: =-B$4+PV(假設!$B$13/12,訂閱模式!$B$35,-($A5*(1-訂閱模式!$B$33)*(1-訂閱模式!$B$41)-訂閱模式!$B$39))-PV(假設!$B$13/12,訂閱模式!$B$35,0,-(B$4*訂閱模式!$B$38-B$4*訂閱模式!$B$40)) -> 935.0761 | C5: =-C$4+PV(假設!$B$13/12,訂閱模式!$B$35,-($A5*(1-訂閱模式!$B$33)*(1-訂閱模式!$B$41)-訂閱模式!$B$39))-PV(假設!$B$13/12,訂閱模式!$B$35,0,-(C$4*訂閱模式!$B$38-C$4*訂閱模式!$B$40)) -> -49.795925 | D5: =-D$4+PV(假設!$B$13/12,訂閱模式!$B$35,-($A5*(1-訂閱模式!$B$33)*(1-訂閱模式!$B$41)-訂閱模式!$B$39))-PV(假設!$B$13/12,訂閱模式!$B$35,0,-(D$4*訂閱模式!$B$38-D$4*訂閱模式!$B$40)) -> -1034.6679 | E5: =-E$4+PV(假設!$B$13/12,訂閱模式!$B$35,-($A5*(1-訂閱模式!$B$33)*(1-訂閱模式!$B$41)-訂閱模式!$B$39))-PV(假設!$B$13/12,訂閱模式!$B$35,0,-(E$4*訂閱模式!$B$38-E$4*訂閱模式!$B$40)) -> -2019.54 | F5: =-F$4+PV(假設!$B$13/12,訂閱模式!$B$35,-($A5*(1-訂閱模式!$B$33)*(1-訂閱模式!$B$41)-訂閱模式!$B$39))-PV(假設!$B$13/12,訂閱模式!$B$35,0,-(F$4*訂閱模式!$B$38-F$4*訂閱模式!$B$40)) -> -3004.412
A6: 399 | B6: =-B$4+PV(假設!$B$13/12,訂閱模式!$B$35,-($A6*(1-訂閱模式!$B$33)*(1-訂閱模式!$B$41)-訂閱模式!$B$39))-PV(假設!$B$13/12,訂閱模式!$B$35,0,-(B$4*訂閱模式!$B$38-B$4*訂閱模式!$B$40)) -> 3568.0568 | C6: =-C$4+PV(假設!$B$13/12,訂閱模式!$B$35,-($A6*(1-訂閱模式!$B$33)*(1-訂閱模式!$B$41)-訂閱模式!$B$39))-PV(假設!$B$13/12,訂閱模式!$B$35,0,-(C$4*訂閱模式!$B$38-C$4*訂閱模式!$B$40)) -> 2583.1848 | D6: =-D$4+PV(假設!$B$13/12,訂閱模式!$B$35,-($A6*(1-訂閱模式!$B$33)*(1-訂閱模式!$B$41)-訂閱模式!$B$39))-PV(假設!$B$13/12,訂閱模式!$B$35,0,-(D$4*訂閱模式!$B$38-D$4*訂閱模式!$B$40)) -> 1598.3128 | E6: =-E$4+PV(假設!$B$13/12,訂閱模式!$B$35,-($A6*(1-訂閱模式!$B$33)*(1-訂閱模式!$B$41)-訂閱模式!$B$39))-PV(假設!$B$13/12,訂閱模式!$B$35,0,-(E$4*訂閱模式!$B$38-E$4*訂閱模式!$B$40)) -> 613.44073 | F6: =-F$4+PV(假設!$B$13/12,訂閱模式!$B$35,-($A6*(1-訂閱模式!$B$33)*(1-訂閱模式!$B$41)-訂閱模式!$B$39))-PV(假設!$B$13/12,訂閱模式!$B$35,0,-(F$4*訂閱模式!$B$38-F$4*訂閱模式!$B$40)) -> -371.4313
A7: 499 | B7: =-B$4+PV(假設!$B$13/12,訂閱模式!$B$35,-($A7*(1-訂閱模式!$B$33)*(1-訂閱模式!$B$41)-訂閱模式!$B$39))-PV(假設!$B$13/12,訂閱模式!$B$35,0,-(B$4*訂閱模式!$B$38-B$4*訂閱模式!$B$40)) -> 6201.0375 | C7: =-C$4+PV(假設!$B$13/12,訂閱模式!$B$35,-($A7*(1-訂閱模式!$B$33)*(1-訂閱模式!$B$41)-訂閱模式!$B$39))-PV(假設!$B$13/12,訂閱模式!$B$35,0,-(C$4*訂閱模式!$B$38-C$4*訂閱模式!$B$40)) -> 5216.1655 | D7: =-D$4+PV(假設!$B$13/12,訂閱模式!$B$35,-($A7*(1-訂閱模式!$B$33)*(1-訂閱模式!$B$41)-訂閱模式!$B$39))-PV(假設!$B$13/12,訂閱模式!$B$35,0,-(D$4*訂閱模式!$B$38-D$4*訂閱模式!$B$40)) -> 4231.2934 | E7: =-E$4+PV(假設!$B$13/12,訂閱模式!$B$35,-($A7*(1-訂閱模式!$B$33)*(1-訂閱模式!$B$41)-訂閱模式!$B$39))-PV(假設!$B$13/12,訂閱模式!$B$35,0,-(E$4*訂閱模式!$B$38-E$4*訂閱模式!$B$40)) -> 3246.4214 | F7: =-F$4+PV(假設!$B$13/12,訂閱模式!$B$35,-($A7*(1-訂閱模式!$B$33)*(1-訂閱模式!$B$41)-訂閱模式!$B$39))-PV(假設!$B$13/12,訂閱模式!$B$35,0,-(F$4*訂閱模式!$B$38-F$4*訂閱模式!$B$40)) -> 2261.5494
A8: 599 | B8: =-B$4+PV(假設!$B$13/12,訂閱模式!$B$35,-($A8*(1-訂閱模式!$B$33)*(1-訂閱模式!$B$41)-訂閱模式!$B$39))-PV(假設!$B$13/12,訂閱模式!$B$35,0,-(B$4*訂閱模式!$B$38-B$4*訂閱模式!$B$40)) -> 8834.0182 | C8: =-C$4+PV(假設!$B$13/12,訂閱模式!$B$35,-($A8*(1-訂閱模式!$B$33)*(1-訂閱模式!$B$41)-訂閱模式!$B$39))-PV(假設!$B$13/12,訂閱模式!$B$35,0,-(C$4*訂閱模式!$B$38-C$4*訂閱模式!$B$40)) -> 7849.1462 | D8: =-D$4+PV(假設!$B$13/12,訂閱模式!$B$35,-($A8*(1-訂閱模式!$B$33)*(1-訂閱模式!$B$41)-訂閱模式!$B$39))-PV(假設!$B$13/12,訂閱模式!$B$35,0,-(D$4*訂閱模式!$B$38-D$4*訂閱模式!$B$40)) -> 6864.2741 | E8: =-E$4+PV(假設!$B$13/12,訂閱模式!$B$35,-($A8*(1-訂閱模式!$B$33)*(1-訂閱模式!$B$41)-訂閱模式!$B$39))-PV(假設!$B$13/12,訂閱模式!$B$35,0,-(E$4*訂閱模式!$B$38-E$4*訂閱模式!$B$40)) -> 5879.4021 | F8: =-F$4+PV(假設!$B$13/12,訂閱模式!$B$35,-($A8*(1-訂閱模式!$B$33)*(1-訂閱模式!$B$41)-訂閱模式!$B$39))-PV(假設!$B$13/12,訂閱模式!$B$35,0,-(F$4*訂閱模式!$B$38-F$4*訂閱模式!$B$40)) -> 4894.5301
A9: 699 | B9: =-B$4+PV(假設!$B$13/12,訂閱模式!$B$35,-($A9*(1-訂閱模式!$B$33)*(1-訂閱模式!$B$41)-訂閱模式!$B$39))-PV(假設!$B$13/12,訂閱模式!$B$35,0,-(B$4*訂閱模式!$B$38-B$4*訂閱模式!$B$40)) -> 11466.999 | C9: =-C$4+PV(假設!$B$13/12,訂閱模式!$B$35,-($A9*(1-訂閱模式!$B$33)*(1-訂閱模式!$B$41)-訂閱模式!$B$39))-PV(假設!$B$13/12,訂閱模式!$B$35,0,-(C$4*訂閱模式!$B$38-C$4*訂閱模式!$B$40)) -> 10482.127 | D9: =-D$4+PV(假設!$B$13/12,訂閱模式!$B$35,-($A9*(1-訂閱模式!$B$33)*(1-訂閱模式!$B$41)-訂閱模式!$B$39))-PV(假設!$B$13/12,訂閱模式!$B$35,0,-(D$4*訂閱模式!$B$38-D$4*訂閱模式!$B$40)) -> 9497.2548 | E9: =-E$4+PV(假設!$B$13/12,訂閱模式!$B$35,-($A9*(1-訂閱模式!$B$33)*(1-訂閱模式!$B$41)-訂閱模式!$B$39))-PV(假設!$B$13/12,訂閱模式!$B$35,0,-(E$4*訂閱模式!$B$38-E$4*訂閱模式!$B$40)) -> 8512.3828 | F9: =-F$4+PV(假設!$B$13/12,訂閱模式!$B$35,-($A9*(1-訂閱模式!$B$33)*(1-訂閱模式!$B$41)-訂閱模式!$B$39))-PV(假設!$B$13/12,訂閱模式!$B$35,0,-(F$4*訂閱模式!$B$38-F$4*訂閱模式!$B$40)) -> 7527.5108
A10: 799 | B10: =-B$4+PV(假設!$B$13/12,訂閱模式!$B$35,-($A10*(1-訂閱模式!$B$33)*(1-訂閱模式!$B$41)-訂閱模式!$B$39))-PV(假設!$B$13/12,訂閱模式!$B$35,0,-(B$4*訂閱模式!$B$38-B$4*訂閱模式!$B$40)) -> 14099.98 | C10: =-C$4+PV(假設!$B$13/12,訂閱模式!$B$35,-($A10*(1-訂閱模式!$B$33)*(1-訂閱模式!$B$41)-訂閱模式!$B$39))-PV(假設!$B$13/12,訂閱模式!$B$35,0,-(C$4*訂閱模式!$B$38-C$4*訂閱模式!$B$40)) -> 13115.108 | D10: =-D$4+PV(假設!$B$13/12,訂閱模式!$B$35,-($A10*(1-訂閱模式!$B$33)*(1-訂閱模式!$B$41)-訂閱模式!$B$39))-PV(假設!$B$13/12,訂閱模式!$B$35,0,-(D$4*訂閱模式!$B$38-D$4*訂閱模式!$B$40)) -> 12130.236 | E10: =-E$4+PV(假設!$B$13/12,訂閱模式!$B$35,-($A10*(1-訂閱模式!$B$33)*(1-訂閱模式!$B$41)-訂閱模式!$B$39))-PV(假設!$B$13/12,訂閱模式!$B$35,0,-(E$4*訂閱模式!$B$38-E$4*訂閱模式!$B$40)) -> 11145.364 | F10: =-F$4+PV(假設!$B$13/12,訂閱模式!$B$35,-($A10*(1-訂閱模式!$B$33)*(1-訂閱模式!$B$41)-訂閱模式!$B$39))-PV(假設!$B$13/12,訂閱模式!$B$35,0,-(F$4*訂閱模式!$B$38-F$4*訂閱模式!$B$40)) -> 10160.491
A13: M3 硬體租賃 NPV（NT$）：月租（列）× 期末殘值（欄）
A14: 月租 \ 殘值 | B14: 0 | C14: 0.1 | D14: 0.15 | E14: 0.25 | F14: 0.35
A15: 800 | B15: =-訂閱模式!$B$52+PV(假設!$B$13/12,訂閱模式!$B$55,-($A15*(1-訂閱模式!$B$54)-訂閱模式!$B$56-訂閱模式!$B$52*訂閱模式!$B$57/12))+訂閱模式!$B$52*B$14/(1+假設!$B$13/12)^訂閱模式!$B$55 -> -5013.1551 | C15: =-訂閱模式!$B$52+PV(假設!$B$13/12,訂閱模式!$B$55,-($A15*(1-訂閱模式!$B$54)-訂閱模式!$B$56-訂閱模式!$B$52*訂閱模式!$B$57/12))+訂閱模式!$B$52*C$14/(1+假設!$B$13/12)^訂閱模式!$B$55 -> -3650.4086 | D15: =-訂閱模式!$B$52+PV(假設!$B$13/12,訂閱模式!$B$55,-($A15*(1-訂閱模式!$B$54)-訂閱模式!$B$56-訂閱模式!$B$52*訂閱模式!$B$57/12))+訂閱模式!$B$52*D$14/(1+假設!$B$13/12)^訂閱模式!$B$55 -> -2969.0354 | E15: =-訂閱模式!$B$52+PV(假設!$B$13/12,訂閱模式!$B$55,-($A15*(1-訂閱模式!$B$54)-訂閱模式!$B$56-訂閱模式!$B$52*訂閱模式!$B$57/12))+訂閱模式!$B$52*E$14/(1+假設!$B$13/12)^訂閱模式!$B$55 -> -1606.2889 | F15: =-訂閱模式!$B$52+PV(假設!$B$13/12,訂閱模式!$B$55,-($A15*(1-訂閱模式!$B$54)-訂閱模式!$B$56-訂閱模式!$B$52*訂閱模式!$B$57/12))+訂閱模式!$B$52*F$14/(1+假設!$B$13/12)^訂閱模式!$B$55 -> -243.5424
A16: 1000 | B16: =-訂閱模式!$B$52+PV(假設!$B$13/12,訂閱模式!$B$55,-($A16*(1-訂閱模式!$B$54)-訂閱模式!$B$56-訂閱模式!$B$52*訂閱模式!$B$57/12))+訂閱模式!$B$52*B$14/(1+假設!$B$13/12)^訂閱模式!$B$55 -> -155.1854 | C16: =-訂閱模式!$B$52+PV(假設!$B$13/12,訂閱模式!$B$55,-($A16*(1-訂閱模式!$B$54)-訂閱模式!$B$56-訂閱模式!$B$52*訂閱模式!$B$57/12))+訂閱模式!$B$52*C$14/(1+假設!$B$13/12)^訂閱模式!$B$55 -> 1207.5611 | D16: =-訂閱模式!$B$52+PV(假設!$B$13/12,訂閱模式!$B$55,-($A16*(1-訂閱模式!$B$54)-訂閱模式!$B$56-訂閱模式!$B$52*訂閱模式!$B$57/12))+訂閱模式!$B$52*D$14/(1+假設!$B$13/12)^訂閱模式!$B$55 -> 1888.9343 | E16: =-訂閱模式!$B$52+PV(假設!$B$13/12,訂閱模式!$B$55,-($A16*(1-訂閱模式!$B$54)-訂閱模式!$B$56-訂閱模式!$B$52*訂閱模式!$B$57/12))+訂閱模式!$B$52*E$14/(1+假設!$B$13/12)^訂閱模式!$B$55 -> 3251.6808 | F16: =-訂閱模式!$B$52+PV(假設!$B$13/12,訂閱模式!$B$55,-($A16*(1-訂閱模式!$B$54)-訂閱模式!$B$56-訂閱模式!$B$52*訂閱模式!$B$57/12))+訂閱模式!$B$52*F$14/(1+假設!$B$13/12)^訂閱模式!$B$55 -> 4614.4273
A17: 1200 | B17: =-訂閱模式!$B$52+PV(假設!$B$13/12,訂閱模式!$B$55,-($A17*(1-訂閱模式!$B$54)-訂閱模式!$B$56-訂閱模式!$B$52*訂閱模式!$B$57/12))+訂閱模式!$B$52*B$14/(1+假設!$B$13/12)^訂閱模式!$B$55 -> 4702.7843 | C17: =-訂閱模式!$B$52+PV(假設!$B$13/12,訂閱模式!$B$55,-($A17*(1-訂閱模式!$B$54)-訂閱模式!$B$56-訂閱模式!$B$52*訂閱模式!$B$57/12))+訂閱模式!$B$52*C$14/(1+假設!$B$13/12)^訂閱模式!$B$55 -> 6065.5307 | D17: =-訂閱模式!$B$52+PV(假設!$B$13/12,訂閱模式!$B$55,-($A17*(1-訂閱模式!$B$54)-訂閱模式!$B$56-訂閱模式!$B$52*訂閱模式!$B$57/12))+訂閱模式!$B$52*D$14/(1+假設!$B$13/12)^訂閱模式!$B$55 -> 6746.904 | E17: =-訂閱模式!$B$52+PV(假設!$B$13/12,訂閱模式!$B$55,-($A17*(1-訂閱模式!$B$54)-訂閱模式!$B$56-訂閱模式!$B$52*訂閱模式!$B$57/12))+訂閱模式!$B$52*E$14/(1+假設!$B$13/12)^訂閱模式!$B$55 -> 8109.6505 | F17: =-訂閱模式!$B$52+PV(假設!$B$13/12,訂閱模式!$B$55,-($A17*(1-訂閱模式!$B$54)-訂閱模式!$B$56-訂閱模式!$B$52*訂閱模式!$B$57/12))+訂閱模式!$B$52*F$14/(1+假設!$B$13/12)^訂閱模式!$B$55 -> 9472.3969
A18: 1400 | B18: =-訂閱模式!$B$52+PV(假設!$B$13/12,訂閱模式!$B$55,-($A18*(1-訂閱模式!$B$54)-訂閱模式!$B$56-訂閱模式!$B$52*訂閱模式!$B$57/12))+訂閱模式!$B$52*B$14/(1+假設!$B$13/12)^訂閱模式!$B$55 -> 9560.7539 | C18: =-訂閱模式!$B$52+PV(假設!$B$13/12,訂閱模式!$B$55,-($A18*(1-訂閱模式!$B$54)-訂閱模式!$B$56-訂閱模式!$B$52*訂閱模式!$B$57/12))+訂閱模式!$B$52*C$14/(1+假設!$B$13/12)^訂閱模式!$B$55 -> 10923.5 | D18: =-訂閱模式!$B$52+PV(假設!$B$13/12,訂閱模式!$B$55,-($A18*(1-訂閱模式!$B$54)-訂閱模式!$B$56-訂閱模式!$B$52*訂閱模式!$B$57/12))+訂閱模式!$B$52*D$14/(1+假設!$B$13/12)^訂閱模式!$B$55 -> 11604.874 | E18: =-訂閱模式!$B$52+PV(假設!$B$13/12,訂閱模式!$B$55,-($A18*(1-訂閱模式!$B$54)-訂閱模式!$B$56-訂閱模式!$B$52*訂閱模式!$B$57/12))+訂閱模式!$B$52*E$14/(1+假設!$B$13/12)^訂閱模式!$B$55 -> 12967.62 | F18: =-訂閱模式!$B$52+PV(假設!$B$13/12,訂閱模式!$B$55,-($A18*(1-訂閱模式!$B$54)-訂閱模式!$B$56-訂閱模式!$B$52*訂閱模式!$B$57/12))+訂閱模式!$B$52*F$14/(1+假設!$B$13/12)^訂閱模式!$B$55 -> 14330.367
A19: 1600 | B19: =-訂閱模式!$B$52+PV(假設!$B$13/12,訂閱模式!$B$55,-($A19*(1-訂閱模式!$B$54)-訂閱模式!$B$56-訂閱模式!$B$52*訂閱模式!$B$57/12))+訂閱模式!$B$52*B$14/(1+假設!$B$13/12)^訂閱模式!$B$55 -> 14418.724 | C19: =-訂閱模式!$B$52+PV(假設!$B$13/12,訂閱模式!$B$55,-($A19*(1-訂閱模式!$B$54)-訂閱模式!$B$56-訂閱模式!$B$52*訂閱模式!$B$57/12))+訂閱模式!$B$52*C$14/(1+假設!$B$13/12)^訂閱模式!$B$55 -> 15781.47 | D19: =-訂閱模式!$B$52+PV(假設!$B$13/12,訂閱模式!$B$55,-($A19*(1-訂閱模式!$B$54)-訂閱模式!$B$56-訂閱模式!$B$52*訂閱模式!$B$57/12))+訂閱模式!$B$52*D$14/(1+假設!$B$13/12)^訂閱模式!$B$55 -> 16462.843 | E19: =-訂閱模式!$B$52+PV(假設!$B$13/12,訂閱模式!$B$55,-($A19*(1-訂閱模式!$B$54)-訂閱模式!$B$56-訂閱模式!$B$52*訂閱模式!$B$57/12))+訂閱模式!$B$52*E$14/(1+假設!$B$13/12)^訂閱模式!$B$55 -> 17825.59 | F19: =-訂閱模式!$B$52+PV(假設!$B$13/12,訂閱模式!$B$55,-($A19*(1-訂閱模式!$B$54)-訂閱模式!$B$56-訂閱模式!$B$52*訂閱模式!$B$57/12))+訂閱模式!$B$52*F$14/(1+假設!$B$13/12)^訂閱模式!$B$55 -> 19188.336
A22: M1 軟體訂閱 每套淨增量毛利（NT$）：轉換率（列）× 年費（欄）
A23: 轉換率 \ 年費 | B23: 990 | C23: 1400 | D23: 1800 | E23: 2400 | F23: 3000
A24: 0.05 | B24: =$A24*訂閱模式!$B$17*(B$23*(1-訂閱模式!$B$18)-訂閱模式!$B$19)-(1-訂閱模式!$B$21)*訂閱模式!$B$20-訂閱模式!$B$23 -> -381.7 | C24: =$A24*訂閱模式!$B$17*(C$23*(1-訂閱模式!$B$18)-訂閱模式!$B$19)-(1-訂閱模式!$B$21)*訂閱模式!$B$20-訂閱模式!$B$23 -> -312 | D24: =$A24*訂閱模式!$B$17*(D$23*(1-訂閱模式!$B$18)-訂閱模式!$B$19)-(1-訂閱模式!$B$21)*訂閱模式!$B$20-訂閱模式!$B$23 -> -244 | E24: =$A24*訂閱模式!$B$17*(E$23*(1-訂閱模式!$B$18)-訂閱模式!$B$19)-(1-訂閱模式!$B$21)*訂閱模式!$B$20-訂閱模式!$B$23 -> -142 | F24: =$A24*訂閱模式!$B$17*(F$23*(1-訂閱模式!$B$18)-訂閱模式!$B$19)-(1-訂閱模式!$B$21)*訂閱模式!$B$20-訂閱模式!$B$23 -> -40
A25: 0.1 | B25: =$A25*訂閱模式!$B$17*(B$23*(1-訂閱模式!$B$18)-訂閱模式!$B$19)-(1-訂閱模式!$B$21)*訂閱模式!$B$20-訂閱模式!$B$23 -> -283.4 | C25: =$A25*訂閱模式!$B$17*(C$23*(1-訂閱模式!$B$18)-訂閱模式!$B$19)-(1-訂閱模式!$B$21)*訂閱模式!$B$20-訂閱模式!$B$23 -> -144 | D25: =$A25*訂閱模式!$B$17*(D$23*(1-訂閱模式!$B$18)-訂閱模式!$B$19)-(1-訂閱模式!$B$21)*訂閱模式!$B$20-訂閱模式!$B$23 -> -8 | E25: =$A25*訂閱模式!$B$17*(E$23*(1-訂閱模式!$B$18)-訂閱模式!$B$19)-(1-訂閱模式!$B$21)*訂閱模式!$B$20-訂閱模式!$B$23 -> 196 | F25: =$A25*訂閱模式!$B$17*(F$23*(1-訂閱模式!$B$18)-訂閱模式!$B$19)-(1-訂閱模式!$B$21)*訂閱模式!$B$20-訂閱模式!$B$23 -> 400
A26: 0.15 | B26: =$A26*訂閱模式!$B$17*(B$23*(1-訂閱模式!$B$18)-訂閱模式!$B$19)-(1-訂閱模式!$B$21)*訂閱模式!$B$20-訂閱模式!$B$23 -> -185.1 | C26: =$A26*訂閱模式!$B$17*(C$23*(1-訂閱模式!$B$18)-訂閱模式!$B$19)-(1-訂閱模式!$B$21)*訂閱模式!$B$20-訂閱模式!$B$23 -> 24 | D26: =$A26*訂閱模式!$B$17*(D$23*(1-訂閱模式!$B$18)-訂閱模式!$B$19)-(1-訂閱模式!$B$21)*訂閱模式!$B$20-訂閱模式!$B$23 -> 228 | E26: =$A26*訂閱模式!$B$17*(E$23*(1-訂閱模式!$B$18)-訂閱模式!$B$19)-(1-訂閱模式!$B$21)*訂閱模式!$B$20-訂閱模式!$B$23 -> 534 | F26: =$A26*訂閱模式!$B$17*(F$23*(1-訂閱模式!$B$18)-訂閱模式!$B$19)-(1-訂閱模式!$B$21)*訂閱模式!$B$20-訂閱模式!$B$23 -> 840
A27: 0.2 | B27: =$A27*訂閱模式!$B$17*(B$23*(1-訂閱模式!$B$18)-訂閱模式!$B$19)-(1-訂閱模式!$B$21)*訂閱模式!$B$20-訂閱模式!$B$23 -> -86.8 | C27: =$A27*訂閱模式!$B$17*(C$23*(1-訂閱模式!$B$18)-訂閱模式!$B$19)-(1-訂閱模式!$B$21)*訂閱模式!$B$20-訂閱模式!$B$23 -> 192 | D27: =$A27*訂閱模式!$B$17*(D$23*(1-訂閱模式!$B$18)-訂閱模式!$B$19)-(1-訂閱模式!$B$21)*訂閱模式!$B$20-訂閱模式!$B$23 -> 464 | E27: =$A27*訂閱模式!$B$17*(E$23*(1-訂閱模式!$B$18)-訂閱模式!$B$19)-(1-訂閱模式!$B$21)*訂閱模式!$B$20-訂閱模式!$B$23 -> 872 | F27: =$A27*訂閱模式!$B$17*(F$23*(1-訂閱模式!$B$18)-訂閱模式!$B$19)-(1-訂閱模式!$B$21)*訂閱模式!$B$20-訂閱模式!$B$23 -> 1280
A28: 0.3 | B28: =$A28*訂閱模式!$B$17*(B$23*(1-訂閱模式!$B$18)-訂閱模式!$B$19)-(1-訂閱模式!$B$21)*訂閱模式!$B$20-訂閱模式!$B$23 -> 109.8 | C28: =$A28*訂閱模式!$B$17*(C$23*(1-訂閱模式!$B$18)-訂閱模式!$B$19)-(1-訂閱模式!$B$21)*訂閱模式!$B$20-訂閱模式!$B$23 -> 528 | D28: =$A28*訂閱模式!$B$17*(D$23*(1-訂閱模式!$B$18)-訂閱模式!$B$19)-(1-訂閱模式!$B$21)*訂閱模式!$B$20-訂閱模式!$B$23 -> 936 | E28: =$A28*訂閱模式!$B$17*(E$23*(1-訂閱模式!$B$18)-訂閱模式!$B$19)-(1-訂閱模式!$B$21)*訂閱模式!$B$20-訂閱模式!$B$23 -> 1548 | F28: =$A28*訂閱模式!$B$17*(F$23*(1-訂閱模式!$B$18)-訂閱模式!$B$19)-(1-訂閱模式!$B$21)*訂閱模式!$B$20-訂閱模式!$B$23 -> 2160
A29: 0.4 | B29: =$A29*訂閱模式!$B$17*(B$23*(1-訂閱模式!$B$18)-訂閱模式!$B$19)-(1-訂閱模式!$B$21)*訂閱模式!$B$20-訂閱模式!$B$23 -> 306.4 | C29: =$A29*訂閱模式!$B$17*(C$23*(1-訂閱模式!$B$18)-訂閱模式!$B$19)-(1-訂閱模式!$B$21)*訂閱模式!$B$20-訂閱模式!$B$23 -> 864 | D29: =$A29*訂閱模式!$B$17*(D$23*(1-訂閱模式!$B$18)-訂閱模式!$B$19)-(1-訂閱模式!$B$21)*訂閱模式!$B$20-訂閱模式!$B$23 -> 1408 | E29: =$A29*訂閱模式!$B$17*(E$23*(1-訂閱模式!$B$18)-訂閱模式!$B$19)-(1-訂閱模式!$B$21)*訂閱模式!$B$20-訂閱模式!$B$23 -> 2224 | F29: =$A29*訂閱模式!$B$17*(F$23*(1-訂閱模式!$B$18)-訂閱模式!$B$19)-(1-訂閱模式!$B$21)*訂閱模式!$B$20-訂閱模式!$B$23 -> 3040
A32: 架構 B 電池成本（NT$）：電芯單價 NT$/Wh（列）× 容量 Wh（欄）
A33: NT$/Wh \ Wh | B33: 500 | C33: 630 | D33: 720 | E33: 800
A34: 2.5 | B34: =$A34*B$33+BOM分析!$C$18+BOM分析!$C$19+BOM分析!$C$20 -> 2950 | C34: =$A34*C$33+BOM分析!$C$18+BOM分析!$C$19+BOM分析!$C$20 -> 3275 | D34: =$A34*D$33+BOM分析!$C$18+BOM分析!$C$19+BOM分析!$C$20 -> 3500 | E34: =$A34*E$33+BOM分析!$C$18+BOM分析!$C$19+BOM分析!$C$20 -> 3700
A35: 3 | B35: =$A35*B$33+BOM分析!$C$18+BOM分析!$C$19+BOM分析!$C$20 -> 3200 | C35: =$A35*C$33+BOM分析!$C$18+BOM分析!$C$19+BOM分析!$C$20 -> 3590 | D35: =$A35*D$33+BOM分析!$C$18+BOM分析!$C$19+BOM分析!$C$20 -> 3860 | E35: =$A35*E$33+BOM分析!$C$18+BOM分析!$C$19+BOM分析!$C$20 -> 4100
A36: 3.5 | B36: =$A36*B$33+BOM分析!$C$18+BOM分析!$C$19+BOM分析!$C$20 -> 3450 | C36: =$A36*C$33+BOM分析!$C$18+BOM分析!$C$19+BOM分析!$C$20 -> 3905 | D36: =$A36*D$33+BOM分析!$C$18+BOM分析!$C$19+BOM分析!$C$20 -> 4220 | E36: =$A36*E$33+BOM分析!$C$18+BOM分析!$C$19+BOM分析!$C$20 -> 4500
A37: 4 | B37: =$A37*B$33+BOM分析!$C$18+BOM分析!$C$19+BOM分析!$C$20 -> 3700 | C37: =$A37*C$33+BOM分析!$C$18+BOM分析!$C$19+BOM分析!$C$20 -> 4220 | D37: =$A37*D$33+BOM分析!$C$18+BOM分析!$C$19+BOM分析!$C$20 -> 4580 | E37: =$A37*E$33+BOM分析!$C$18+BOM分析!$C$19+BOM分析!$C$20 -> 4900
A38: 4.5 | B38: =$A38*B$33+BOM分析!$C$18+BOM分析!$C$19+BOM分析!$C$20 -> 3950 | C38: =$A38*C$33+BOM分析!$C$18+BOM分析!$C$19+BOM分析!$C$20 -> 4535 | D38: =$A38*D$33+BOM分析!$C$18+BOM分析!$C$19+BOM分析!$C$20 -> 4940 | E38: =$A38*E$33+BOM分析!$C$18+BOM分析!$C$19+BOM分析!$C$20 -> 5300
A39: 5 | B39: =$A39*B$33+BOM分析!$C$18+BOM分析!$C$19+BOM分析!$C$20 -> 4200 | C39: =$A39*C$33+BOM分析!$C$18+BOM分析!$C$19+BOM分析!$C$20 -> 4850 | D39: =$A39*D$33+BOM分析!$C$18+BOM分析!$C$19+BOM分析!$C$20 -> 5300 | E39: =$A39*E$33+BOM分析!$C$18+BOM分析!$C$19+BOM分析!$C$20 -> 5700
