Workbook

Sheet 假設
A1: V3 補充：電池 + 充電器拆分為訂閱｜入手價、訂閱費、輪內可拆成本、護城河
A2: 藍字 = 可調輸入（取自「單速+Hub-motor 整車出廠價降本模型 V3」與 StealthWheel 盡調報告）；黑字 = 公式；綠字 = 跨表連結。2026-09-21
A4: A. V3 模型基準（中國 FOB，10 萬台/年）
A5: 參數 | B5: 值 | C5: 來源
A6: 極簡 180Wh 配置材料合計（RMB） | B6: 1121 | C6: V3 1_假設與單價 C43（鋼架/V煞/PAS/單鍵/單速/180Wh）
A7: 直接組裝工時 + QC（RMB/台） | B7: 22 | C7: V3 B8
A8: ODM 毛利率（爭取值） | B8: 0.13 | C8: V3 B9
A9: ODM 毛利率（實際可能） | B9: 0.18 | C9: V3 分頁 3：富士達電助力車事業 18.94%
A10: 電芯單價（RMB/Wh） | B10: 0.66 | C10: V3 B10
A11: 電池包固定成本（RMB） | B11: 120 | C11: V3 B11：BMS + 外殼/軌道/鎖 + 連接器/點焊/測試，不隨容量縮小
A12: 電池包加工毛利 | B12: 0.18 | C12: V3 B12
A13: 充電器 36V 2A（RMB） | B13: 40 | C13: V3 C31
A14: 日本版力矩感測淨增額（RMB 材料） | B14: 160 | C14: V3 分頁 7 D15（力矩中軸 160 − 標準中軸 7 + 線束 14 + 校正 3 − PAS 10 ≈ 160）
A15: 日本版非 BOM 增額（型式認定/PSE/說明書/OTP，RMB） | B15: 7.3 | C15: V3 分頁 7 B40:B43
A17: B. 匯率（V3 一致）
A18: 參數 | B18: 值 | C18: 來源
A19: RMB / EUR | B19: 10.8 | C19: V3 分頁 10
A20: NTD / RMB | B20: 4.54 | C20: V3 B7
A21: JPY / RMB | B21: 23.5 | C21: V3 分頁 8 B7
A23: C. 車體零售（入手價）假設
A24: 參數 | B24: 值 | C24: 來源
A25: 歐洲：關稅（台越製 MFN；中國製不適用） | B25: 0.06 | C25: V3 分頁 10 B36。注意：中國 FOB 出貨至歐盟另有 AD+CVD，本表沿用 V3 假設以台越製計
A26: 歐洲：運費（€/台） | B26: 8 | C26: V3 分頁 10
A27: 歐洲：DTC 毛利率 | B27: 0.35 | C27: V3
A28: 歐洲：經銷抽成 | B28: 0.38 | C28: V3
A29: 歐洲：VAT | B29: 0.19
A30: 台灣：DTC 毛利率 | B30: 0.35 | C30: V3
A31: 台灣：營業稅 | B31: 0.05
A32: 日本：出口報關/內陸 4% | B32: 0.04 | C32: V3 分頁 8 B9
A33: 日本：海運保險（¥/台） | B33: 1800 | C33: V3 B10
A34: 日本：通關拖運（¥/台） | B34: 800 | C34: V3 B14
A35: 日本：PSE 逐台檢查 + 認證攤提（¥/台） | B35: 600 | C35: V3 B15
A36: 日本：PDI/說明書/防犯登録/保固準備（¥/台） | B36: 3500 | C36: V3 B16
A37: 日本：通路 PB 情境 PDI 減項（¥） | B37: 3500 | C37: V3 B25
A38: 日本：通路 PB 零售毛利 | B38: 0.3 | C38: V3 E25
A39: 日本：BESV 壓縮進口毛利 | B39: 0.15 | C39: V3 C24
A40: 日本：經銷零售毛利 | B40: 0.22 | C40: V3 E24
A41: 日本：消費稅 | B41: 0.1
A43: D. 電池訂閱費：成本堆疊定價假設（三市場）
A44: 參數 | B44: 歐洲 € / 台灣 NT$ / 日本 ¥（同列三值見備註） | C44: 說明
...

Sheet 入手價
A1: 入手價：把電池與充電器移出整車後，各市場的出廠價與零售價
A2: 單位依欄標。配置 C 為本次計算重點；A、B 為 V3 既有基準的對照。
A4: A. 材料與出廠價（RMB）
A5: 配置 | B5: 材料 RMB | C5: 出廠 @13% | D5: 出廠 @18% | E5: NT$ 出廠 @13% | F5: NT$ 出廠 @18% | I5: 說明
A6: A 極簡 180Wh 含電池含充電器（V3 基準） | B6: =假設!$B$6 -> 1121 | C6: =(B6+假設!$B$7)/(1-假設!$B$8) -> 1313.7931 | D6: =(B6+假設!$B$7)/(1-假設!$B$9) -> 1393.9024 | E6: =C6*假設!$B$20 -> 5964.6207 | F6: =D6*假設!$B$20 -> 6328.3171 | I6: V3 分頁 3 C6：RMB 1,314
A7: B 不含電池、含充電器（V3 分頁 10） | B7: =假設!$B$6-((180)*假設!$B$10+假設!$B$11)*(1+假設!$B$12) -> 839.216 | C7: =(B7+假設!$B$7)/(1-假設!$B$8) -> 989.90345 | D7: =(B7+假設!$B$7)/(1-假設!$B$9) -> 1050.2634 | E7: =C7*假設!$B$20 -> 4494.1617 | F7: =D7*假設!$B$20 -> 4768.1959 | I7: V3 分頁 10 C32：材料 839
A8: C 不含電池、不含充電器（本次） | B8: =假設!$B$6-((180)*假設!$B$10+假設!$B$11)*(1+假設!$B$12)-假設!$B$13 -> 799.216 | C8: =(B8+假設!$B$7)/(1-假設!$B$8) -> 943.92644 | D8: =(B8+假設!$B$7)/(1-假設!$B$9) -> 1001.4829 | E8: =C8*假設!$B$20 -> 4285.426 | F8: =D8*假設!$B$20 -> 4546.7325 | I8: 電池與充電器皆為訂閱資產
A9: D 日本版 C（力矩感測，電池 144Wh 訂閱） | B9: =假設!$B$6-((180)*假設!$B$10+假設!$B$11)*(1+假設!$B$12)-假設!$B$13+假設!$B$14+假設!$B$15 -> 966.516 | C9: =(B9+假設!$B$7)/(1-假設!$B$8) -> 1136.2253 | D9: =(B9+假設!$B$7)/(1-假設!$B$9) -> 1205.5073 | E9: =C9*假設!$B$20 -> 5158.4628 | F9: =D9*假設!$B$20 -> 5473.0032 | I9: V3 分頁 7：力矩 +160、非 BOM +7.3；電池降配 144Wh 在訂閱側
A10: C 對 A 的出廠價降幅 | C10: =1-C8/C6 -> 0.28152581 | I10: 電池 + 充電器移出後，車體出廠價降 28%
A11: 訂閱資產：180Wh 電池 + 充電器（RMB） | B11: =((180)*假設!$B$10+假設!$B$11)*(1+假設!$B$12)+假設!$B$13 -> 321.784 | I11: 電池 282 + 充電器 40
A13: B. 歐洲與台灣零售（配置 C）
A14: 項目 | B14: 歐洲 € | C14: 台灣 NT$ | I14: 公式 / 對照
A15: 出廠價（配置 C，ODM 13%） | B15: =C8/假設!$B$19 -> 87.400596 | C15: =E8 -> 4285.426 | I15: RMB ÷ 10.8；NT$ 直接取
A16: 落地成本（歐洲：關稅 6% + €8；台灣：假設 +NT$150 運費） | B16: =B15*(1+假設!$B$25)+假設!$B$26 -> 100.64463 | C16: =C15+150 -> 4435.426 | I16: V3 分頁 10 D36 結構
A17: DTC 零售（含稅） | B17: =B16/(1-假設!$B$27)*(1+假設!$B$46) -> 184.2571 | C17: =C16/(1-假設!$B$30)*(1+假設!$B$31) -> 7164.919 | I17: ＝ 落地 ÷ (1 − 35%) × (1 + 稅)
A18: 經銷零售（含稅，歐洲抽 38%） | B18: =B16/(1-假設!$B$27)/(1-假設!$B$28)*(1+假設!$B$46) -> 297.18886 | C18: =C16/(1-假設!$B$30)/(1-0.30)*(1+假設!$B$31) -> 10235.599 | I18: 台灣經銷以抽 30% 假設
A19: 對照：市場最低價合法 e-bike 買斷 | B19: 699 | C19: 15000 | I19: 歐洲 Action E200 / Lidl €699；台灣入門電輔車約 NT$15,000（假設，內需無公開統計）
A20: 對照：一般（非電動）自行車均價 | B20: 500 | C20: 5500 | I20: 德國 ZIV 2025 €500；台灣通勤/淑女車 NT$4,000–7,000（V3 分頁 10）
A21: DTC 入手價 vs 最低價 e-bike | B21: =B17/B19-1 -> -0.73639901 | C21: =C17/C19-1 -> -0.52233874 | I21: 負值 = 入手價低於對照
A22: DTC 入手價 vs 一般自行車 | B22: =B17/B20-1 -> -0.63148581 | C22: =C17/C20-1 -> 0.30271254 | I22: V3「反向滲透」檢核：歐洲成立、台灣勉強
A24: C. 日本零售（配置 D，V3 分頁 8 結構）
A25: 項目 | B25: ¥/台 | I25: 說明
A26: 出廠價（配置 D，ODM 13%，RMB） | B26: =C9 -> 1136.2253
A27: 出廠價（¥） | B27: =B26*假設!$B$21 -> 26701.294
A28: CIF（+4% 報關 + 海運保險） | B28: =B27*(1+假設!$B$32)+假設!$B$33 -> 29569.346
A29: 進口商全載成本（+通關 + PSE + PDI；關稅 0%） | B29: =B28+假設!$B$34+假設!$B$35+假設!$B$36 -> 34469.346 | I29: V3：HS 8711.60 無稅；消費稅可扣抵不計
A30: 情境 3：通路自有品牌 PB 零售（税込） | B30: =(B29-假設!$B$37)/(1-假設!$B$38)*(1+假設!$B$41) -> 48666.115 | I30: V3 情境 3 已用 Cainz ¥59,800 / ドンキ ¥65,780 校準
A31: 情境 2：BESV 壓縮毛利 15% + 經銷 22%（税込） | B31: =B29/(1-假設!$B$39)/(1-假設!$B$40)*(1+假設!$B$41) -> 57188.96
A32: 對照：Cainz PB ¥59,800／Panasonic ビビ EYX ¥89,800／NORUDE ¥2,890×36 | B32: 59800 | I32: V3 分頁 8 C 段
A33: PB 入手價 vs Cainz | B33: =B30/B32-1 -> -0.18618536 | I33: 電池不在車價內，PB 通路入手價可低於現有最低價帶

Sheet 電池訂閱費
A1: 電池訂閱費：成本堆疊定價（三市場 × 三容量）
A2: 建議月費 = [資產攤提 + 更換準備 + 失竊 + 客服 + 維修物流 + CAC 攤提] ÷ (1 − 目標貢獻率) ÷ (1 − 呆帳 − 金流) × (1 + 稅)。再以「建議定價（取整）」回算貢獻與淨值。
A4: 歐洲 €（每戶每月）
A5: 項目 | B5: 180 Wh | C5: 250 Wh | D5: 360 Wh | K5: 公式 / 說明
A6: 電池包 FOB（RMB） | B6: =((180)*假設!$B$10+假設!$B$11)*(1+假設!$B$12) -> 281.784 | C6: =((250)*假設!$B$10+假設!$B$11)*(1+假設!$B$12) -> 336.3 | D6: =((360)*假設!$B$10+假設!$B$11)*(1+假設!$B$12) -> 421.968 | K6: V3 成本函數 (Wh×0.66+120)×1.18
A7: 電池落地成本（當地幣） | B7: =B6/假設!$B$19*(1+假設!$B$25)+假設!$B$58 -> 31.656578 | C7: =C6/假設!$B$19*(1+假設!$B$25)+假設!$B$58 -> 37.007222 | D7: =D6/假設!$B$19*(1+假設!$B$25)+假設!$B$58 -> 45.415378 | K7: RMB / 10.8 × 1.06 + 物流分攤
A8: 充電器落地成本（當地幣） | B8: =假設!$B$13/假設!$B$19*(1+假設!$B$25) -> 3.9259259 | C8: =假設!$B$13/假設!$B$19*(1+假設!$B$25) -> 3.9259259 | D8: =假設!$B$13/假設!$B$19*(1+假設!$B$25) -> 3.9259259 | K8: 日本充電器為 ◇PSE 特定電気用品，認證費另計
A9: 每戶訂閱資產（電池 + 充電器） | B9: =B7+B8 -> 35.582504 | C9: =C7+C8 -> 40.933148 | D9: =D7+D8 -> 49.341304 | K9: 對照 V3 分頁 10：三電訂閱資產 €69、電池 €32
A10: ① 電池資產攤提 = 資產 × (1 − 殘值) ÷ 壽命 | B10: =B7*(1-假設!$B$56)/假設!$B$54 -> 0.74744698 | C10: =C7*(1-假設!$B$56)/假設!$B$54 -> 0.87378164 | D10: =D7*(1-假設!$B$56)/假設!$B$54 -> 1.0723075
A11: ② 充電器攤提 = 充電器 ÷ 壽命 | B11: =B8/假設!$B$54 -> 0.1090535 | C11: =C8/假設!$B$54 -> 0.1090535 | D11: =D8/假設!$B$54 -> 0.1090535
A12: ③ 電池更換準備 = (電池 + 更換物流) ÷ 更換週期 | B12: =(B7+假設!$B$53)/假設!$B$52 -> 1.284512 | C12: =(C7+假設!$B$53)/假設!$B$52 -> 1.3959838 | D12: =(D7+假設!$B$53)/假設!$B$52 -> 1.5711537 | K12: SoH < 70% 免費換新的準備金；物流走經銷點（UN3480）
A13: ④ 失竊補償 + ⑤ 客服/雲端 + ⑥ 維修物流 | B13: =假設!$B$51+假設!$B$49+假設!$B$50 -> 1.7 | C13: =假設!$B$51+假設!$B$49+假設!$B$50 -> 1.7 | D13: =假設!$B$51+假設!$B$49+假設!$B$50 -> 1.7 | K13: 按戶固定，不隨電池大小縮小（V3 分頁 9/10 的核心結構）
A14: ⑦ CAC 攤提 = CAC ÷ 壽命 | B14: =假設!$B$55/假設!$B$54 -> 0.83333333 | C14: =假設!$B$55/假設!$B$54 -> 0.83333333 | D14: =假設!$B$55/假設!$B$54 -> 0.83333333
A15: 每戶每月成本合計 | B15: =SUM(B10:B14) -> 4.6743458 | C15: =SUM(C10:C14) -> 4.9121523 | D15: =SUM(D10:D14) -> 5.2858481
A16: 所需淨月費 = 成本 ÷ (1 − 目標貢獻率) | B16: =B15/(1-假設!$B$57) -> 6.2324611 | C16: =C15/(1-假設!$B$57) -> 6.5495364 | D16: =D15/(1-假設!$B$57) -> 7.0477974
A17: 建議月費（含稅、含呆帳金流）= 淨月費 ÷ (1 − 呆帳 − 金流) × (1 + 稅) | B17: =B16/(1-假設!$B$47-假設!$B$48)*(1+假設!$B$46) -> 8.1056052 | C17: =C16/(1-假設!$B$47-假設!$B$48)*(1+假設!$B$46) -> 8.5179762 | D17: =D16/(1-假設!$B$47-假設!$B$48)*(1+假設!$B$46) -> 9.1659879 | K17: 成本堆疊得出的月費
A18: 損益兩平月費（貢獻率 0） | B18: =B15/(1-假設!$B$47-假設!$B$48)*(1+假設!$B$46) -> 6.0792039 | C18: =C15/(1-假設!$B$47-假設!$B$48)*(1+假設!$B$46) -> 6.3884822 | D18: =D15/(1-假設!$B$47-假設!$B$48)*(1+假設!$B$46) -> 6.8744909
A19: 建議定價（取整，可改） | B19: 7.9 | C19: 9.9 | D19: 12.9 | K19: 對照錨點：歐洲替換電池零售 €120–180；台灣 Gogoro NT$319 起；日本 NORUDE 盜難補償 ¥700/月
A20: 以定價回算：每戶月貢獻 | B20: =B19/(1+假設!$B$46)*(1-假設!$B$47-假設!$B$48)-B15+B10+B14 -> 2.9808042 | C20: =C19/(1+假設!$B$46)*(1-假設!$B$47-假設!$B$48)-C15+C10+C14 -> 4.4071476 | D20: =D19/(1+假設!$B$46)*(1-假設!$B$47-假設!$B$48)-D15+D10+D14 -> 6.5387004 | K20: ＝ 淨收 − 現金成本（③④⑤⑥；資產與 CAC 另列）
A21: 資產回收期（月） | B21: =IF(B20>0,B9/B20,999) -> 11.937216 | C21: =IF(C20>0,C9/C20,999) -> 9.2879005 | D21: =IF(D20>0,D9/D20,999) -> 7.5460414
A22: 36 月單戶淨值 = 貢獻 × 壽命 + 殘值 − 資產 − CAC | B22: =B20*假設!$B$54+B7*假設!$B$56-B9-假設!$B$55 -> 46.474935 | C22: =C20*假設!$B$54+C7*假設!$B$56-C9-假設!$B$55 -> 93.275248 | D22: =D20*假設!$B$54+D7*假設!$B$56-D9-假設!$B$55 -> 162.86422
A23: 定價 × 36 月合計（消費者視角） | B23: =B19*36 -> 284.4 | C23: =C19*36 -> 356.4 | D23: =D19*36 -> 464.4 | K23: 對照：買斷方案第 4 年換電池 €250 / NT$6,000 / ¥35,000
A25: 台灣 NT$（每戶每月）
A26: 項目 | B26: 180 Wh | C26: 250 Wh | D26: 360 Wh | K26: 公式 / 說明
A27: 電池包 FOB（RMB） | B27: =((180)*假設!$B$10+假設!$B$11)*(1+假設!$B$12) -> 281.784 | C27: =((250)*假設!$B$10+假設!$B$11)*(1+假設!$B$12) -> 336.3 | D27: =((360)*假設!$B$10+假設!$B$11)*(1+假設!$B$12) -> 421.968 | K27: V3 成本函數 (Wh×0.66+120)×1.18
A28: 電池落地成本（當地幣） | B28: =B27*假設!$B$20+假設!$B$72 -> 1379.2994 | C28: =C27*假設!$B$20+假設!$B$72 -> 1626.802 | D28: =D27*假設!$B$20+假設!$B$72 -> 2015.7347 | K28: RMB × 4.54 + 物流分攤
A29: 充電器落地成本（當地幣） | B29: =假設!$B$13*假設!$B$20 -> 181.6 | C29: =假設!$B$13*假設!$B$20 -> 181.6 | D29: =假設!$B$13*假設!$B$20 -> 181.6 | K29: 日本充電器為 ◇PSE 特定電気用品，認證費另計
A30: 每戶訂閱資產（電池 + 充電器） | B30: =B28+B29 -> 1560.8994 | C30: =C28+C29 -> 1808.402 | D30: =D28+D29 -> 2197.3347 | K30: 對照 V3 分頁 10：三電訂閱資產 €69、電池 €32
A31: ① 電池資產攤提 = 資產 × (1 − 殘值) ÷ 壽命 | B31: =B28*(1-假設!$B$70)/假設!$B$68 -> 32.56679 | C31: =C28*(1-假設!$B$70)/假設!$B$68 -> 38.410603 | D31: =D28*(1-假設!$B$70)/假設!$B$68 -> 47.593736
A32: ② 充電器攤提 = 充電器 ÷ 壽命 | B32: =B29/假設!$B$68 -> 5.0444444 | C32: =C29/假設!$B$68 -> 5.0444444 | D32: =D29/假設!$B$68 -> 5.0444444
A33: ③ 電池更換準備 = (電池 + 更換物流) ÷ 更換週期 | B33: =(B28+假設!$B$67)/假設!$B$66 -> 34.985403 | C33: =(C28+假設!$B$67)/假設!$B$66 -> 40.141708 | D33: =(D28+假設!$B$67)/假設!$B$66 -> 48.244473 | K33: SoH < 70% 免費換新的準備金；物流走經銷點（UN3480）
A34: ④ 失竊補償 + ⑤ 客服/雲端 + ⑥ 維修物流 | B34: =假設!$B$65+假設!$B$63+假設!$B$64 -> 53 | C34: =假設!$B$65+假設!$B$63+假設!$B$64 -> 53 | D34: =假設!$B$65+假設!$B$63+假設!$B$64 -> 53 | K34: 按戶固定，不隨電池大小縮小（V3 分頁 9/10 的核心結構）
A35: ⑦ CAC 攤提 = CAC ÷ 壽命 | B35: =假設!$B$69/假設!$B$68 -> 22.222222 | C35: =假設!$B$69/假設!$B$68 -> 22.222222 | D35: =假設!$B$69/假設!$B$68 -> 22.222222
A36: 每戶每月成本合計 | B36: =SUM(B31:B35) -> 147.81886 | C36: =SUM(C31:C35) -> 158.81898 | D36: =SUM(D31:D35) -> 176.10488
A37: 所需淨月費 = 成本 ÷ (1 − 目標貢獻率) | B37: =B36/(1-假設!$B$71) -> 197.09181 | C37: =C36/(1-假設!$B$71) -> 211.75864 | D37: =D36/(1-假設!$B$71) -> 234.8065
A38: 建議月費（含稅、含呆帳金流）= 淨月費 ÷ (1 − 呆帳 − 金流) × (1 + 稅) | B38: =B37/(1-假設!$B$61-假設!$B$62)*(1+假設!$B$60) -> 220.15575 | C38: =C37/(1-假設!$B$61-假設!$B$62)*(1+假設!$B$60) -> 236.5389 | D38: =D37/(1-假設!$B$61-假設!$B$62)*(1+假設!$B$60) -> 262.28386 | K38: 成本堆疊得出的月費
A39: 損益兩平月費（貢獻率 0） | B39: =B36/(1-假設!$B$61-假設!$B$62)*(1+假設!$B$60) -> 165.11681 | C39: =C36/(1-假設!$B$61-假設!$B$62)*(1+假設!$B$60) -> 177.40418 | D39: =D36/(1-假設!$B$61-假設!$B$62)*(1+假設!$B$60) -> 196.71289
A40: 建議定價（取整，可改） | B40: 249 | C40: 299 | D40: 399 | K40: 對照錨點：歐洲替換電池零售 €120–180；台灣 Gogoro NT$319 起；日本 NORUDE 盜難補償 ¥700/月
A41: 以定價回算：每戶月貢獻 | B41: =B40/(1+假設!$B$60)*(1-假設!$B$61-假設!$B$62)-B36+B31+B35 -> 129.88444 | C41: =C40/(1+假設!$B$60)*(1-假設!$B$61-假設!$B$62)-C36+C31+C35 -> 169.49004 | D41: =D40/(1+假設!$B$60)*(1-假設!$B$61-假設!$B$62)-D36+D31+D35 -> 250.91108 | K41: ＝ 淨收 − 現金成本（③④⑤⑥；資產與 CAC 另列）
A42: 資產回收期（月） | B42: =IF(B41>0,B30/B41,999) -> 12.017601 | C42: =IF(C41>0,C30/C41,999) -> 10.669665 | D42: =IF(D41>0,D30/D41,999) -> 8.7574239
...

Sheet 輪內可拆vs車架可拆
A1: 電池可拆卸的位置：車架可拆包（標準品）vs 輪內分體母模（StealthWheel）
A2: RMB/台。車架可拆包是 V3 電池成本函數的基準（固定成本 120 已含外殼/軌道/鎖），增量為零；輪內方案的增量取自盡調報告重估與 V3 分頁 6。
A4: 項目 | B4: 車架可拆包 | C4: 輪內分體母模 | D4: 差額 | E4: 依據
A5: 電池模組 180Wh（訂閱資產） | B5: =((180)*假設!$B$10+假設!$B$11)*(1+假設!$B$12) -> 281.784 | C5: =假設!$B$90*假設!$B$91 -> 549.9 | D5: =C5-B5 -> 268.116 | E5: 盡調：母模需鍍金同心環 + 冠簧 + 卡口 + 氟膠 O 環 + CNC 鋁殼；US$78 vs 標準包 RMB 282
A6: 馬達 | B6: =假設!$B$93 -> 205 | C6: =假設!$B$92 -> 500 | D6: =C6-B6 -> 295 | E6: 商品化輪轂無卡口/導電介面；分體公模須客製，落入 TK-06U 級距價位
A7: 車架後下叉間隙 | B7: 0 | C7: =假設!$B$94 -> 28 | D7: =C7-B7 -> 28 | E7: Ø130mm 母模須特製後下叉，失去「公版車架」優勢
A8: 組裝、IP67 氣密測試 | B8: 0 | C8: =假設!$B$95 -> 32 | D8: =C8-B8 -> 32 | E8: 扭力管制 + 氣密測試，非隨插即裝
A9: 編輪偏擺處理 | B9: 0 | C9: =假設!$B$96 -> 15 | D9: =C9-B9 -> 15 | E9: 兩側法蘭同在公模 → 輪組偏擺（dish）
A10: 模具與專屬認證 NRE 攤提 | B10: 0 | C10: =假設!$B$97*假設!$B$91/假設!$B$98 -> 17.625 | D10: =C10-B10 -> 17.625 | E10: US$250k ÷ 攤提量
A11: 增量合計（RMB/台） | B11: =SUM(B5:B10) -> 486.784 | C11: =SUM(C5:C10) -> 1142.525 | D11: =SUM(D5:D10) -> 655.741
A12: 其中落在車體（出廠價）的增量 | B12: 0 | C12: =SUM(D6:D10) -> 387.625 | D12: =C12-B12 -> 387.625 | E12: 馬達 + 車架 + 組裝 + 編輪 + NRE
A13: 其中落在訂閱資產（電池模組）的增量 | B13: 0 | C13: =D5 -> 268.116 | D13: =C13-B13 -> 268.116
A15: B. 對出廠價與訂閱費的影響（歐洲 180Wh）
A16: 指標 | B16: 車架可拆包 | C16: 輪內分體母模 | D16: 差額 | E16: 說明
A17: 車體出廠價 RMB（配置 C，ODM 13%） | B17: =入手價!C8 -> 943.92644 | C17: =(入手價!B8+C12-假設!$B$95+假設!$B$7+假設!$B$95)/(1-假設!$B$8) -> 1389.4724 | D17: =C17/B17-1 -> 0.47201345 | E17: 組裝增額計入工時；其餘計入材料
A18: 車體出廠價 NT$ | B18: =B17*假設!$B$20 -> 4285.426 | C18: =C17*假設!$B$20 -> 6308.2048 | D18: =C18-B18 -> 2022.7787 | E18: 對 NT$6,000 目標
A19: 每戶訂閱資產 €（電池 + 充電器） | B19: =電池訂閱費!B9 -> 35.582504 | C19: =C5/假設!$B$19*(1+假設!$B$25)+假設!$B$58+假設!$B$13/假設!$B$19*(1+假設!$B$25) -> 61.897593 | D19: =C19-B19 -> 26.315089
A20: 電池更換週期（月） | B20: =假設!$B$52 -> 48 | C20: =假設!$B$99 -> 36 | D20: =C20-B20 -> -12 | E20: 輪內受熱：盡調矛盾 3
A21: 成本堆疊所需月費 €（含稅） | B21: =((B19-假設!$B$13/假設!$B$19*(1+假設!$B$25))*(1-假設!$B$56)/假設!$B$54+假設!$B$13/假設!$B$19*(1+假設!$B$25)/假設!$B$54+((B19-假設!$B$13/假設!$B$19*(1+假設!$B$25))+假設!$B$53)/B20+假設!$B$51+假設!$B$49+假設!$B$50+假設!$B$55/假設!$B$54)/(1-假設!$B$57)/(1-假設!$B$47-假設!$B$48)*(1+假設!$B$46) -> 8.1056052 | C21: =((C19-假設!$B$13/假設!$B$19*(1+假設!$B$25))*(1-假設!$B$56)/假設!$B$54+假設!$B$13/假設!$B$19*(1+假設!$B$25)/假設!$B$54+((C19-假設!$B$13/假設!$B$19*(1+假設!$B$25))+假設!$B$53)/C20+假設!$B$51+假設!$B$49+假設!$B$50+假設!$B$55/假設!$B$54)/(1-假設!$B$57)/(1-假設!$B$47-假設!$B$48)*(1+假設!$B$46) -> 11.193057 | D21: =C21/B21-1 -> 0.38090332 | E21: 同一套定價公式（見電池訂閱費表）
A23: C. 車架包做到「電芯層級可更換」的成本與效益
A24: 項目 | B24: 點焊鎳片（現行） | C24: 電芯座/螺絲殼（Art.11） | D24: 差額 | E24: 說明
A25: 電池包 FOB RMB（180Wh） | B25: =((180)*假設!$B$10+假設!$B$11)*(1+假設!$B$12) -> 281.784 | C25: =((180)*假設!$B$10+假設!$B$11)*(1+假設!$B$12)+假設!$B$100 -> 301.784 | D25: =C25-B25 -> 20 | E25: +RMB 20：電芯座、彈簧接點、可拆殼體；體積能量密度約 −10%
A26: 翻新成本（佔新品） | B26: 0.6 | C26: =假設!$B$101 -> 0.3 | D26: =C26-B26 -> -0.3 | E26: 點焊包只能整包報廢或拆解回收；電芯座包可只換衰退電芯
A27: 每次翻新成本 RMB | B27: =B25*B26 -> 169.0704 | C27: =C25*C26 -> 90.5352 | D27: =C27-B27 -> -78.5352 | E27: 一次翻新即回收設計增額的 4 倍以上
A28: 法規 | B28: 2027/2/18 起不符 Art.11 | C28: 符合 | E28: 執委會指引 C/2025/214：LMT 電池可拆換義務適用於電芯層級

Sheet 護城河
A1: 護城河評估：電池 + 充電器訂閱能築起什麼
A2: 量化項目連動 V3 分頁 4/5 與本表；質性判定為分析意見。
A4: 候選護城河 | B4: 機制 | C4: 量化效益（RMB/台 或 說明） | D4: 對手複製難度 | E4: 判定
A5: 1. 依實測 duty cycle 配電池 | B5: 持有資產且看得到里程 → 70/22/8 分群配 180/250/360Wh，車隊平均 210Wh；賣斷制必須一律配 360Wh | C5: =(360*假設!$B$10+假設!$B$11)*(1+假設!$B$12)-(0.7*((180)*假設!$B$10+假設!$B$11)*(1+假設!$B$12)+0.22*((250)*假設!$B$10+假設!$B$11)*(1+假設!$B$12)+0.08*((360)*假設!$B$10+假設!$B$11)*(1+假設!$B$12)) -> 116.97576 | D5: 不持有資產者無法做；需 500–1,000 台種子車隊實測 | E5: 中強：成本護城河
A6: 2. 二次電芯降階 | B6: 回收包電芯（SoH 80%）降階給低里程用戶；賣斷制在保固與消保法上不可能 | C6: =0.3*(1-0.4)*180*假設!$B$10 -> 21.384 | D6: 同上；且需電芯級可更換的包設計（本表 C 段） | E6: 中：與 1 合計約出廠價 11%（V3）
A7: 3. 法規鎖定 | B7: EN 15194 §4.2.17.2(c) closed set of components：只有已發布的電池可運作；電池法 Art.60–62 回收義務與 Art.11 電芯可換、2027 電池護照——義務變收費項目 | C7: 第三方電池無法合法相容；護照資料（SoH 歷程）由營運商持有 → 殘值定價 | D7: 對手可自建，但需 2027 前完成合規架構；先行者取得 2 年窗口 | E7: 中：合規即鎖定
A8: 4. 電池池與翻新迴圈 | B8: 同一顆電池跨用戶流轉（升降級、二次利用、翻新 20–30%）；規模越大翻新中心利用率越高、更換預測越準 | C8: =B13 -> 47.8122 | D8: 需逆物流網（經銷點/回收點）+ 翻新產能；Gogoro 靠換電站築牆，本案靠電池池 | E8: 中：規模型
A9: 5. 通路與資產融資 | B9: B2B2C 通路（電鐵/電力/物管/JobRad）CAC 趨近零；SPV 或 JAIC 式夥伴持有電池資產 | C9: CAC €120 → €30：36 月單戶淨值 +€90（V3 分頁 9 對照） | D9: 可抄，但關係型資產需時間 | E9: 弱—中
A10: 6. 用戶轉換成本 | B10: 無電池的車是 22kg 單速車、騎不動；但這是資產與付款關係，不是數據（V3 分頁 5）；且須提供買斷電池選項與「回家模式」 | C10: 中度鎖定，同時是客訴來源 | D10: — | E10: 中，但雙面刃
A11: 7. 手感繼承／APP | B11: 4–8 個助力參數，對手 2–3 趟收斂；歐盟資料法 2023/2854 要求資料可攜 | C11: 0 | D11: 一週內 | E11: 不是護城河（V3 結論四）
A12: 8. 硬體與低價本身 | B12: V3 八項降本槓桿中七項任何中國廠一週可複製；雅迪已把電池與充電器列為獨立營收（RMB 47.3 億） | C12: 0 | D12: 即時 | E12: 不是護城河
A13: 翻新迴圈每台年化節省（RMB） | B13: =(輪內可拆vs車架可拆!B25-輪內可拆vs車架可拆!C25*假設!$B$101)/4 -> 47.8122 | C13: ＝ (新包成本 − 翻新成本) ÷ 4 年更換週期
A15: 合計：可量化的結構性成本優勢（RMB/台）
A16: 1 + 2 + 翻新迴圈 | B16: =C5+C6+B13 -> 186.17196 | C16: =B16/入手價!C6 -> 0.14170569 | D16: 佔 V3 基準出廠價 RMB 1,314 的比例
A17: 可拿來做什麼 | B17: 補回力矩感測（RMB 160）或電池容量，做出同價位對手做不到的產品；或降 €1/月訂閱費擴大滲透

Sheet 日本付款路徑
A1: 日本三條付款路徑：通路零利率分期／法人租賃 B2B2C／ふるさと納税
A2: 日本沒有德國 JobRad 型薪資扣抵制度；公司貸與自行車屬現物給與、全額課稅。本表以配置 D（力矩版）PB 通路零售價與 202Wh 電池訂閱為基準。JPY。
A4: A. 假設（藍字可改）
A5: 參數 | B5: 值 | F5: 來源 / 說明
A6: 車體零售價（平地版，PB 通路，税込） | B6: =入手價!B30 -> 48666.115 | F6: 入手價表情境 3
A7: 車體零售價（坡地／載童版，税込，估） | B7: 58000 | F7: 前次分析：扭力 + 20 吋 + 45 N·m 馬達 + 後碟 + 子乗せ車架，PB 通路約 ¥58,000
A8: 電池月費（202Wh） | B8: =電池訂閱費!C61 -> 1280 | F8: 電池訂閱費表
A9: 電池月費（360Wh，載童版） | B9: =電池訂閱費!D61 -> 1680 | F9: 電池訂閱費表
A10: 分期回數 | B10: 36 | F10: JACCS／Orico ショッピングローン；Panasonic 官網、ハヤサカ最多 36 回無金利
A11: 消費者分期利率（無金利活動） | B11: 0 | F11: 通路負擔金利
A12: 通路負擔之分期手數料率（佔本金） | B12: 0.08 | F12: 假設：36 回無金利活動由通路支付金融公司約 8–12%
A13: NORUDE ViVi SX 整車訂閱月費 | B13: 2890 | F13: V3 分頁 9；36 月 ¥104,040，期末還車
A14: NORUDE 子乗せ月費 | B14: 5690 | F14: V3 分頁 9
A15: 員工邊際稅率（所得稅 + 住民稅） | B15: 0.2 | F15: 年收 500–700 萬圓區間概算；用於現物給與課稅
A16: 法人租賃：年利率 | B16: 0.05 | F16: 假設
A17: 法人租賃：期末殘值率（車體） | B17: 0.1 | F17: 假設；中國製車在日本二手市場近乎無行情
A18: 法人租賃：保養與保險（¥/月） | B18: 300 | F18: 假設；Yamaha PAS リース含保養保險
A19: 法人通路：訂閱呆帳率 | B19: 0.01 | F19: 公司統一請款
A20: 法人通路：訂閱 CAC（¥） | B20: 1000 | F20: B2B2C 通路，趨近零
A21: ふるさと納税：返礼品率上限 | B21: 0.3 | F21: 總務省基準：返礼品 ≤ 寄付額 3 割、含送料事務 ≤ 5 割
... A25: 自治體子乗せ補助（¥） | B25: 40000 | F25: 赤穂市 ¥4 萬、輕井澤町 ¥5 萬、廣島府中町 2026 新設；多要求型式認定／BAA
A27: B. 消費者視角：每月支出與 3 年總成本（平地版，202Wh）
A28: 路徑 | B28: 月付（¥） | C28: 前置費用（¥） | D28: 3 年總支出（¥） | E28: 期末車體歸屬 | F28: 說明
A29: ① 通路零利率分期 36 回 + 電池訂閱 | B29: =B6*(1+B11)/B10+B8 -> 2631.8365 | C29: 0 | D29: =B6*(1+B11)+B8*36 -> 94746.115 | E29: 消費者 | F29: 主打對比：與 NORUDE 同價位，但車歸自己、電池永遠有效
A30: ② A 法人付電池訂閱、員工自買車體（分期） | B30: =B6/B10+B8*B15 -> 1607.8365 | C30: 0 | D30: =B30*36 -> 57882.115 | E30: 員工 | F30: 員工月付 = 車體分期 + 電池訂閱現物給與之稅負；公司付電池月費
A31: ② B 法人全額租賃（車體 + 電池 + 保養），員工負擔課稅 | B31: =((B6*(1-B17))/B10+B6*B16/12+B8+B18)*B15 -> 599.88567 | C31: 0 | D31: =B31*36 -> 21595.884 | E31: 公司（期末殘值） | F31: 公司月付見 C 段；員工僅負擔現物給與稅
A32: ③ ふるさと納税（車體 + 首年電池訂閱券） | B32: =B8*(36-B23)/36 -> 853.33333 | C32: =B22 -> 2000 | D32: =B22+B8*(36-B23) -> 32720 | E32: 消費者 | F32: 前提：寄付額落在個人控除上限內（見 D 段），且產品符合地場產品基準
A33: 對照：NORUDE ViVi SX 整車訂閱 | B33: =B13 -> 2890 | C33: 3520 | D33: =B13*36+C33 -> 107560 | E33: NORUDE（還車） | F33: 事務手數料 ¥3,520；盜難補償 ¥700/月另計
A34: 對照：PELTECH 型式認定車買斷 ¥89,980 | B34: =89980/36 -> 2499.4444 | C34: 89980 | D34: =89980+5000*3 -> 104980 | E34: 消費者 | F34: 含年維護 ¥5,000；第 4 年換電池 ¥35,000 未計入 3 年
A35: ① 對 NORUDE 之 3 年差額（負值 = 本案較省） | D35: =D29-D33 -> -12813.885 | F35: 且車體歸消費者
A37: B-2. 載童版（360Wh）：分期 + 自治體補助
A38: 路徑 | B38: 月付（¥） | C38: 前置費用（¥） | D38: 3 年總支出（¥） | E38: 期末車體歸屬 | F38: 說明
A39: ① 載童版分期 36 回 + 360Wh 訂閱 | B39: =B7/B10+B9 -> 3291.1111 | C39: 0 | D39: =B7+B9*36 -> 118480 | E39: 消費者 | F39: 對照 NORUDE 子乗せ ¥5,690/月、Panasonic Gyutto ¥170,000
A40: ① 載童版 + 自治體補助（補助後車體一次付清） | B40: =B9 -> 1680 | C40: =MAX(B7-B25,0) -> 18000 | D40: =C40+B9*36 -> 78480 | E40: 消費者 | F40: 限有補助之自治體；須型式認定 + BAA
A41: 對照：NORUDE 子乗せ | B41: =B14 -> 5690 | C41: 3520 | D41: =B14*36+C41 -> 208360 | E41: NORUDE（還車）
A43: C. 營運商／通路視角：每戶 36 月淨值（電池訂閱）與車體通路成本
A44: 路徑 | B44: 訂閱月費（¥） | C44: 呆帳率 | D44: CAC（¥） | E44: 36 月單戶淨值（¥） | F44: 車體側成本 / 說明
A45: ① 通路分期（B2C） | B45: =B8 -> 1280 | C45: =假設!$B$75 -> 0.03 | D45: =假設!$B$83 -> 3000 | E45: =(B8/(1+假設!$B$74)*(1-假設!$B$75-假設!$B$76)-(假設!$B$78+假設!$B$79+假設!$B$77)-電池訂閱費!C54-電池訂閱費!C53)*假設!$B$82+電池訂閱費!C49*假設!$B$84-電池訂閱費!C51-假設!$B$83 -> 11153.926 | F45: ="車體通路須負擔分期手數料 ¥"&TEXT(B6*B12,"#,##0")&"/台（佔零售 "&TEXT(B12,"0%")&"）" -> 車體通路須負擔分期手數料 ¥3,893/台（佔零售 8%）
A46: ② 法人通路（B2B2C） | B46: =B8 -> 1280 | C46: =B19 -> 0.01 | D46: =B20 -> 1000 | E46: =(B8/(1+假設!$B$74)*(1-B19-假設!$B$76)-(假設!$B$78+假設!$B$79+假設!$B$77)-電池訂閱費!C54-電池訂閱費!C53)*假設!$B$82+電池訂閱費!C49*假設!$B$84-電池訂閱費!C51-B20 -> 13991.744 | F46: 公司統一請款、呆帳趨近零；Yamaha PAS リース 3 台起、NORUDE for Biz 為現成對照
A47: ③ ふるさと納税（首年由自治體支付，次年起 B2C） | B47: =B8 -> 1280 | C47: =假設!$B$75 -> 0.03 | D47: 0 | E47: =(B8/(1+假設!$B$74)*(1-假設!$B$75-假設!$B$76)-(假設!$B$78+假設!$B$79+假設!$B$77)-電池訂閱費!C54-電池訂閱費!C53)*假設!$B$82+電池訂閱費!C49*假設!$B$84-電池訂閱費!C51-0 -> 14153.926 | F47: CAC 為零（自治體通路）；但須在地組裝加價、且首年訂閱以躉售價賣給自治體
...

Sheet 三變體
A1: 三個產品變體：平地版／日本平地版／坡地載童版
A2: 同一車體平台，差異化延到總裝段。材料增額對配置 C（不含電池、不含充電器）計；RMB。
A4: A. 規格矩陣
A5: 項目 | B5: 平地版（歐洲／台灣） | C5: 日本平地版 | D5: 坡地載童版（日本、坡地城市） | E5: 說明
A6: 感測 | B6: 踏頻 + IMU + 相電流估算（B 方案） | C6: 中軸扭力感測（法規） | D6: 中軸扭力感測 | E6: 日本助力比以人力為分母，踏頻不能取證
A7: 控制邏輯 | B7: 速度保持：目標 20/22/25 km/h，22–25 線性衰減 | C7: 2:1 → 0 線性遞減（10–24 km/h） | D7: 同日本平地版 | E7: 兩套韌體皆鎖 OTP，出廠依市場燒錄
A8: 輪徑／齒比 | B8: 26 吋或 700c、44/16 | C8: 26 吋、44/16 | D8: 20–24 吋、42/18 | E8: 小輪徑 + 低齒比補單速在坡地的踏頻與扭矩
A9: 馬達 | B9: 商品化 250W 齒輪輪轂 30–32 N·m | C9: 同左 | D9: 40–45 N·m 級齒輪輪轂，含溫度感測與降額 | E9: 載童 125 kg 爬 10% 坡需 33 N·m（20 吋）
A10: 煞車 | B10: V 煞前後 | C10: V 煞前後 | D10: 後機械碟 + 前 V | E10: 30 kg 整車加小孩下坡，V 煞不過 JIS
A11: 車架 | B11: 公版鋁／鋼、無內走線 | C11: 公版 | D11: 通過幼児二人同乗基準之公版（BAA／SG）、両立スタンド、把手鎖 | E11: 仍是零開模公版
A12: 電池訂閱層級 | B12: 180／252Wh | C12: 144／202Wh | D12: 360Wh（更換週期抓 36 月） | E12: 電池在訂閱側切換，不動出廠價
A13: 目標市場 | B13: 台北、阿姆斯特丹、柏林等平地都會 | C13: 東京 23 區、大阪 | D13: 橫濱、神戶、長崎；日本載童家庭 | E13: 長坡（>10 分鐘連續爬升）不保證
A15: B. 材料增額與出廠價（RMB，對配置 C）
A16: 項目 | B16: 平地版 | C16: 日本平地版 | D16: 坡地載童版 | E16: 依據
A17: 配置 C 材料（不含電池、充電器） | B17: =入手價!B8 -> 799.216 | C17: =入手價!B8 -> 799.216 | D17: =入手價!B8 -> 799.216 | E17: 入手價表
A18: 扭力感測淨增額 | B18: 0 | C18: =假設!$B$14 -> 160 | D18: =假設!$B$14 -> 160 | E18: V3 分頁 7
A19: 日本非 BOM 增額（認定／PSE／說明書／OTP） | B19: 0 | C19: =假設!$B$15 -> 7.3 | D19: =假設!$B$15 -> 7.3 | E19: V3 分頁 7
A20: 馬達升級 40–45 N·m 級 | B20: 0 | C20: 0 | D20: 80 | E20: 假設：商品化 45 N·m 齒輪輪轂 RMB 280–300 vs 205
A21: 後機械碟煞（含碟煞座） | B21: 0 | C21: 0 | D21: 54 | E21: V3 分頁 2：機械碟 vs V 煞差 54
A22: 子乗せ車架強度與両立スタンド、把手鎖 | B22: 0 | C22: 0 | D22: 90 | E22: 假設：車架 +60、支撐與配件 +30
A23: 20 吋輪組差額 | B23: 0 | C23: 0 | D23: -10 | E23: 20 吋成輪較 26 吋便宜
A24: 型式認定 + 子乗せ檢測攤提 | B24: 0 | C24: 0 | D24: 8 | E24: ¥2–3M ÷ 2 萬台 ≈ ¥120 ≈ RMB 5–8
A25: 材料合計（RMB） | B25: =B17+SUM(B18:B24) -> 799.216 | C25: =C17+SUM(C18:C24) -> 966.516 | D25: =D17+SUM(D18:D24) -> 1188.516
A26: 出廠價 @ODM 13%（RMB，不含電池） | B26: =(B25+假設!$B$7)/(1-假設!$B$8) -> 943.92644 | C26: =(C25+假設!$B$7)/(1-假設!$B$8) -> 1136.2253 | D26: =(D25+假設!$B$7)/(1-假設!$B$8) -> 1391.3977
A27: 出廠價 @ODM 18%（RMB） | B27: =(B25+假設!$B$7)/(1-假設!$B$9) -> 1001.4829 | C27: =(C25+假設!$B$7)/(1-假設!$B$9) -> 1205.5073 | D27: =(D25+假設!$B$7)/(1-假設!$B$9) -> 1476.239
A28: 出廠價 @13%（NT$） | B28: =B26*假設!$B$20 -> 4285.426 | C28: =C26*假設!$B$20 -> 5158.4628 | D28: =D26*假設!$B$20 -> 6316.9456
A29: 出廠價 @13%（JPY） | B29: =B26*假設!$B$21 -> 22182.271 | C29: =C26*假設!$B$21 -> 26701.294 | D29: =D26*假設!$B$21 -> 32697.846
A30: 對平地版出廠價之溢出 | B30: =B26/$B$26-1 -> 0 | C30: =C26/$B$26-1 -> 0.20372229 | D30: =D26/$B$26-1 -> 0.47405311
A32: C. 各市場零售（含稅）與電池訂閱
A33: 項目 | B33: 平地版 | C33: 日本平地版 | D33: 坡地載童版 | E33: 公式
A34: 歐洲 DTC 零售 €（台越製） | B34: =(B26/假設!$B$19*(1+假設!$B$25)+假設!$B$26)/(1-假設!$B$27)*(1+假設!$B$46) -> 184.2571 | C34: — | D34: =(D26/假設!$B$19*(1+假設!$B$25)+假設!$B$26)/(1-假設!$B$27)*(1+假設!$B$46) -> 264.66169 | E34: 入手價表結構；坡地版在歐洲坡地城市亦適用
A35: 台灣 DTC 零售 NT$ | B35: =(B28+150)/(1-假設!$B$30)*(1+假設!$B$31) -> 7164.919 | C35: — | D35: =(D28+150)/(1-假設!$B$30)*(1+假設!$B$31) -> 10446.604 | E35: 台灣坡地（北投、基隆）可用坡地版
A36: 日本 PB 通路零售 ¥（税込） | B36: — | C36: =((C29*(1+假設!$B$32)+假設!$B$33+假設!$B$34+假設!$B$35+假設!$B$36)-假設!$B$37)/(1-假設!$B$38)*(1+假設!$B$41) -> 48666.115 | D36: =((D29*(1+假設!$B$32)+假設!$B$33+假設!$B$34+假設!$B$35+假設!$B$36)-假設!$B$37)/(1-假設!$B$38)*(1+假設!$B$41) -> 58466.194 | E36: V3 分頁 8 情境 3；載童版不含兒童座椅
A37: 日本 BESV 通路零售 ¥（15% + 22%） | B37: — | C37: =(C29*(1+假設!$B$32)+假設!$B$33+假設!$B$34+假設!$B$35+假設!$B$36)/(1-假設!$B$39)/(1-假設!$B$40)*(1+假設!$B$41) -> 57188.96 | D37: =(D29*(1+假設!$B$32)+假設!$B$33+假設!$B$34+假設!$B$35+假設!$B$36)/(1-假設!$B$39)/(1-假設!$B$40)*(1+假設!$B$41) -> 67535.951 | E37: V3 分頁 8 情境 2
A38: 電池訂閱月費（建議定價） | B38: ="€"&TEXT(電池訂閱費!C19,"0.0")&" / NT$"&TEXT(電池訂閱費!C40,"#,##0") -> €9.9 / NT$299 | C38: ="¥"&TEXT(電池訂閱費!C61,"#,##0") -> ¥1,280 | D38: ="¥"&TEXT(電池訂閱費!D61,"#,##0") -> ¥1,680 | E38: 電池訂閱費表
A39: 日本對照（税込） | B39: — | C39: Cainz PB ¥59,800／Panasonic ビビ EYX ¥89,800 | D39: Panasonic Gyutto ¥170,000／Yamaha PAS Kiss ¥187,000 | E39: V3 分頁 8 C 段
A41: D. 物理檢核：輪端扭矩、踏頻與騎士出力（藍字可改）
A42: 參數 | B42: 值 | E42: 說明
A43: 重力加速度 g | B43: 9.81 | E43: m/s²
A44: 滾動阻力係數 Crr | B44: 0.006 | E44: 盡調報告假設
...

Sheet 五年財務
A1: 五年財務計畫（達方視角，NT$ 百萬）
A2: 硬體以出廠價加達方毛利賣給通路；電池訂閱由達方（或 SPV）持有資產並收月費。藍字為量與比率假設。
A4: A. 量與組合假設
A5: 項目 | B5: 2027 | C5: 2028 | D5: 2029 | E5: 2030 | F5: 2031 | G5: 說明
A6: 整車出貨量（台） | B6: 8000 | C6: 25000 | D6: 50000 | E6: 80000 | F6: 110000 | G6: 保守：原提案 Y5 45 萬台被盡調否決；30k 為出廠價達標門檻
A7: 歐洲平地版占比 | B7: 0.5 | C7: 0.5 | D7: 0.5 | E7: 0.5 | F7: 0.5
A8: 日本平地版占比 | B8: 0.18 | C8: 0.18 | D8: 0.18 | E8: 0.18 | F8: 0.18
A9: 日本載童版占比 | B9: 0.12 | C9: 0.12 | D9: 0.12 | E9: 0.12 | F9: 0.12
A10: 台灣／其他平地版占比 | B10: 0.2 | C10: 0.2 | D10: 0.2 | E10: 0.2 | F10: 0.2
A11: 電池訂閱附加率（未買斷比例） | B11: 0.85 | C11: 0.85 | D11: 0.85 | E11: 0.85 | F11: 0.85 | G11: 提供買斷選項；假設 15% 買斷
A12: 訂戶年留存率 | B12: 0.8 | C12: 0.8 | D12: 0.8 | E12: 0.8 | F12: 0.8 | G12: 平均壽命 36 月 ≈ 年留存 75–80%
A13: 達方硬體毛利率（對出廠價加成） | B13: 0.2 | C13: 0.2 | D13: 0.2 | E13: 0.2 | F13: 0.2 | G13: 品牌／整合／保固；8/28 門檻 ≥ 15%
A15: B. 單價（NT$／台或／戶，連動模型）
A16: 項目 | B16: 歐洲平地 | C16: 日本平地 | D16: 日本載童 | E16: 台灣平地 | F16: 加權 | G16: 說明
A17: 出廠價（NT$） | B17: =三變體!B28 -> 4285.426 | C17: =三變體!C28 -> 5158.4628 | D17: =三變體!D28 -> 6316.9456 | E17: =三變體!B28 -> 4285.426 | F17: =B17*$B$7+C17*$B$8+D17*$B$9+E17*$B$10 -> 4686.355 | G17: 三變體表；加權以 2027 組合計
A18: 電池月費（NT$，含稅） | B18: =電池訂閱費!C19*假設!$B$19*假設!$B$20 -> 485.4168 | C18: =電池訂閱費!C61/假設!$B$21*假設!$B$20 -> 247.28511 | D18: =電池訂閱費!D61/假設!$B$21*假設!$B$20 -> 324.5617 | E18: =電池訂閱費!C40 -> 299 | F18: =B18*$B$7+C18*$B$8+D18*$B$9+E18*$B$10 -> 385.96712 | G18: €9.9／¥1,280／¥1,680／NT$299
A19: 月費淨額係數（除 VAT／消費稅） | B19: =1/(1+假設!$B$46) -> 0.84033613 | C19: =1/(1+假設!$B$41) -> 0.90909091 | D19: =1/(1+假設!$B$41) -> 0.90909091 | E19: =1/(1+假設!$B$31) -> 0.95238095 | F19: =B19*$B$7+C19*$B$8+D19*$B$9+E19*$B$10 -> 0.88337153
A20: 每戶每月現金成本（NT$，③④⑤⑥ + 呆帳金流） | B20: =(電池訂閱費!C12+電池訂閱費!C13+電池訂閱費!C19/(1+假設!$B$46)*(假設!$B$47+假設!$B$48))*假設!$B$19*假設!$B$20 -> 186.47491 | C20: =(電池訂閱費!C54+電池訂閱費!C55+電池訂閱費!C61/(1+假設!$B$41)*(假設!$B$75+假設!$B$76))/假設!$B$21*假設!$B$20 -> 103.6637 | D20: =(電池訂閱費!D54+電池訂閱費!D55+電池訂閱費!D61/(1+假設!$B$41)*(假設!$B$75+假設!$B$76))/假設!$B$21*假設!$B$20 -> 120.3341 | E20: =電池訂閱費!C33+電池訂閱費!C34+電池訂閱費!C40/(1+假設!$B$31)*(假設!$B$61+假設!$B$62) -> 110.22742 | F20: =B20*$B$7+C20*$B$8+D20*$B$9+E20*$B$10 -> 148.3825 | G20: 更換準備 + 失竊／客服／物流 + 呆帳金流；資產與 CAC 另列
A21: 每戶電池 + 充電器資產（NT$） | B21: =電池訂閱費!C9*假設!$B$19*假設!$B$20 -> 2007.0341 | C21: =電池訂閱費!C51/假設!$B$21*假設!$B$20 -> 1658.1908 | D21: =電池訂閱費!D51/假設!$B$21*假設!$B$20 -> 2239.1856 | E21: =電池訂閱費!C30 -> 1808.402 | F21: =B21*$B$7+C21*$B$8+D21*$B$9+E21*$B$10 -> 1932.3741 | G21: 資本支出；4 年折舊
A22: 每戶 CAC（NT$） | B22: =假設!$B$55*假設!$B$19*假設!$B$20 -> 1470.96 | C22: =假設!$B$83/假設!$B$21*假設!$B$20 -> 579.57447 | D22: =假設!$B$83/假設!$B$21*假設!$B$20 -> 579.57447 | E22: =假設!$B$69 -> 800 | F22: =B22*$B$7+C22*$B$8+D22*$B$9+E22*$B$10 -> 1069.3523 | G22: 隨車成交
A24: C. 營運費用假設（NT$ 百萬／年）
A25: 項目 | B25: 2027 | C25: 2028 | D25: 2029 | E25: 2030 | F25: 2031 | G25: 說明
A26: 三電 RD（韌體、控制器、電池包） | B26: 5 | C26: 5 | D26: 8 | E26: 8 | F26: 8 | G26: 8/28：RD NT$3–5M 上限起步
A27: APP／雲端／資料團隊 | B27: 6 | C27: 8 | D27: 8 | E27: 10 | F27: 10 | G27: BOM 報告：完整 IoT 平台 NT$12M；本案 BLE + SoH 較輕
A28: 認證與模具（EN 15194／UN38.3／日本型式認定 ×3／PSE） | B28: 4 | C28: 4 | D28: 3 | E28: 1 | F28: 1 | G28: US$130k + ¥2–3M + 模具
A29: 翻新中心與逆物流建置（歐、日各一） | B29: 3 | C29: 10 | D29: 5 | E29: 3 | F29: 3 | G29: 含治具、危險品倉儲
A30: 行銷與通路（佔硬體營收） | B30: 0.08 | C30: 0.06 | D30: 0.05 | E30: 0.05 | F30: 0.05 | G30: 比率；DTC 與 B2B2C 混合
A31: 管理與其他（佔總營收） | B31: 0.04 | C31: 0.03 | D31: 0.03 | E31: 0.03 | F31: 0.03 | G31: 比率
A33: D. 損益與現金流（NT$ 百萬）
A34: 項目 | B34: 2027 | C34: 2028 | D34: 2029 | E34: 2030 | F34: 2031 | G34: 公式
A35: 新增訂戶（戶） | B35: =B6*B11 -> 6800 | C35: =C6*C11 -> 21250 | D35: =D6*D11 -> 42500 | E35: =E6*E11 -> 68000 | F35: =F6*F11 -> 93500 | G35: 出貨 × 附加率
A36: 期末在訂戶（戶） | B36: =B35 -> 6800 | C36: =B36*C12+C35 -> 26690 | D36: =C36*D12+D35 -> 63852 | E36: =D36*E12+E35 -> 119081.6 | F36: =E36*F12+F35 -> 188765.28 | G36: 上期 × 留存 + 新增
A37: 平均在訂戶（戶） | B37: =B36/2 -> 3400 | C37: =(B36+C36)/2 -> 16745 | D37: =(C36+D36)/2 -> 45271 | E37: =(D36+E36)/2 -> 91466.8 | F37: =(E36+F36)/2 -> 153923.44
A38: 硬體營收 | B38: =B6*$F$17*(1+B13)/1000000 -> 44.989008 | C38: =C6*$F$17*(1+C13)/1000000 -> 140.59065 | D38: =D6*$F$17*(1+D13)/1000000 -> 281.1813 | E38: =E6*$F$17*(1+E13)/1000000 -> 449.89008 | F38: =F6*$F$17*(1+F13)/1000000 -> 618.59886 | G38: 出貨 × 出廠價 × (1 + 達方毛利)
A39: 硬體成本 | B39: =B6*$F$17/1000000 -> 37.49084 | C39: =C6*$F$17/1000000 -> 117.15887 | D39: =D6*$F$17/1000000 -> 234.31775 | E39: =E6*$F$17/1000000 -> 374.9084 | F39: =F6*$F$17/1000000 -> 515.49905 | G39: 以出廠價採購
A40: 訂閱營收（淨額） | B40: =B37*$F$18*$F$19*12/1000000 -> 13.910857 | C40: =C37*$F$18*$F$19*12/1000000 -> 68.510969 | D40: =D37*$F$18*$F$19*12/1000000 -> 185.22306 | E40: =E37*$F$18*$F$19*12/1000000 -> 374.22987 | F40: =F37*$F$18*$F$19*12/1000000 -> 629.76674 | G40: 平均戶 × 月費淨額 × 12
A41: 訂閱現金成本 | B41: =B37*$F$20*12/1000000 -> 6.0540059 | C41: =C37*$F$20*12/1000000 -> 29.815979 | D41: =D37*$F$20*12/1000000 -> 80.609088 | E41: =E37*$F$20*12/1000000 -> 162.86487 | F41: =F37*$F$20*12/1000000 -> 274.07453
A42: 訂閱 CAC | B42: =B35*$F$22/1000000 -> 7.2715959 | C42: =C35*$F$22/1000000 -> 22.723737 | D42: =D35*$F$22/1000000 -> 45.447474 | E42: =E35*$F$22/1000000 -> 72.715959 | F42: =F35*$F$22/1000000 -> 99.984444
A43: 電池資產折舊（4 年） | B43: =B35*$F$21/4/1000000 -> 3.2850359 | C43: =B35*$F$21/4/1000000+C35*$F$21/4/1000000 -> 13.550773 | D43: =B35*$F$21/4/1000000+C35*$F$21/4/1000000+D35*$F$21/4/1000000 -> 34.082248 | E43: =B35*$F$21/4/1000000+C35*$F$21/4/1000000+D35*$F$21/4/1000000+E35*$F$21/4/1000000 -> 66.932607 | F43: =C35*$F$21/4/1000000+D35*$F$21/4/1000000+E35*$F$21/4/1000000+F35*$F$21/4/1000000 -> 108.81681 | G43: 新增訂戶資產 ÷ 4，攤 4 年
A44: 總營收 | B44: =B38+B40 -> 58.899865 | C44: =C38+C40 -> 209.10162 | D44: =D38+D40 -> 466.40436 | E44: =E38+E40 -> 824.11994 | F44: =F38+F40 -> 1248.3656
...

Sheet 兩條路對照
A1: 兩條路五年對照與決策門檻：合規電池平台 + OEM 服務（C1） vs 低價整車 + 電池訂閱（B2C）
A2: C1 參數取自 V4 分頁 11；B2C 連動五年財務分頁並以量級倍數做情境。NT$ 百萬除非另註。藍字可改。
A4: A. C1 假設（V4 分頁 11）
A5: 參數 | B5: 值 | G5: 來源
A6: 三電成本 €/台 | B6: 55 | G6: RMB 595 ÷ 10.8
A7: 賣 OEM 毛利率 | B7: 0.25 | G7: Tier 1 常見 20–30%
A8: 服務合約 €/台/年 | B8: 10 | G8: 護照、EPR、備品、SoH、回收；無公開價格
A9: 服務成本 €/台/年 | B9: 4.5 | G9: 系統、行政、備品攤提
A10: 在保年數（服務收費期） | B10: 5 | G10: 備品義務 5 年
A11: EUR/NTD | B11: =假設!$B$19*假設!$B$20 -> 49.032 | G11: ＝ RMB/EUR × NTD/RMB
A12: C1 固定費用：合規系統與團隊（NT$M/年） | B12: 25 | G12: 護照平台 €80–150k + EPR 27 國 + 團隊；假設
A13: C1 建置一次性（NT$M，第一年） | B13: 15 | G13: 系統與備品初始庫存
A14: C1 第一年出貨占穩態比例 | B14: 0.5 | G14: 爬坡
A16: C1 年出貨情境（台/年） | B16: 悲觀 | C16: 基準 | D16: 樂觀 | G16: 說明
A17: 三電白牌年出貨 | B17: 30000 | C17: 60000 | D17: 100000 | G17: 歐洲中價位用八方／安乃達的品牌約 30–45 萬台/年（估）
A18: 第 5 年在保台數 | B18: =B17*$B$10 -> 150000 | C18: =C17*$B$10 -> 300000 | D18: =D17*$B$10 -> 500000
A19: 第 5 年硬體毛利（NT$M） | B19: =B17*$B$6/(1-$B$7)*$B$7*$B$11/1000000 -> 26.9676 | C19: =C17*$B$6/(1-$B$7)*$B$7*$B$11/1000000 -> 53.9352 | D19: =D17*$B$6/(1-$B$7)*$B$7*$B$11/1000000 -> 89.892
A20: 第 5 年服務毛利（NT$M） | B20: =B18*($B$8-$B$9)*$B$11/1000000 -> 40.4514 | C20: =C18*($B$8-$B$9)*$B$11/1000000 -> 80.9028 | D20: =D18*($B$8-$B$9)*$B$11/1000000 -> 134.838
A21: 第 5 年營收（NT$M） | B21: =(B17*$B$6/(1-$B$7)+B18*$B$8)*$B$11/1000000 -> 181.4184 | C21: =(C17*$B$6/(1-$B$7)+C18*$B$8)*$B$11/1000000 -> 362.8368 | D21: =(D17*$B$6/(1-$B$7)+D18*$B$8)*$B$11/1000000 -> 604.728
A22: 第 5 年 EBIT（NT$M） | B22: =B19+B20-$B$12 -> 42.419 | C22: =C19+C20-$B$12 -> 109.838 | D22: =D19+D20-$B$12 -> 199.73
A23: 五年累計 EBIT（NT$M，服務基數線性累積） | B23: =5*B19+B20*(1+2+3+4+5)/5-5*$B$12-$B$13 -> 116.1922 | C23: =5*C19+C20*(1+2+3+4+5)/5-5*$B$12-$B$13 -> 372.3844 | D23: =5*D19+D20*(1+2+3+4+5)/5-5*$B$12-$B$13 -> 713.974
A24: 資金需求峰值（NT$M） | B24: =MAX($B$13+$B$12-(B19+B20/5)*$B$14,0) -> 22.47106 | C24: =MAX($B$13+$B$12-(C19+C20/5)*$B$14,0) -> 4.94212 | D24: =MAX($B$13+$B$12-(D19+D20/5)*$B$14,0) -> 0 | G24: 第一年：建置 + 固定費用 − 首年毛利；零電池資產、零 CAC
A26: B. B2C 情境（連動五年財務分頁，以量級倍數縮放）
A27: 項目 | B27: 悲觀 | C27: 基準 | D27: 樂觀 | G27: 說明
A28: 量級倍數（對五年財務基準 110k） | B28: 0.36 | C28: 1 | D28: 2.3 | G28: 悲觀 40k、基準 110k、樂觀 250k（SAM 4.7M 的 1–5%）
A29: 第 5 年出貨（台） | B29: =B28*五年財務!F6 -> 39600 | C29: =C28*五年財務!F6 -> 110000 | D29: =D28*五年財務!F6 -> 253000
A30: 第 5 年營收（NT$M） | B30: =B28*五年財務!F44 -> 449.41161 | C30: =C28*五年財務!F44 -> 1248.3656 | D30: =D28*五年財務!F44 -> 2871.2409
A31: 第 5 年 EBIT（NT$M） | B31: =B28*(五年財務!F45-五年財務!F48-五年財務!F49)-五年財務!F47 -> 43.379545 | C31: =C28*(五年財務!F45-五年財務!F48-五年財務!F49)-五年財務!F47 -> 159.60985 | D31: =D28*(五年財務!F45-五年財務!F48-五年財務!F49)-五年財務!F47 -> 395.70265 | G31: 毛利與變動費用隨量縮放，RD／APP／認證／翻新建置固定
A32: 五年累計現金流（NT$M） | B32: =B28*(五年財務!F54+SUM(五年財務!B47:F47))-SUM(五年財務!B47:F47) -> -72.235914 | C32: =C28*(五年財務!F54+SUM(五年財務!B47:F47))-SUM(五年財務!B47:F47) -> 0.2335724 | D32: =D28*(五年財務!F54+SUM(五年財務!B47:F47))-SUM(五年財務!B47:F47) -> 147.43722
A33: 資金需求峰值（NT$M，自持電池） | B33: =B28*(五年財務!B56-SUM(五年財務!B47:D47))+SUM(五年財務!B47:D47) -> 80.349826 | C33: =C28*(五年財務!B56-SUM(五年財務!B47:D47))+SUM(五年財務!B47:D47) -> 100.52729 | D33: =D28*(五年財務!B56-SUM(五年財務!B47:D47))+SUM(五年財務!B47:D47) -> 141.51278 | G33: 近似：峰值中的電池資本與 CAC 隨量縮放，前三年固定費用不縮放
A34: 資金需求峰值（NT$M，SPV 持有電池） | B34: =MAX(B28*(-五年財務!B57-SUM(五年財務!B47:C47))+SUM(五年財務!B47:C47),0) -> 35.343775 | C34: =MAX(C28*(-五年財務!B57-SUM(五年財務!B47:C47))+SUM(五年財務!B47:C47),0) -> 18.177152 | D34: =MAX(D28*(-五年財務!B57-SUM(五年財務!B47:C47))+SUM(五年財務!B47:C47),0) -> 0
A35: 第 5 年在訂戶（戶） | B35: =B28*五年財務!F36 -> 67955.501 | C35: =C28*五年財務!F36 -> 188765.28 | D35: =D28*五年財務!F36 -> 434160.14
A37: C. 五年對照（基準情境）
A38: 面向 | B38: C1 合規電池平台 + OEM 服務 | C38: B2C 低價整車 + 電池訂閱 | G38: 判讀
A39: 第 5 年營收（NT$M） | B39: =C21 -> 362.8368 | C39: =C30 -> 1248.3656 | G39: B2C 約為 C1 的 2.5–3 倍
A40: 第 5 年 EBIT（NT$M） | B40: =C22 -> 109.838 | C40: =C31 -> 159.60985 | G40: 同一數量級
A41: 資金需求峰值（NT$M） | B41: =C24 -> 4.94212 | C41: =C33 -> 100.52729 | G41: B2C 自持電池；SPV 時見 B 段
A42: EBIT ÷ 峰值資金（倍） | B42: =IF(C24>0,C22/C24,99) -> 22.224875 | C42: =C31/C33 -> 1.5877265 | G42: 資本效率
A43: 悲觀情境第 5 年 EBIT（NT$M） | B43: =B22 -> 42.419 | C43: =B31 -> 43.379545 | G43: 下檔
A44: 樂觀情境第 5 年 EBIT（NT$M） | B44: =D22 -> 199.73 | C44: =D31 -> 395.70265 | G44: 上檔
...
