Workbook

Sheet BOM清單
A1: 極簡版 Hub-motor E-Bike BOM 清單：單價、報價出處、MOQ、供應商（RMB，10 萬台/年估）
A2: 基準：V4 模型分頁 1「單價來源（已查證，MOQ 標註於備註）」極簡配置，材料合計 RMB 1,121；補充盡調報告、三電 BOM 報告附錄 A（BESV 2026/06 內部錨點）與附錄 B（外部基準）。藍字為單價輸入，黑字為公式。「來源文件已具名」為文件中出現的供應商／品牌；「建議詢價」為本表補充、尚未接觸亦無報價。2026-09-23
A4: 序 | B4: 系統 | C4: 項目 | D4: 規格 | E4: 數量 | F4: 單價 RMB | G4: 小計 RMB | H4: 報價依據（掛牌價／錨點原值） | I4: MOQ／量級 | J4: 報價出處（文件） | K4: 來源文件已具名之供應商／品牌 | L4: 建議詢價供應商（本表補充，未接觸） | M4: 驗證狀態 | N4: 備註／待辦
A5: 匯率 USD/RMB | F5: 7.05 | H5: V4 分頁 1 B6
A6: 匯率 NTD/RMB | F6: 4.54 | H6: V4 分頁 1 B7
A7: 電芯單價 RMB/Wh | F7: 0.66 | H7: V4 分頁 1 B10：21700 量產 RMB 610–720/kWh；DMEGC 50E $1.80–1.90 @MOQ100
A8: 電池包加工毛利 | F8: 0.18 | H8: V4 分頁 1 B12
A10: 1. 三電（不含電池）── 計入出廠價
A11: 1 | B11: 三電 | C11: 250W 齒輪後輪轂馬達 | D11: 商品化 2.3–3.0 kg、輪端 30–32 N·m、135mm 開檔、螺紋單速飛輪座；控制器整合側蓋另計 | E11: 1 | F11: 205 | G11: =E11*F11 -> 205 | H11: 常州 Found US$34–45 @30 set、US$34.5–39.2 @100 pc；Bafang RM G010 FOB US$69–79 @500 pcs（3.0 kg／32 N·m）；八方／安乃達齒輪輪轂 ASP RMB 230–335（年報）；通用 250W 輪轂 Alibaba ≈US$55；BESV 錨點 AKM 後輪轂 NT$2,807（小量） | I11: 30–500 pc；年報 ASP 為量產 | J11: V4 分頁 1；盡調報告第二、四節；BOM 報告附錄 A、B | K11: 常州 Found；Bafang 八方（RM G010、G310）；Ananda 安乃達（AKM 品牌，BESV 既有供應商）；Mivice（Tenways 用，40 N·m）；Mahle X20／X35+（OEM 專供，無公開價，僅對照） | L11: Shengyi 盛義、XOFO 信孚；請 Bafang／Ananda／Found 報「輪轂 + 側蓋整合控制器」整合價 | M11: 掛牌價／年報 ASP | N11: 盡調：1.35 kg／40 N·m 無量產品，ALEX TK-06U 為 IP54 螺紋飛輪、寬 83.2mm，不採用。三檔（10k／30k／100k）書面報價為第一優先
A12: 2 | B12: 三電 | C12: 36V 15A 正弦波控制器（整合側蓋） | D12: 同時吃踏頻脈衝與 0–5V 扭力訊號；限速與峰值電流燒 OTP；燈輸出、煞車斷電 | E12: 1 | F12: 60 | G12: =E12*F12 -> 60 | H12: 外掛控制器 US$7.2 @100 pc + 外殼／相線束／連接器／支架／工時；整合進側蓋省 RMB 23–41；BESV 錨點 YTMT02（RPM 250W for 8FUN MAX）NT$1,126、Controller cartridge 3G 達方自製 NT$2,577、YCDT03 25 km/h EU NT$2,050 | I12: 100 pc（外掛掛牌） | J12: V4 分頁 1、分頁 7；BOM 報告附錄 A | K12: 達方自製 controller cartridge；YTMT02、YCDT03（BESV 既有料號，供應商未具名） | L12: 麗水 Lishui、昆騰 KT；或由達方韌體 + 馬達廠側蓋共同開發（達瑞 actuator 團隊） | M12: 掛牌價／內部錨點 | N12: V4 分頁 7：控制器設計成雙訊號輸入，每台多 RMB 1–2，差異化延到總裝
A13: 3 | B13: 三電 | C13: PAS 踏頻盤 | D13: 12 磁極 + 引線（比 5 磁極反應快） | E13: 1 | F13: 8 | G13: =E13*F13 -> 8 | H13: US$1.99 @568 pc（12 磁極貴約 RMB 2） | I13: 568 pc | J13: V4 分頁 1、分頁 7 | K13: 未具名（1688／Made-in-China 通用件） | L13: 通用件，隨馬達廠配套詢價 | M13: 掛牌價 | N13: 分頁 7 列 RMB 10（含引線），分頁 1 列 8，本表取分頁 1
A14: 4 | B14: 三電 | C14: 單鍵 RGB 按鍵 + 4pin 線束（無儀表） | D14: 上管或把手單鍵、3 段 LED 電量；取代 LCD + HiGo 5pin | E14: 1 | F14: 22 | G14: =E14*F14 -> 22 | H14: LCD US$8.38–10.21 @10 pc + HiGo 5pin 線束（傳統配置 RMB 70）vs 單鍵 RGB + 4pin（極簡 RMB 22） | I14: 10 pc（LCD 對照） | J14: V4 分頁 1；BOM 報告附錄 A（LCM NT$534、TFT NT$1,164 對照） | K14: HiGo（連接器／線束品牌） | L14: HiGo、Julet 線束；按鍵通用件 | M14: 掛牌價
A15: 5 | B15: 三電 | C15: 主線束 | D15: 無變速線、無儀表線；外走線 | E15: 1 | F15: 25 | G15: =E15*F15 -> 25 | H15: V4：傳統 38 → 極簡 25；BESV 錨點 Cartridge 主線束 5 條 NT$771、整車主線束 NT$1,264（小量） | I15: — | J15: V4 分頁 1；BOM 報告附錄 A | K15: 未具名 | L15: HiGo、Julet | M15: 估值（含錨點對照）
C16: 三電小計（V4 極簡配置基準） | G16: =SUM(G11:G15) -> 320
A18: 1b. 三電 B 方案增量（踏頻 + IMU + 電流估算；V4 分頁 7）
A19: 6 | B19: 三電 B 方案增量 | C19: 煞把斷電開關 ×2 | D19: 磁簧式，整合於煞車把手；EN 15194 §4.2.13.1 斷電距離 ≤2 m | E19: 2 | F19: 6 | G19: =E19*F19 -> 12 | H19: V4 分頁 7：RMB 12／對（A、B、C 三方案皆列）；BESV 錨點煞車斷電感測開關 NT$180／個（小量） | I19: — | J19: V4 分頁 7；BOM 報告附錄 A | K19: 未具名 | L19: 無錫五星 Wuxing、Promax（含斷電把手） | M19: 需對帳 | N19: 分頁 1 極簡配置未單列此項，分頁 7 有列；出廠價模型以分頁 1 為準，本表獨立列出供對帳
A20: 7 | B20: 三電 B 方案增量 | C20: 6 軸 IMU | D20: 判坡度與加速度，改善踏頻方案起步手感（B 方案） | E20: 1 | F20: 8 | G20: =E20*F20 -> 8 | H20: V4 分頁 7：RMB 8（僅 B 方案） | I20: — | J20: V4 分頁 7 | K20: 未具名 | L20: TDK InvenSense、Bosch Sensortec、ST | M20: 估值 | N20: 全球版建議走 B 方案（V4 分頁 7 E 段）
C21: B 方案增量小計 | G21: =SUM(G19:G20) -> 20
A23: 2. 電池與充電器 ── 訂閱資產，不計入出廠價
A24: 8 | B24: 電池 | C24: 電芯（180Wh 標準） | D24: 10s1p 21700 5Ah（10 顆）；252Wh 為 10s2p 18650 3.5Ah（20 顆）；360Wh 為 10s2p 21700 5Ah | E24: 180 | F24: =F7 -> 0.66 | G24: =E24*F24 -> 118.8 | H24: 21700 量產 RMB 610–720/kWh；DMEGC 50E US$1.80–1.90 @MOQ100；Alibaba 客製包 Samsung 50S US$1.45–2.20／顆（≈US$0.08–0.12/Wh）；中系 50E 級小批 US$1.98–3.50／顆；BNEF 2025 車用電芯均價 US$79/kWh（對照） | I24: MOQ100（DMEGC）；量產 kWh 報價 | J24: V4 分頁 1；BOM 報告附錄 B（Alibaba、BNEF）；盡調報告第四節 | K24: DMEGC 橫店東磁（50E）；Samsung SDI（50E／50S） | L24: EVE 億緯、BAK 比克、Lishen 力神；達宇既有電芯供應商（達方捷克廠現用電芯） | M24: 掛牌價／公開均價 | N24: 數量欄為 Wh；單價為 RMB/Wh。日本版 144Wh 為 10s1p 21700 4.0Ah
A25: 9 | B25: 電池 | C25: 電池包固定成本（BMS、外殼／軌道／鎖、連接器／鎳片／點焊／測試） | D25: 10s BMS 含均衡、BLE SoH 回報、電池護照資料；ABS 殼；下管滑軌 + 鑰匙鎖；防呆放電連接器 | E25: 1 | F25: 120 | G25: =E25*F25 -> 120 | H25: V4 分頁 1 B11：BMS 11–18 + 外殼／軌道／鎖 28–49 + 連接器／鎳片／點焊／測試 14–28；不隨容量縮小 | I25: — | J25: V4 分頁 1 | K25: 未具名 | L25: BMS：達方自製（含護照資料）或中系 BMS 廠；殼與軌道：模具件（達宇／蘇州） | M25: 需對帳 | N25: 分項上限合計 95，與 120 差 25 未說明；電芯級可換（電芯座 + 彈簧接點）另 +RMB 20（V3 補充模型假設）
C26: 電池包 FOB（180Wh）= (電芯 + 固定成本) × (1 + 加工毛利) | G26: =(G24+G25)*(1+F8) -> 281.784 | H26: V4 分頁 1 D17 = 281.8；本表公式對帳 | L26: 電池包組裝：達宇（Darfon Energy）／蘇州；歐洲落地可用達方捷克廠（年產 30 萬組，Bike Europe 2023/12） | M26: 公式
C27: 電池包 FOB（252Wh，參考） | D27: 10s2p 18650 3.5Ah | G27: =(252*F7+G25)*(1+F8) -> 337.8576 | H27: 同上成本函數 | M27: 公式
C28: 電池包 FOB（360Wh，參考） | D28: 10s2p 21700 5Ah | G28: =(360*F7+G25)*(1+F8) -> 421.968 | H28: 同上成本函數 | M28: 公式
A30: 10 | B30: 電池 | C30: 充電器 36V 2A | D30: 全電壓、CE／GS；日本版為 ◇PSE 特定電気用品 | E30: 1 | F30: 40 | G30: =E30*F30 -> 40 | H30: V4 分頁 1：RMB 40（CE/GS）；BOM 報告附錄 B：Alibaba 42V 2A 充電器批發 US$6.5–11；BESV 錨點 36V 2A 全電壓充電器 NT$532、電源板 B240-003 NT$978（小量） | I30: — | J30: V4 分頁 1；BOM 報告附錄 A、B | K30: 未具名 | L30: 中系充電器廠（深圳／東莞）；日本 ◇PSE 需登録検査機関 + 海外工廠檢查（費用數百萬円，V4 分頁 13） | M30: 掛牌價／內部錨點 | N30: 隨訂閱提供，不含在車價內
C31: 電池 + 充電器小計（180Wh，訂閱資產） | G31: =G26+G30 -> 321.784
A33: 3. 車體 ── 計入出廠價
A34: 11 | B34: 車體 | C34: 車架 + 前叉（含塗裝） | D34: 極簡配置取高拉力鋼公版；135mm 開檔、無內走線孔；鋁架為 +RMB 110 選項 | E34: 1 | F34: 100 | G34: =E34*F34 -> 100 | H34: 6061 鋁 US$25 @500 pc／US$40 @100 pc；高拉力鋼中國內銷 RMB 150–400；極簡配置取 RMB 100（鋼） | I34: 100–500 pc | J34: V4 分頁 1、分頁 2 | K34: 未具名 | L34: 台灣／越南既有 EN 15194 認證車架廠（世同、太宇現有供應鏈）；天津車架廠；日本載童版須通過幼児二人同乗基準之公版 | M34: 掛牌價 | N34: 鋼比鋁重 1.2–1.5 kg；金屬 +40%、塑料 +80% 為 2026/4 漲價主因（V4 分頁 3）
A35: 12 | B35: 車體 | C35: 前輪組（圈／輻／轂／編輪） | D35: 24 吋鋁合金成輪；平地版 26 吋或 700c | E35: 1 | F35: 70 | G35: =E35*F35 -> 70 | H35: 24 吋鋁合金成輪 US$10–15 @500 pc | I35: 500 pc | J35: V4 分頁 1 | K35: 未具名 | L35: 中系成輪廠；Alex Rims（台灣，升級選項） | M35: 掛牌價
A36: 13 | B36: 車體 | C36: 後輪編輪工資 | D36: 後輪圈 + 輻條編於馬達花鼓（馬達另計） | E36: 1 | F36: 40 | G36: =E36*F36 -> 40 | H36: V4 分頁 1：RMB 40 | I36: — | J36: V4 分頁 1 | K36: — | L36: 整車 ODM（世同／蘇州）自編 | M36: 估值
A37: 14 | B37: 車體 | C37: 煞車（前後全套） | D37: V 煞前後含把手；機械碟版另加 US$7–12 + 碟煞花鼓／座 RMB 15–25 | E37: 1 | F37: 30 | G37: =E37*F37 -> 30 | H37: V 煞 US$3–5；機械碟 US$7–12 + 碟煞花鼓／座 RMB 15–25 | I37: — | J37: V4 分頁 1、分頁 2 | K37: 未具名 | L37: Tektro 彥豪、Promax、Alhonga | M37: 掛牌價 | N37: 載童版後碟 +RMB 54（V4 分頁 2）
A38: 15 | B38: 車體 | C38: 輪胎 ×2 + 內胎 ×2 | D38: 26 吋城市防刺胎 | E38: 1 | F38: 32 | G38: =E38*F38 -> 32 | H38: 26 吋胎 US$0.95–1.85 @500 pc | I38: 500 pc | J38: V4 分頁 1 | K38: 未具名 | L38: 朝陽 Chaoyang、建大 Kenda、正新 CST | M38: 掛牌價
A39: 16 | B39: 車體 | C39: 曲柄／中軸／踏板 | D39: 44T 曲柄組（載童版 42T）、方孔 BB、踏板 | E39: 1 | F39: 45 | G39: =E39*F39 -> 45 | H39: 曲柄 US$2.56–6.34 @200 pc、中軸 US$0.75–1 @100 pc | I39: 100–200 pc | J39: V4 分頁 1 | K39: 未具名 | L39: Prowheel、Lasco 華祥；VP 踏板 | M39: 掛牌價 | N39: 日本版扭力中軸取代標準中軸（−RMB 7）
A40: 17 | B40: 車體 | C40: 單速鏈條 + 16T 飛輪 | D40: 單速鏈條、螺紋單速飛輪（載童版 18T） | E40: 1 | F40: 16 | G40: =E40*F40 -> 16 | H40: 單速鏈條 + 飛輪 US$1.7–3；對照 Tourney 後撥 + 指撥 + 飛輪 + 線 RMB 78–113 | I40: — | J40: V4 分頁 1、分頁 2 | K40: Shimano Tourney（對照，不採用） | L40: KMC 桂盟（鏈條）、DNP（飛輪） | M40: 掛牌價
A41: 18 | B41: 車體 | C41: 把手／龍頭／座管／坐墊／握把 | D41: 公版座艙 | E41: 1 | F41: 55 | G41: =E41*F41 -> 55 | H41: 坐墊 US$1.25–1.36 @100 pc；其餘估值 | I41: 100 pc | J41: V4 分頁 1 | K41: 未具名 | L41: 中系；Velo 維樂（升級） | M41: 掛牌價／估值
A42: 19 | B42: 車體 | C42: 擋泥板／腳撐／車燈／反光／鈴 | D42: LED 前後燈由控制器供電 | E42: 1 | F42: 40 | G42: =E42*F42 -> 40 | H42: LED 車燈 US$1.2–1.7 @500 pc；其餘估值 | I42: 500 pc | J42: V4 分頁 1 | K42: 未具名 | L42: 中系；Spanninga（升級） | M42: 掛牌價／估值 | N42: 日本載童版另加両立スタンド、前籃、全鏈罩、把手鎖（+RMB 30，V3 補充模型假設）
A43: 20 | B43: 車體 | C43: 五金／束帶／小件 | E43: 1 | F43: 25 | G43: =E43*F43 -> 25 | H43: V4 分頁 1：RMB 25 | I43: — | J43: V4 分頁 1 | K43: — | L43: 整車 ODM 自備 | M43: 估值
A44: 21 | B44: 車體 | C44: 包裝 | D44: 紙箱／EPE／護角／零件盒／說明書；SKD 85% | E44: 1 | F44: 26 | G44: =E44*F44 -> 26 | H44: V4 分頁 1：RMB 26 | I44: — | J44: V4 分頁 1 | K44: — | L44: 整車 ODM 自備 | M44: 估值
C45: 車體小計 | G45: =SUM(G34:G44) -> 479
A47: 4. 彙總與出廠價（對帳 V4 分頁 1／3）
...

Sheet 報價出處索引
A1: 報價出處索引：每一筆單價來自哪份文件、什麼類型、可靠度如何
A3: 代號 | B3: 出處 | C3: 類型 | D3: 涵蓋項目 | E3: 可靠度 | F3: 備註
A4: S1 | B4: V4 模型分頁 1「單價來源（已查證，MOQ 標註於備註）」 | C4: Made-in-China／1688 掛牌價，依 10 萬台量產折算 15–25% | D4: 馬達、控制器、PAS、LCD／單鍵、線束、車架、輪組、煞車、輪胎、曲柄中軸、鏈條飛輪、坐墊、車燈、電芯、電池包固定成本、充電器 | E4: 中（掛牌價，MOQ 30–1,000） | F4: V4 自述：非供應商書面報價
A5: S2 | B5: V4 模型分頁 7「感測器方案比較」 | C5: 掛牌價 + 工程估值 | D5: PAS 12 磁、IMU、力矩中軸、煞把斷電、線束加長、EOL 校正、日本非 BOM 增額 | E5: 中 | F5: 力矩中軸 US$28–30 @MOQ100 為多筆一致報價
A6: S3 | B6: V4 模型分頁 2「降本槓桿排序」 | C6: V4 自算差額 | D6: V 煞 vs 機械碟、鋁 vs 鋼架、變速 vs 單速、儀表、充電器、控制器整合 | E6: 中
A7: S4 | B7: V4 模型分頁 12、13（認證費、達方歐洲布局） | C7: 市場行情、TMT 公告費率、業者公開報價、產業媒體 | D7: EN 15194 + EN 50604-1 €40–60k／型；日本型式認定 ¥266,000–377,000／型；PSE ○ ¥50 萬–600 萬、◇ 數百萬円；台灣 VSCC €9–15k／型；達方捷克廠與客戶（Bike Europe 2024/12） | E7: 中高（費率為公告） | F7: PSE 費用引自業者公開報價
A8: S5 | B8: StealthWheel 技術暨商業盡職調查（2026-09-21）第二、四節 | C8: 產業查證：FOB 報價、零售價、OEM 專供 | D8: Bafang RM G010 FOB US$69–79 @500 pcs；Bafang G310 零售 US$125；Mahle X20／X35+ 規格；TDCM 力矩感測飛輪體零售 US$115；電芯 10 × US$2.8、BMS US$8、PD3.1 US$10；ALEX TK-06U 規格修正 | E8: 中高 | F8: 盡調重估 BOM US$336 之明細
A9: S6 | B9: 三電系統訂閱制與 BOM 分析報告 附錄 A（BESV 2026/06 庫存單位成本） | C9: 內部錨點（小量、舊世代、多層貿易） | D9: AKM 前後輪轂、Bafang 前輪轂、Darfon 720／630Wh 電池、E4C0E、控制器 cartridge／YCDT03／YTMT02、LCM／TFT、Thun／SR／TS0003 扭力感測、速度與煞車感測、SANAV／SARA350 連網、線束、充電器 | E9: 高（實際採購價）但偏高 | F9: 僅供對照上限，不作量產單價
A10: S7 | B10: 三電系統訂閱制與 BOM 分析報告 附錄 B（外部基準） | C10: 上市公司年報 ASP、Alibaba 批發、研究推估 | D10: 八方／安乃達齒輪輪轂 ASP RMB 230–335；Bafang M600／H700 套件 OEM 估價；Samsung 50S US$0.10/Wh；720Wh 包 FOB US$170；中軸扭力感測中系批量 US$15–40；Quectel EC200S US$6.50 @10k；42V 2A 充電器 US$6.5–11；認證 US$80–180k／新平台 | E10: 中高（年報）／中（Alibaba） | F10: 標註「待驗證」者須核對原頁
A11: S8 | B11: V3 補充模型（三變體、輪內可拆 vs 車架可拆） | C11: 本專案假設 | D11: 45 N·m 馬達 +80、子乗せ車架 +90、20 吋 −10、認定攤提 +8、電芯級可換 +20、輪內母模 US$78 | E11: 低（假設） | F11: 須以報價覆寫
A12: S9 | B12: 網路查證（2026-09）：Bike Europe、Show Daily、BMZ、Bafang 官網 | C12: 產業媒體與供應商公開資料 | D12: 達方捷克廠年產 30 萬組、Shimano 認證替換電池、Stromer 客製包；BMZ RB-900 合規電池；Bafang LMT 電池 Art.10 宣告 | E12: 中高 | F12: 對照與供應商能力，不含單價

Sheet 待詢價清單
A1: RFQ 待詢價清單：依佔不含電池 BOM 比重與價格不透明度排序（10k／30k／100k 三檔書面報價，填入後覆寫 BOM 清單藍字）
A3: 優先 | B3: 項目 | C3: 目標規格（詢價用） | D3: 建議詢價對象 | E3: 目前估值 RMB | F3: 10k 報價 | G3: 30k 報價 | H3: 100k 報價 | I3: 佔配置 C 材料 | J3: 狀態 | K3: 備註
A4: 1 | B4: 250W 齒輪後輪轂馬達 + 側蓋整合控制器 | C4: 250W 連續、輪端 30–32 N·m、2.3–3.0 kg、135mm、螺紋單飛座；側蓋內建 36V 15A 正弦波控制器（雙訊號輸入、OTP 限速）；另報 40–45 N·m 級 | D4: Bafang 八方、Ananda 安乃達（AKM）、常州 Found、Shengyi 盛義、XOFO 信孚 | E4: 265 | I4: =E4/BOM清單!G49 -> 0.33166458 | J4: 待詢價 | K4: 馬達 205 + 控制器 60；整合報價可省 RMB 23–41
A5: 2 | B5: 電池包（三容量同殼、電芯級可換） | C5: 36V 180／252／360Wh，10s1p／10s2p，同一外殼不同填充率；電芯座 + 彈簧接點；BMS 含 BLE SoH 與護照資料欄位；IP65；EN 50604-1、UN38.3 | D5: 達宇 Darfon Energy（自製）、蘇州；電芯：DMEGC、EVE、BAK、Lishen、Samsung SDI；歐洲落地：達方捷克廠 | E5: 282 | I5: =E5/BOM清單!G49 -> 0.35294118 | J5: 待詢價 | K5: 訂閱資產，不計入出廠價但決定月費
A6: 3 | B6: 中軸扭力感測器（日本版） | C6: 0–80 N·m、IP66、方孔或 ISIS、0–5V 或 CAN 輸出、含線束；出廠零點校正治具 | D6: 森浦 Sempu、TDCM、NCTE、SR | E6: 160 | I6: =E6/BOM清單!G49 -> 0.20025031 | J6: 待詢價 | K6: 日本版必要；最不透明
A7: 4 | B7: 車架 + 前叉（含塗裝） | C7: 鋼公版城市車架、135mm 開檔、無內走線；鋁 6061 選項；日本載童版：通過幼児二人同乗基準之公版 | D7: 世同／太宇既有車架供應商（台灣／越南）、天津車架廠；日本 BAA 會員廠之 OEM | E7: 100 | I7: =E7/BOM清單!G49 -> 0.12515645 | J7: 待詢價 | K7: 歐洲版須台越製以避 AD+CVD
A8: 5 | B8: 充電器 36V 2A（CE／GS；日本 ◇PSE） | C8: 全電壓、CE/GS；日本版 PSE 特定電気用品認證含海外工廠檢查 | D8: 中系充電器廠；BESV JAPAN 協助 PSE | E8: 40 | I8: =E8/BOM清單!G49 -> 0.050062578 | J8: 待詢價 | K8: PSE 認證費數百萬円須先確認由誰承擔
A9: 6 | B9: 煞車全套 | C9: V 煞前後含斷電把手；機械碟版含碟煞花鼓／座 | D9: Tektro 彥豪、Promax、Alhonga、無錫五星 | E9: 30 | I9: =E9/BOM清單!G49 -> 0.037546934 | J9: 待詢價 | K9: 載童版後碟 +54
A10: 7 | B10: 輪組與輪胎 | C10: 24／26 吋成輪、防刺胎 | D10: 中系成輪廠、朝陽、建大、正新 | E10: 102 | I10: =E10/BOM清單!G49 -> 0.12765957 | J10: 待詢價 | K10: 前輪組 70 + 輪胎 32
A11: 8 | B11: 曲柄／中軸／踏板、鏈條、飛輪 | C11: 44T／42T 曲柄組、方孔 BB、單速鏈、16T／18T 單飛 | D11: Prowheel、Lasco、KMC、DNP | E11: 61 | I11: =E11/BOM清單!G49 -> 0.076345432 | J11: 待詢價
A12: 9 | B12: 座艙與配件 | C12: 把手、龍頭、座管、坐墊、握把、擋泥板、側柱、LED 燈、鈴 | D12: 中系；Velo、Spanninga（升級） | E12: 95 | I12: =E12/BOM清單!G49 -> 0.11889862 | J12: 待詢價
A13: 10 | B13: PAS、IMU、按鍵、線束 | C13: 12 磁 PAS、6 軸 IMU、單鍵 RGB、主線束 4pin | D13: 通用件；HiGo、Julet；TDK、Bosch Sensortec | E13: 63 | I13: =E13/BOM清單!G49 -> 0.078848561 | J13: 待詢價 | K13: B 方案增量含 IMU 8、煞把 12
B14: 說明 | C14: 三檔報價填入後，將 100k 報價回填 BOM 清單 F 欄藍字，出廠價與三變體合計自動重算。序 1–3 合計佔不含電池 BOM 約 35%，為投模具前必須關閉的不確定性。
