Workbook

Sheet 假設
A1: 極簡版 Hub-motor E-Bike｜訂閱制降低購買門檻｜出廠價 NT$6,000 / RMB 1,300 模型
A2: 藍字 = 可調輸入值；黑字 = 公式；綠字 = 跨表連結。修改藍字後全表自動重算。基準日 2026-09-21。幣別以標頭為準。
A4: A. 匯率
A5: 參數 | B5: 值 | C5: 說明 / 來源
A6: USD / NTD | B6: 31 | C6: 假設值，與三電系統 BOM 報告一致
A7: USD / RMB | B7: 7.2 | C7: 假設值
A8: EUR / USD | B8: 1.08 | C8: 假設值，與 StealthWheel TCO 模型一致
A9: USD / JPY | B9: 157 | C9: 假設值（JPY/EUR 170 ÷ EUR/USD 1.08 ≈ 157）
A10: EUR / NTD（導出） | B10: =B8*B6 -> 33.48 | C10: ＝ EUR/USD × USD/NTD
A11: RMB / JPY（導出） | B11: =B9/B7 -> 21.805556 | C11: ＝ USD/JPY ÷ USD/RMB
A13: B. 量級與出廠價目標
A14: 參數 | B14: 值 | C14: 說明 / 來源
A15: 量級 1（台/年） | B15: 10000 | C15: 種子量產（原提案 Year 1）
A16: 量級 2（台/年） | B16: 30000 | C16: 區域規模
A17: 量級 3（台/年） | B17: 100000 | C17: 原提案 BOM 基準量
A18: 出廠價目標（NT$，台灣/越南廠，不含電池） | B18: 6000 | C18: 使用者設定
A19: 出廠價目標（RMB，中國廠，不含電池） | B19: 1300 | C19: 使用者設定
A20: 工廠目標毛利率（出廠價對 BOM） | B20: 0.1 | C20: ODM 整車廠常態 8–12%（8/28 會議門檻：新事業毛利 ≥12–15%）
A21: 中國廠對台越廠製造成本折減 | B21: 0.05 | C21: 假設：人工與在地零件供應差異；日本版採中國廠
A22: EN 15194 + EMC + UN38.3 新平台認證費（USD） | B22: 130000 | C22: BOM 報告附錄 B：US$80–180k／新平台
A23: 日本型式認定費（JPY／型） | B23: 377000 | C23: TCO 模型：¥266,000–377,000／型
A24: 認證攤提年數 | B24: 3 | C24: 假設
A25: 保固準備金率（佔硬體 BOM） | B25: 0.015 | C25: 假設：以換代修、電池另計
A26: 日本版占總量比例（攤提用） | B26: 0.3 | C26: 假設
A28: C. 歐洲市場假設（EUR）
A29: 參數 | B29: 值 | C29: 說明 / 來源
A30: 關稅（台灣製 MFN，越南製 EVFTA 待驗證） | B30: 0.06 | C30: CN 8711 60 10 MFN 6%；中國製另加 AD 62.1% + CVD 17.2%，本模型不採用
A31: 海運 + 內陸物流（USD／台，整車 SKD） | B31: 30 | C31: 假設：40HQ 約 120–150 台
A32: 車體 DTC 目標毛利率 | B32: 0.35 | C32: TCO 模型車架毛利 35%
A33: 增值稅（德國） | B33: 0.19
A34: 訂閱呆帳率 | B34: 0.05 | C34: TCO 模型 6%（Upbound 中值）；本案用戶已持有車體，違約動機較低，取 5%
A35: 金流手續費 | B35: 0.025
A36: 維修／物流準備（EUR／戶／月，僅電池） | B36: 0.4 | C36: TCO 模型：年故障率 5% × 修理 + 雙程物流
A37: 失竊補償準備（EUR／戶／月） | B37: 0.5 | C37: 假設：電池失竊率 3%/年 × 電池成本 ≈ €0.15/月，加保險行政取 €0.5
A38: 客服／APP／雲端（EUR／戶／月） | B38: 0.6 | C38: TCO 模型 €1.0（含三電診斷）；本案僅電池 SoH 與 BLE，取 €0.6
A39: 電池更換週期（月） | B39: 48 | C39: 通勤 2,500 km/年、252Wh → 約 125 循環/年（TCO 模型）
A40: 電池更換物流（EUR／次，經銷點／回收點，非快遞） | B40: 30 | C40: 盡調報告：陸運 €20–50／程；180Wh 以上為 UN3480，不能一般包裹寄送
A41: 平均訂閱壽命（月） | B41: 36 | C41: 假設：綁定車體持有期（自行車平均持有 5–8 年），保守取 3 年
A42: 訂閱獲客成本 CAC（EUR） | B42: 30 | C42: 假設：隨車體銷售同時成交，B2C 純電商 CAC €120 不適用
A43: 期末電池殘值率 | B43: 0.15 | C43: TCO 模型 30%（含馬達）；電池衰退後翻新/儲能再利用取 15%
...

Sheet BOM
A1: BOM 與出廠價：極簡版（單速 + 踏頻感測 + 商品化輪轂馬達）
A2: USD／台。三個量級為獨立輸入（藍字）；電池與充電器列為訂閱資產，不計入出廠價。
A4: 項目 | B4: 規格 | C4: 10k 台/年 | D4: 30k 台/年 | E4: 100k 台/年 | F4: 依據 / 來源
A5: 量級（台/年） | B5: 連結假設表 | C5: =假設!$B$15 -> 10000 | D5: =假設!$B$16 -> 30000 | E5: =假設!$B$17 -> 100000
A6: 1. 三電（不含電池）── 計入出廠價
A7: 250W 齒輪後輪轂馬達 | B7: 商品化 2.3–3.0 kg、30–32 N·m、135mm 開檔、螺紋單飛座（Bafang RM G010／安乃達／XOFO 級） | C7: 55 | D7: 47 | E7: 42 | F7: 盡調報告：Bafang RM G010 FOB US$69–79 @500 pcs；BOM 報告附錄 B：Bafang/安乃達齒輪輪轂 ASP RMB 230–335（US$32–47）、通用 250W 輪轂 Alibaba ≈US$55。10 萬台取 ASP 上緣。無書面報價。
A8: 正弦波控制器 36V 15A（踏頻版） | B8: 分離式，含 LED 燈輸出、煞車斷電、速度分段助力曲線 | C8: 12 | D8: 10 | E8: 9 | F8: BOM 報告附錄 B：輪轂套件（控制器/顯示/感測）約 US$60；踏頻版無 TFT、無扭力，中系批發估 US$8–15
A9: 踏頻感測器 PAS | B9: 12 磁盤 + 霍爾 | C9: 2 | D9: 1.7 | E9: 1.5 | F9: 商品化元件，估值
A10: 煞車斷電感測 ×2 | B10: 磁簧式，整合於煞車把手 | C10: 2 | D10: 1.7 | E10: 1.5 | F10: BESV 錨點 NT$180/個（小量）；大量估 US$0.75/個
A11: 三段 LED 電量／助力按鍵（無儀表） | B11: 上管或把手單鍵 + 3 LED | C11: 4 | D11: 3.3 | E11: 3 | F11: 原提案：上管單鍵 RGB；商品化 LED 按鍵 US$2.5–4
A12: 線束 + 電源座 | B12: 外走線、無內走線孔 | C12: 5 | D12: 4.5 | E12: 4 | F12: BESV 錨點 Cartridge 主線束 NT$771（小量）；大量估 US$4–5
A13: 三電小計（不含電池） | C13: =SUM(C7:C12) -> 80 | D13: =SUM(D7:D12) -> 68.2 | E13: =SUM(E7:E12) -> 61
A15: 2. 電池與充電器 ── 訂閱資產，不計入出廠價
A16: 36V 7Ah 252Wh 電池組 | B16: 10s2p 18650 3.5Ah 中系電芯、BMS（含 BLE SoH 回報）、ABS 殼、鎖具、後貨架式或下管掛載 | C16: 56 | D16: 50 | E16: 46 | F16: BOM 報告：中系電芯 NT$2.8/Wh（US$0.09/Wh）→ 252Wh 電芯 ≈US$23；BMS US$5；殼/鎖/連接器 US$10；組裝測試 UN38.3 US$5–8。對照 500Wh 包 FOB US$150（Tier-1 電芯）。
A17: 36V 2A 充電器 | B17: 全電壓、CE/PSE | C17: 9 | D17: 7.5 | E17: 7 | F17: BOM 報告附錄 B：Alibaba 42V 2A 充電器批發 US$6.5–11
A18: 電池 + 充電器小計（訂閱資產） | C18: =SUM(C16:C17) -> 65 | D18: =SUM(D16:D17) -> 57.5 | E18: =SUM(E16:E17) -> 53
A20: 3. 車體 ── 計入出廠價
A21: 鋁合金公版車架 + 剛性前叉 | B21: 700c 或 26 吋城市車幾何、135mm 開檔、無內走線孔、無電裝開模 | C21: 50 | D21: 45 | E21: 42 | F21: 原提案 US$58（公版）；TCO 模型 US$62（需容納 Ø130 母模）。本案無特製需求，取公版下緣。
A22: 輪組 + 外胎內胎 | B22: 前輪完整；後輪圈 + 輻條編於馬達花鼓；城市防刺胎 | C22: 24 | D22: 21.5 | E22: 20 | F22: 估值；盡調報告：編輪工資含於煞車與配件 US$24
A23: 煞車（V 煞前後，含把手） | B23: 機械碟煞版另加 US$8 | C23: 7 | D23: 6.3 | E23: 6 | F23: 原提案機械碟煞含配件 US$19；V 煞為城市車最低成本方案
A24: 單速傳動 | B24: 44T 曲柄組、方孔 BB、鏈條、16T 單速飛輪、踏板 | C24: 14 | D24: 12.8 | E24: 12 | F24: 原提案 US$6.5 僅鏈條 + 飛輪；加曲柄/BB/踏板
A25: 座艙 | B25: 把手、龍頭、碗組、握把、座墊、座管 | C25: 13 | D25: 11.8 | E25: 11 | F25: 估值
A26: 配件 | B26: 擋泥板、側柱、LED 前後燈（控制器供電）、反光片、車鈴 | C26: 9 | D26: 8.4 | E26: 8 | F26: 估值；EN 15194／日本道交法之最低配備
A27: 包裝 + 組裝工時 | B27: SKD 85% 組裝、免走線免調變速，約 10–12 分鐘 | C27: 12 | D27: 11 | E27: 10 | F27: 原提案 US$9.5（10 分鐘）；TCO 模型 US$14
A28: 認證攤提（EN 15194 + EMC + UN38.3） | B28: ＝ 認證費 ÷ (量級 × 攤提年數) | C28: =假設!$B$22/(C$5*假設!$B$24) -> 4.3333333 | D28: =假設!$B$22/(D$5*假設!$B$24) -> 1.4444444 | E28: =假設!$B$22/(E$5*假設!$B$24) -> 0.43333333 | F28: 假設表 B 段；BOM 報告附錄 B：US$80–180k／新平台
A29: 保固準備金 | B29: ＝ 保固率 × (三電 + 車體硬體) | C29: =假設!$B$25*(C13+SUM(C21:C27)) -> 3.135 | D29: =假設!$B$25*(D13+SUM(D21:D27)) -> 2.775 | E29: =假設!$B$25*(E13+SUM(E21:E27)) -> 2.55 | F29: 假設表 B 段
A30: 車體小計 | C30: =SUM(C21:C29) -> 136.46833 | D30: =SUM(D21:D29) -> 121.01944 | E30: =SUM(E21:E29) -> 111.98333
A32: 4. 成本彙總與出廠價（台灣／越南廠，歐洲版）
A33: 項目 | B33: 公式 | C33: 10k 台/年 | D33: 30k 台/年 | E33: 100k 台/年 | F33: 判讀
A34: 整車 BOM（不含電池，USD） | B34: ＝ 三電 + 車體 | C34: =C13+C30 -> 216.46833 | D34: =D13+D30 -> 189.21944 | E34: =E13+E30 -> 172.98333 | F34: 出廠價的成本基礎
A35: 整車 BOM（含電池 + 充電器，USD） | B35: ＝ 上列 + 訂閱資產 | C35: =C34+C18 -> 281.46833 | D35: =D34+D18 -> 246.71944 | E35: =E34+E18 -> 225.98333 | F35: 若電池隨車賣斷的成本
A36: 整車 BOM（不含電池，NT$） | B36: × USD/NTD | C36: =C34*假設!$B$6 -> 6710.5183 | D36: =D34*假設!$B$6 -> 5865.8028 | E36: =E34*假設!$B$6 -> 5362.4833
A37: 整車 BOM（含電池，NT$） | B37: × USD/NTD | C37: =C35*假設!$B$6 -> 8725.5183 | D37: =D35*假設!$B$6 -> 7648.3028 | E37: =E35*假設!$B$6 -> 7005.4833
A38: 出廠價 @ 目標毛利（不含電池，NT$） | B38: ＝ BOM ÷ (1 − 工廠毛利率) | C38: =C36/(1-假設!$B$20) -> 7456.1315 | D38: =D36/(1-假設!$B$20) -> 6517.5586 | E38: =E36/(1-假設!$B$20) -> 5958.3148 | F38: 與 NT$6,000 目標比較
A39: 出廠價 @ 目標毛利（含電池，NT$） | B39: ＝ BOM ÷ (1 − 工廠毛利率) | C39: =C37/(1-假設!$B$20) -> 9695.0204 | D39: =D37/(1-假設!$B$20) -> 8498.1142 | E39: =E37/(1-假設!$B$20) -> 7783.8704 | F39: 電池隨車賣斷時無法達標
A40: NT$6,000 出廠價隱含工廠毛利率（不含電池） | B40: ＝ 1 − BOM ÷ 目標出廠價 | C40: =1-C36/假設!$B$18 -> -0.11841972 | D40: =1-D36/假設!$B$18 -> 0.022366204 | E40: =1-E36/假設!$B$18 -> 0.10625278 | F40: ≥ 8–10% 才有 ODM 廠願意接
A41: NT$6,000 出廠價隱含工廠毛利率（含電池） | B41: ＝ 1 − BOM ÷ 目標出廠價 | C41: =1-C37/假設!$B$18 -> -0.45425306 | D41: =1-D37/假設!$B$18 -> -0.27471713 | E41: =1-E37/假設!$B$18 -> -0.16758056 | F41: 全部為負值 → 電池必須移出出廠價
A42: 達標所需 BOM 上限（USD，不含電池） | B42: ＝ 目標出廠價 × (1 − 毛利率) ÷ USD/NTD | C42: =假設!$B$18*(1-假設!$B$20)/假設!$B$6 -> 174.19355 | D42: =假設!$B$18*(1-假設!$B$20)/假設!$B$6 -> 174.19355 | E42: =假設!$B$18*(1-假設!$B$20)/假設!$B$6 -> 174.19355 | F42: BOM 天花板
A43: 缺口（USD，正值 = 超出天花板） | B43: ＝ BOM − 上限 | C43: =C34-C42 -> 42.274785 | D43: =D34-D42 -> 15.025896 | E43: =E34-E42 -> -1.2102151 | F43: 負值代表已達標
A45: 5. 中國廠版本（RMB）與日本版增量
...

Sheet 訂閱單位經濟
A1: 訂閱單位經濟：車體賣斷 + 電池訂閱（營運商側）
A2: 資產只有電池 + 充電器；車體由消費者買斷（或經第三方分期／薪資扣抵），營運商帳上不留整車。BOM 取 100k 量級。
A4: A. 車體零售定價（消費者購買門檻）
A5: 項目 | B5: 歐洲（EUR） | C5: 日本（JPY） | F5: 公式
A6: 出廠價（不含電池） | B6: =BOM!E38/假設!$B$10 -> 177.96639 | C6: =BOM!E57 -> 33905.17 | F6: 歐洲：台越廠 NT$ 出廠價 ÷ EUR/NTD；日本：中國廠日本版 JPY
A7: 關稅 | B7: =B6*假設!$B$30 -> 10.677984 | C7: =C6*假設!$B$50 -> 0 | F7: 假設表
A8: 海運 + 內陸物流 | B8: =假設!$B$31/假設!$B$8 -> 27.777778 | C8: =假設!$B$51 -> 2500 | F8: 假設表
A9: 落地成本 | B9: =SUM(B6:B8) -> 216.42215 | C9: =SUM(C6:C8) -> 36405.17
A10: 車體零售價（含稅） | B10: =B9/(1-假設!$B$32)*(1+假設!$B$33) -> 396.21902 | C10: =C9/(1-假設!$B$52)*(1+假設!$B$53) -> 61608.749 | F10: ＝ 落地 ÷ (1 − 毛利率) × (1 + 稅)
A11: 對照：市場最低價合法 e-bike 買斷（含電池） | B11: 699 | C11: 89980 | F11: 歐洲 Action E200 / Lidl Crivit €699；日本 PELTECH ¥89,980 起（2026）
A12: 購買門檻降幅 | B12: =1-B10/B11 -> 0.43316306 | C12: =1-C10/C11 -> 0.31530619 | F12: 前置支出相對最低價買斷的減幅
A14: B. 電池訂閱資產（每戶）
A15: 項目 | B15: 歐洲（EUR） | C15: 日本（JPY） | F15: 公式
A16: 電池 + 充電器 BOM（USD，100k） | B16: =BOM!E18 -> 53 | C16: =BOM!E64+BOM!E17 -> 67.72 | F16: 歐洲 252Wh；日本以 360Wh 計（保守）
A17: 電池資產落地成本（當地幣） | B17: =B16/假設!$B$8*(1+假設!$B$30)+假設!$B$31/假設!$B$8*0.2 -> 57.574074 | C17: =C16*假設!$B$9*(1+假設!$B$50)+假設!$B$51*0.2 -> 11132.04 | F17: 隨車出貨，物流按整車 20% 分攤
A18: 電池更換成本（料 + 經銷點物流） | B18: =B17+假設!$B$40 -> 87.574074 | C18: =C17+假設!$B$60 -> 14132.04 | F18: UN3480：不走一般快遞，走經銷／回收點
A19: 每月電池更換攤提 | B19: =B18/假設!$B$39 -> 1.8244599 | C19: =C18/假設!$B$59 -> 294.4175 | F19: ＝ 更換成本 ÷ 更換週期
A21: C. 歐洲：每戶每月損益（EUR）
A22: 項目 | B22: 月費 €7.9 | C22: 月費 €9.9 | D22: 月費 €12.9 | E22: 月費 €14.9 | F22: 公式
A23: 月費（含稅） | B23: 7.9 | C23: 9.9 | D23: 12.9 | E23: 14.9 | F23: 情境輸入
A24: 淨營收（除 VAT） | B24: =B23/(1+假設!$B$33) -> 6.6386555 | C24: =C23/(1+假設!$B$33) -> 8.3193277 | D24: =D23/(1+假設!$B$33) -> 10.840336 | E24: =E23/(1+假設!$B$33) -> 12.521008
A25: 減：呆帳 + 金流 | B25: =-B24*(假設!$B$34+假設!$B$35) -> -0.49789916 | C25: =-C24*(假設!$B$34+假設!$B$35) -> -0.62394958 | D25: =-D24*(假設!$B$34+假設!$B$35) -> -0.81302521 | E25: =-E24*(假設!$B$34+假設!$B$35) -> -0.93907563
A26: 減：維修／物流 + 失竊補償 + 雲端 | B26: =-(假設!$B$36+假設!$B$37+假設!$B$38) -> -1.5 | C26: =-(假設!$B$36+假設!$B$37+假設!$B$38) -> -1.5 | D26: =-(假設!$B$36+假設!$B$37+假設!$B$38) -> -1.5 | E26: =-(假設!$B$36+假設!$B$37+假設!$B$38) -> -1.5
A27: 減：電池更換攤提 | B27: =-B19 -> -1.8244599 | C27: =-B19 -> -1.8244599 | D27: =-B19 -> -1.8244599 | E27: =-B19 -> -1.8244599
A28: 每戶月貢獻 | B28: =SUM(B24:B27) -> 2.8162964 | C28: =SUM(C24:C27) -> 4.3709183 | D28: =SUM(D24:D27) -> 6.702851 | E28: =SUM(E24:E27) -> 8.2574729
A29: 資產回收期（月） | B29: =IF(B28>0,B17/B28,999) -> 20.443187 | C29: =IF(C28>0,B17/C28,999) -> 13.172077 | D29: =IF(D28>0,B17/D28,999) -> 8.5894903 | E29: =IF(E28>0,B17/E28,999) -> 6.97236 | F29: ＝ 電池資產 ÷ 月貢獻
A30: 訂閱壽命內累計貢獻 | B30: =B28*假設!$B$41 -> 101.38667 | C30: =C28*假設!$B$41 -> 157.35306 | D30: =D28*假設!$B$41 -> 241.30264 | E30: =E28*假設!$B$41 -> 297.26902
A31: 單戶淨值（累計貢獻 + 殘值 − 資產 − CAC） | B31: =B30+B17*假設!$B$43-B17-假設!$B$42 -> 22.448708 | C31: =C30+B17*假設!$B$43-B17-假設!$B$42 -> 78.415095 | D31: =D30+B17*假設!$B$43-B17-假設!$B$42 -> 162.36467 | E31: =E30+B17*假設!$B$43-B17-假設!$B$42 -> 218.33106 | F31: 對照 TCO 模型三電全訂閱 €15/月：−€70
A32: 損益兩平月費（含稅） | B32: =((假設!$B$36+假設!$B$37+假設!$B$38+B19)+(B17*(1-假設!$B$43)+假設!$B$42)/假設!$B$41)/(1-假設!$B$34-假設!$B$35)*(1+假設!$B$33) -> 7.0977789 | C32: =((假設!$B$36+假設!$B$37+假設!$B$38+B19)+(B17*(1-假設!$B$43)+假設!$B$42)/假設!$B$41)/(1-假設!$B$34-假設!$B$35)*(1+假設!$B$33) -> 7.0977789 | D32: =((假設!$B$36+假設!$B$37+假設!$B$38+B19)+(B17*(1-假設!$B$43)+假設!$B$42)/假設!$B$41)/(1-假設!$B$34-假設!$B$35)*(1+假設!$B$33) -> 7.0977789 | E32: =((假設!$B$36+假設!$B$37+假設!$B$38+B19)+(B17*(1-假設!$B$43)+假設!$B$42)/假設!$B$41)/(1-假設!$B$34-假設!$B$35)*(1+假設!$B$33) -> 7.0977789 | F32: 單戶淨值 = 0 的月費（各欄相同）
A34: D. 日本：每戶每月損益（JPY）
A35: 項目 | B35: 月費 ¥980 | C35: 月費 ¥1,280 | D35: 月費 ¥1,680 | E35: 月費 ¥1,980 | F35: 公式
A36: 月費（含稅） | B36: 980 | C36: 1280 | D36: 1680 | E36: 1980 | F36: 情境輸入；NORUDE 整車訂閱 ¥2,890 起
A37: 淨營收（除消費稅） | B37: =B36/(1+假設!$B$53) -> 890.90909 | C37: =C36/(1+假設!$B$53) -> 1163.6364 | D37: =D36/(1+假設!$B$53) -> 1527.2727 | E37: =E36/(1+假設!$B$53) -> 1800
A38: 減：呆帳 + 金流 | B38: =-B37*(假設!$B$54+假設!$B$55) -> -57.909091 | C38: =-C37*(假設!$B$54+假設!$B$55) -> -75.636364 | D38: =-D37*(假設!$B$54+假設!$B$55) -> -99.272727 | E38: =-E37*(假設!$B$54+假設!$B$55) -> -117
A39: 減：維修／物流 + 失竊補償 + 雲端 | B39: =-(假設!$B$56+假設!$B$57+假設!$B$58) -> -240 | C39: =-(假設!$B$56+假設!$B$57+假設!$B$58) -> -240 | D39: =-(假設!$B$56+假設!$B$57+假設!$B$58) -> -240 | E39: =-(假設!$B$56+假設!$B$57+假設!$B$58) -> -240
A40: 減：電池更換攤提（360Wh） | B40: =-C19 -> -294.4175 | C40: =-C19 -> -294.4175 | D40: =-C19 -> -294.4175 | E40: =-C19 -> -294.4175
A41: 每戶月貢獻 | B41: =SUM(B37:B40) -> 298.5825 | C41: =SUM(C37:C40) -> 553.5825 | D41: =SUM(D37:D40) -> 893.5825 | E41: =SUM(E37:E40) -> 1148.5825
A42: 資產回收期（月） | B42: =IF(B41>0,C17/B41,999) -> 37.282962 | C42: =IF(C41>0,C17/C41,999) -> 20.109089 | D42: =IF(D41>0,C17/D41,999) -> 12.457764 | E42: =IF(E41>0,C17/E41,999) -> 9.6919812
A43: 訂閱壽命內累計貢獻 | B43: =B41*假設!$B$61 -> 10748.97 | C43: =C41*假設!$B$61 -> 19928.97 | D43: =D41*假設!$B$61 -> 32168.97 | E43: =E41*假設!$B$61 -> 41348.97
A44: 單戶淨值（累計貢獻 + 殘值 − 資產 − CAC） | B44: =B43+C17*假設!$B$63-C17-假設!$B$62 -> -3713.264 | C44: =C43+C17*假設!$B$63-C17-假設!$B$62 -> 5466.736 | D44: =D43+C17*假設!$B$63-C17-假設!$B$62 -> 17706.736 | E44: =E43+C17*假設!$B$63-C17-假設!$B$62 -> 26886.736
...

Sheet 消費者TCO
A1: 消費者總持有成本（含稅）
A2: 本案 = 車體買斷 + 電池月費（含電池更換、失竊補償）。買斷方案另加年維護與第 4／8 年換電池。
A4: A. 歐洲（EUR）
A5: 方案 | B5: 前置費用 | C5: 月費 | D5: 2 年 | E5: 3 年 | F5: 5 年 | G5: 8 年 | H5: 說明
A6: 本案：車體買斷 + €7.9/月電池訂閱 | B6: =訂閱單位經濟!B10 -> 396.21902 | C6: 7.9 | D6: =$B6+$C6*12*2 -> 585.81902 | E6: =$B6+$C6*12*3 -> 680.61902 | F6: =$B6+$C6*12*5 -> 870.21902 | G6: =$B6+$C6*12*8 -> 1154.619 | H6: 含電池更換與失竊補償；車體歸消費者
A7: 本案：車體買斷 + €9.9/月電池訂閱 | B7: =訂閱單位經濟!B10 -> 396.21902 | C7: 9.9 | D7: =$B7+$C7*12*2 -> 633.81902 | E7: =$B7+$C7*12*3 -> 752.61902 | F7: =$B7+$C7*12*5 -> 990.21902 | G7: =$B7+$C7*12*8 -> 1346.619 | H7: 含電池更換與失竊補償；車體歸消費者
A8: 本案：車體買斷 + €12.9/月電池訂閱 | B8: =訂閱單位經濟!B10 -> 396.21902 | C8: 12.9 | D8: =$B8+$C8*12*2 -> 705.81902 | E8: =$B8+$C8*12*3 -> 860.61902 | F8: =$B8+$C8*12*5 -> 1170.219 | G8: =$B8+$C8*12*8 -> 1634.619 | H8: 含電池更換與失竊補償；車體歸消費者
A9: 本案：車體買斷 + €14.9/月電池訂閱 | B9: =訂閱單位經濟!B10 -> 396.21902 | C9: 14.9 | D9: =$B9+$C9*12*2 -> 753.81902 | E9: =$B9+$C9*12*3 -> 932.61902 | F9: =$B9+$C9*12*5 -> 1290.219 | G9: =$B9+$C9*12*8 -> 1826.619 | H9: 含電池更換與失竊補償；車體歸消費者
A10: Action E200 買斷（€699，歐盟最低價合法 EPAC） | B10: 699 | C10: 0 | D10: =$B10+假設!$B$44*2+IF(2>=4,假設!$B$45,0)+IF(2>=8,假設!$B$45,0) -> 799 | E10: =$B10+假設!$B$44*3+IF(3>=4,假設!$B$45,0)+IF(3>=8,假設!$B$45,0) -> 849 | F10: =$B10+假設!$B$44*5+IF(5>=4,假設!$B$45,0)+IF(5>=8,假設!$B$45,0) -> 1199 | G10: =$B10+假設!$B$44*8+IF(8>=4,假設!$B$45,0)+IF(8>=8,假設!$B$45,0) -> 1599 | H10: 468Wh、7 速、25.2kg
A11: Lidl Crivit 城市 e-bike 買斷（€699） | B11: 699 | C11: 0 | D11: =$B11+假設!$B$44*2+IF(2>=4,假設!$B$45,0)+IF(2>=8,假設!$B$45,0) -> 799 | E11: =$B11+假設!$B$44*3+IF(3>=4,假設!$B$45,0)+IF(3>=8,假設!$B$45,0) -> 849 | F11: =$B11+假設!$B$44*5+IF(5>=4,假設!$B$45,0)+IF(5>=8,假設!$B$45,0) -> 1199 | G11: =$B11+假設!$B$44*8+IF(8>=4,假設!$B$45,0)+IF(8>=8,假設!$B$45,0) -> 1599 | H11: 2026 Lidl 城市 e-bike €699（Shimano 變速）
A12: Decathlon Elops 120 E 買斷（€799） | B12: 799 | C12: 0 | D12: =$B12+假設!$B$44*2+IF(2>=4,假設!$B$45,0)+IF(2>=8,假設!$B$45,0) -> 899 | E12: =$B12+假設!$B$44*3+IF(3>=4,假設!$B$45,0)+IF(3>=8,假設!$B$45,0) -> 949 | F12: =$B12+假設!$B$44*5+IF(5>=4,假設!$B$45,0)+IF(5>=8,假設!$B$45,0) -> 1299 | G12: =$B12+假設!$B$44*8+IF(8>=4,假設!$B$45,0)+IF(8>=8,假設!$B$45,0) -> 1699 | H12: 313Wh、6 速
A13: Tenways CGO600 買斷（€1,099，單速對標） | B13: 1099 | C13: 0 | D13: =$B13+假設!$B$44*2+IF(2>=4,假設!$B$45,0)+IF(2>=8,假設!$B$45,0) -> 1199 | E13: =$B13+假設!$B$44*3+IF(3>=4,假設!$B$45,0)+IF(3>=8,假設!$B$45,0) -> 1249 | F13: =$B13+假設!$B$44*5+IF(5>=4,假設!$B$45,0)+IF(5>=8,假設!$B$45,0) -> 1599 | G13: =$B13+假設!$B$44*8+IF(8>=4,假設!$B$45,0)+IF(8>=8,假設!$B$45,0) -> 1999 | H13: 單速皮帶、Mivice 40N·m、扭力感測
A14: Swapfiets Power 1 整車訂閱 | B14: 0 | C14: 59.9 | D14: =$B14+$C14*12*2 -> 1437.6 | E14: =$B14+$C14*12*3 -> 2156.4 | F14: =$B14+$C14*12*5 -> 3594 | G14: =$B14+$C14*12*8 -> 5750.4 | H14: €49.90 導入價、常態 €59.90；含維修保險，車不歸消費者
A16: 本案 €9.9/月 vs Action E200：5 年差額（負值 = 本案較省） | F16: =F7-F10 -> -208.78098 | G16: =G7-G10 -> -252.38098 | H16: 8 年差額見 G 欄
A18: B. 日本（JPY）
A19: 方案 | B19: 前置費用 | C19: 月費 | D19: 2 年 | E19: 3 年 | F19: 5 年 | G19: 8 年 | H19: 說明
A20: 本案：車體買斷 + ¥980/月電池訂閱（含扭力感測） | B20: =訂閱單位經濟!C10 -> 61608.749 | C20: 980 | D20: =$B20+$C20*12*2 -> 85128.749 | E20: =$B20+$C20*12*3 -> 96888.749 | F20: =$B20+$C20*12*5 -> 120408.75 | G20: =$B20+$C20*12*8 -> 155688.75 | H20: 含電池更換與失竊補償；車體歸消費者
A21: 本案：車體買斷 + ¥1,280/月電池訂閱（含扭力感測） | B21: =訂閱單位經濟!C10 -> 61608.749 | C21: 1280 | D21: =$B21+$C21*12*2 -> 92328.749 | E21: =$B21+$C21*12*3 -> 107688.75 | F21: =$B21+$C21*12*5 -> 138408.75 | G21: =$B21+$C21*12*8 -> 184488.75 | H21: 含電池更換與失竊補償；車體歸消費者
A22: 本案：車體買斷 + ¥1,680/月電池訂閱（含扭力感測） | B22: =訂閱單位經濟!C10 -> 61608.749 | C22: 1680 | D22: =$B22+$C22*12*2 -> 101928.75 | E22: =$B22+$C22*12*3 -> 122088.75 | F22: =$B22+$C22*12*5 -> 162408.75 | G22: =$B22+$C22*12*8 -> 222888.75 | H22: 含電池更換與失竊補償；車體歸消費者
A23: 本案：車體買斷 + ¥1,980/月電池訂閱（含扭力感測） | B23: =訂閱單位經濟!C10 -> 61608.749 | C23: 1980 | D23: =$B23+$C23*12*2 -> 109128.75 | E23: =$B23+$C23*12*3 -> 132888.75 | F23: =$B23+$C23*12*5 -> 180408.75 | G23: =$B23+$C23*12*8 -> 251688.75 | H23: 含電池更換與失竊補償；車體歸消費者
A24: NORUDE Panasonic ViVi SX 整車訂閱 | B24: 0 | C24: 2890 | D24: =$B24+$C24*12*2 -> 69360 | E24: =$B24+$C24*12*3 -> 104040 | F24: =$B24+$C24*12*5 -> 173400 | G24: =$B24+$C24*12*8 -> 277440 | H24: 整車 + 維護 + 換電池（零售 ¥158,000）；車不歸消費者
A25: PELTECH 型式認定車買斷（¥89,980 起） | B25: 89980 | C25: 0 | D25: =$B25+假設!$B$64*2+IF(2>=4,假設!$B$65,0)+IF(2>=8,假設!$B$65,0) -> 99980 | E25: =$B25+假設!$B$64*3+IF(3>=4,假設!$B$65,0)+IF(3>=8,假設!$B$65,0) -> 104980 | F25: =$B25+假設!$B$64*5+IF(5>=4,假設!$B$65,0)+IF(5>=8,假設!$B$65,0) -> 149980 | G25: =$B25+假設!$B$64*8+IF(8>=4,假設!$B$65,0)+IF(8>=8,假設!$B$65,0) -> 199980 | H25: 2026 日本最低價帶合法電動アシスト
A26: 電動アシスト POS 平均買斷（¥130,663） | B26: 130663 | C26: 0 | D26: =$B26+假設!$B$64*2+IF(2>=4,假設!$B$65,0)+IF(2>=8,假設!$B$65,0) -> 140663 | E26: =$B26+假設!$B$64*3+IF(3>=4,假設!$B$65,0)+IF(3>=8,假設!$B$65,0) -> 145663 | F26: =$B26+假設!$B$64*5+IF(5>=4,假設!$B$65,0)+IF(5>=8,假設!$B$65,0) -> 190663 | G26: =$B26+假設!$B$64*8+IF(8>=4,假設!$B$65,0)+IF(8>=8,假設!$B$65,0) -> 240663 | H26: JBPI 2025/7 POS
A27: 軽快車／媽媽車買斷（¥28,729，無助力） | B27: 28729 | C27: 0 | D27: =$B27+2000*2+IF(2>=4,0,0)+IF(2>=8,0,0) -> 32729 | E27: =$B27+2000*3+IF(3>=4,0,0)+IF(3>=8,0,0) -> 34729 | F27: =$B27+2000*5+IF(5>=4,0,0)+IF(5>=8,0,0) -> 38729 | G27: =$B27+2000*8+IF(8>=4,0,0)+IF(8>=8,0,0) -> 44729 | H27: JBPI 2025/7 POS；年維護以 ¥2,000 計
A29: 本案 ¥1,280/月 vs PELTECH 買斷：3 年差額（負值 = 本案較省） | E29: =E21-E25 -> 2708.7493 | F29: =F21-F25 -> -11571.251 | H29: 5 年差額見 F 欄
A30: 本案 ¥1,280/月 vs NORUDE：3 年差額 | E30: =E21-E24 -> 3648.7493 | F30: =F21-F24 -> -34991.251 | H30: NORUDE 期末須還車；本案車體歸消費者

Sheet 敏感度
A1: 敏感度分析
A2: 全部連動假設表與 BOM 表。
A4: A. 歐洲單戶淨值（€）：月費 × 訂閱壽命
A5: 月費（含稅） ＼ 壽命（月） | B5: 24 月 | C5: 36 月 | D5: 48 月 | E5: 60 月 | H5: 說明
A6: 5.9 | B6: =($A6/(1+假設!$B$33)*(1-假設!$B$34-假設!$B$35)-假設!$B$36-假設!$B$37-假設!$B$38-訂閱單位經濟!$B$19)*24+訂閱單位經濟!$B$17*(假設!$B$43-1)-假設!$B$42 -> -48.657773 | C6: =($A6/(1+假設!$B$33)*(1-假設!$B$34-假設!$B$35)-假設!$B$36-假設!$B$37-假設!$B$38-訂閱單位經濟!$B$19)*36+訂閱單位經濟!$B$17*(假設!$B$43-1)-假設!$B$42 -> -33.517678 | D6: =($A6/(1+假設!$B$33)*(1-假設!$B$34-假設!$B$35)-假設!$B$36-假設!$B$37-假設!$B$38-訂閱單位經濟!$B$19)*48+訂閱單位經濟!$B$17*(假設!$B$43-1)-假設!$B$42 -> -18.377583 | E6: =($A6/(1+假設!$B$33)*(1-假設!$B$34-假設!$B$35)-假設!$B$36-假設!$B$37-假設!$B$38-訂閱單位經濟!$B$19)*60+訂閱單位經濟!$B$17*(假設!$B$43-1)-假設!$B$42 -> -3.2374883 | H6: 壽命 = 電池訂閱持續月數
A7: 7.9 | B7: =($A7/(1+假設!$B$33)*(1-假設!$B$34-假設!$B$35)-假設!$B$36-假設!$B$37-假設!$B$38-訂閱單位經濟!$B$19)*24+訂閱單位經濟!$B$17*(假設!$B$43-1)-假設!$B$42 -> -11.346849 | C7: =($A7/(1+假設!$B$33)*(1-假設!$B$34-假設!$B$35)-假設!$B$36-假設!$B$37-假設!$B$38-訂閱單位經濟!$B$19)*36+訂閱單位經濟!$B$17*(假設!$B$43-1)-假設!$B$42 -> 22.448708 | D7: =($A7/(1+假設!$B$33)*(1-假設!$B$34-假設!$B$35)-假設!$B$36-假設!$B$37-假設!$B$38-訂閱單位經濟!$B$19)*48+訂閱單位經濟!$B$17*(假設!$B$43-1)-假設!$B$42 -> 56.244265 | E7: =($A7/(1+假設!$B$33)*(1-假設!$B$34-假設!$B$35)-假設!$B$36-假設!$B$37-假設!$B$38-訂閱單位經濟!$B$19)*60+訂閱單位經濟!$B$17*(假設!$B$43-1)-假設!$B$42 -> 90.039823 | H7: 壽命 = 電池訂閱持續月數
A8: 9.9 | B8: =($A8/(1+假設!$B$33)*(1-假設!$B$34-假設!$B$35)-假設!$B$36-假設!$B$37-假設!$B$38-訂閱單位經濟!$B$19)*24+訂閱單位經濟!$B$17*(假設!$B$43-1)-假設!$B$42 -> 25.964076 | C8: =($A8/(1+假設!$B$33)*(1-假設!$B$34-假設!$B$35)-假設!$B$36-假設!$B$37-假設!$B$38-訂閱單位經濟!$B$19)*36+訂閱單位經濟!$B$17*(假設!$B$43-1)-假設!$B$42 -> 78.415095 | D8: =($A8/(1+假設!$B$33)*(1-假設!$B$34-假設!$B$35)-假設!$B$36-假設!$B$37-假設!$B$38-訂閱單位經濟!$B$19)*48+訂閱單位經濟!$B$17*(假設!$B$43-1)-假設!$B$42 -> 130.86611 | E8: =($A8/(1+假設!$B$33)*(1-假設!$B$34-假設!$B$35)-假設!$B$36-假設!$B$37-假設!$B$38-訂閱單位經濟!$B$19)*60+訂閱單位經濟!$B$17*(假設!$B$43-1)-假設!$B$42 -> 183.31713 | H8: 壽命 = 電池訂閱持續月數
A9: 12.9 | B9: =($A9/(1+假設!$B$33)*(1-假設!$B$34-假設!$B$35)-假設!$B$36-假設!$B$37-假設!$B$38-訂閱單位經濟!$B$19)*24+訂閱單位經濟!$B$17*(假設!$B$43-1)-假設!$B$42 -> 81.930462 | C9: =($A9/(1+假設!$B$33)*(1-假設!$B$34-假設!$B$35)-假設!$B$36-假設!$B$37-假設!$B$38-訂閱單位經濟!$B$19)*36+訂閱單位經濟!$B$17*(假設!$B$43-1)-假設!$B$42 -> 162.36467 | D9: =($A9/(1+假設!$B$33)*(1-假設!$B$34-假設!$B$35)-假設!$B$36-假設!$B$37-假設!$B$38-訂閱單位經濟!$B$19)*48+訂閱單位經濟!$B$17*(假設!$B$43-1)-假設!$B$42 -> 242.79889 | E9: =($A9/(1+假設!$B$33)*(1-假設!$B$34-假設!$B$35)-假設!$B$36-假設!$B$37-假設!$B$38-訂閱單位經濟!$B$19)*60+訂閱單位經濟!$B$17*(假設!$B$43-1)-假設!$B$42 -> 323.2331 | H9: 壽命 = 電池訂閱持續月數
A10: 14.9 | B10: =($A10/(1+假設!$B$33)*(1-假設!$B$34-假設!$B$35)-假設!$B$36-假設!$B$37-假設!$B$38-訂閱單位經濟!$B$19)*24+訂閱單位經濟!$B$17*(假設!$B$43-1)-假設!$B$42 -> 119.24139 | C10: =($A10/(1+假設!$B$33)*(1-假設!$B$34-假設!$B$35)-假設!$B$36-假設!$B$37-假設!$B$38-訂閱單位經濟!$B$19)*36+訂閱單位經濟!$B$17*(假設!$B$43-1)-假設!$B$42 -> 218.33106 | D10: =($A10/(1+假設!$B$33)*(1-假設!$B$34-假設!$B$35)-假設!$B$36-假設!$B$37-假設!$B$38-訂閱單位經濟!$B$19)*48+訂閱單位經濟!$B$17*(假設!$B$43-1)-假設!$B$42 -> 317.42074 | E10: =($A10/(1+假設!$B$33)*(1-假設!$B$34-假設!$B$35)-假設!$B$36-假設!$B$37-假設!$B$38-訂閱單位經濟!$B$19)*60+訂閱單位經濟!$B$17*(假設!$B$43-1)-假設!$B$42 -> 416.51041 | H10: 壽命 = 電池訂閱持續月數
A12: B. 日本單戶淨值（¥）：月費 × 電池更換週期
A13: 月費（含稅） ＼ 更換週期（月） | B13: 30 月 | C13: 36 月 | D13: 48 月 | E13: 60 月 | H13: 說明
A14: 980 | B14: =($A14/(1+假設!$B$53)*(1-假設!$B$54-假設!$B$55)-假設!$B$56-假設!$B$57-假設!$B$58-訂閱單位經濟!$C$18/30)*假設!$B$61+訂閱單位經濟!$C$17*(假設!$B$63-1)-假設!$B$62 -> -10072.682 | C14: =($A14/(1+假設!$B$53)*(1-假設!$B$54-假設!$B$55)-假設!$B$56-假設!$B$57-假設!$B$58-訂閱單位經濟!$C$18/36)*假設!$B$61+訂閱單位經濟!$C$17*(假設!$B$63-1)-假設!$B$62 -> -7246.274 | D14: =($A14/(1+假設!$B$53)*(1-假設!$B$54-假設!$B$55)-假設!$B$56-假設!$B$57-假設!$B$58-訂閱單位經濟!$C$18/48)*假設!$B$61+訂閱單位經濟!$C$17*(假設!$B$63-1)-假設!$B$62 -> -3713.264 | E14: =($A14/(1+假設!$B$53)*(1-假設!$B$54-假設!$B$55)-假設!$B$56-假設!$B$57-假設!$B$58-訂閱單位經濟!$C$18/60)*假設!$B$61+訂閱單位經濟!$C$17*(假設!$B$63-1)-假設!$B$62 -> -1593.458 | H14: 日本 1:2 助力比耗電高，週期可能縮至 30–36 月
A15: 1280 | B15: =($A15/(1+假設!$B$53)*(1-假設!$B$54-假設!$B$55)-假設!$B$56-假設!$B$57-假設!$B$58-訂閱單位經濟!$C$18/30)*假設!$B$61+訂閱單位經濟!$C$17*(假設!$B$63-1)-假設!$B$62 -> -892.682 | C15: =($A15/(1+假設!$B$53)*(1-假設!$B$54-假設!$B$55)-假設!$B$56-假設!$B$57-假設!$B$58-訂閱單位經濟!$C$18/36)*假設!$B$61+訂閱單位經濟!$C$17*(假設!$B$63-1)-假設!$B$62 -> 1933.726 | D15: =($A15/(1+假設!$B$53)*(1-假設!$B$54-假設!$B$55)-假設!$B$56-假設!$B$57-假設!$B$58-訂閱單位經濟!$C$18/48)*假設!$B$61+訂閱單位經濟!$C$17*(假設!$B$63-1)-假設!$B$62 -> 5466.736 | E15: =($A15/(1+假設!$B$53)*(1-假設!$B$54-假設!$B$55)-假設!$B$56-假設!$B$57-假設!$B$58-訂閱單位經濟!$C$18/60)*假設!$B$61+訂閱單位經濟!$C$17*(假設!$B$63-1)-假設!$B$62 -> 7586.542 | H15: 日本 1:2 助力比耗電高，週期可能縮至 30–36 月
A16: 1680 | B16: =($A16/(1+假設!$B$53)*(1-假設!$B$54-假設!$B$55)-假設!$B$56-假設!$B$57-假設!$B$58-訂閱單位經濟!$C$18/30)*假設!$B$61+訂閱單位經濟!$C$17*(假設!$B$63-1)-假設!$B$62 -> 11347.318 | C16: =($A16/(1+假設!$B$53)*(1-假設!$B$54-假設!$B$55)-假設!$B$56-假設!$B$57-假設!$B$58-訂閱單位經濟!$C$18/36)*假設!$B$61+訂閱單位經濟!$C$17*(假設!$B$63-1)-假設!$B$62 -> 14173.726 | D16: =($A16/(1+假設!$B$53)*(1-假設!$B$54-假設!$B$55)-假設!$B$56-假設!$B$57-假設!$B$58-訂閱單位經濟!$C$18/48)*假設!$B$61+訂閱單位經濟!$C$17*(假設!$B$63-1)-假設!$B$62 -> 17706.736 | E16: =($A16/(1+假設!$B$53)*(1-假設!$B$54-假設!$B$55)-假設!$B$56-假設!$B$57-假設!$B$58-訂閱單位經濟!$C$18/60)*假設!$B$61+訂閱單位經濟!$C$17*(假設!$B$63-1)-假設!$B$62 -> 19826.542 | H16: 日本 1:2 助力比耗電高，週期可能縮至 30–36 月
A17: 1980 | B17: =($A17/(1+假設!$B$53)*(1-假設!$B$54-假設!$B$55)-假設!$B$56-假設!$B$57-假設!$B$58-訂閱單位經濟!$C$18/30)*假設!$B$61+訂閱單位經濟!$C$17*(假設!$B$63-1)-假設!$B$62 -> 20527.318 | C17: =($A17/(1+假設!$B$53)*(1-假設!$B$54-假設!$B$55)-假設!$B$56-假設!$B$57-假設!$B$58-訂閱單位經濟!$C$18/36)*假設!$B$61+訂閱單位經濟!$C$17*(假設!$B$63-1)-假設!$B$62 -> 23353.726 | D17: =($A17/(1+假設!$B$53)*(1-假設!$B$54-假設!$B$55)-假設!$B$56-假設!$B$57-假設!$B$58-訂閱單位經濟!$C$18/48)*假設!$B$61+訂閱單位經濟!$C$17*(假設!$B$63-1)-假設!$B$62 -> 26886.736 | E17: =($A17/(1+假設!$B$53)*(1-假設!$B$54-假設!$B$55)-假設!$B$56-假設!$B$57-假設!$B$58-訂閱單位經濟!$C$18/60)*假設!$B$61+訂閱單位經濟!$C$17*(假設!$B$63-1)-假設!$B$62 -> 29006.542 | H17: 日本 1:2 助力比耗電高，週期可能縮至 30–36 月
A19: C. NT$6,000 出廠價隱含工廠毛利率：馬達單價 × 車架單價（100k 量級，不含電池）
A20: 馬達 US$ ＼ 車架 US$ | B20: $38 | C20: $42 | D20: $46 | E20: $50 | H20: 說明
A21: 36 | B21: =1-(BOM!$E$34+(($A21-BOM!$E$7)+(38-BOM!$E$21))*(1+假設!$B$25))*假設!$B$6/假設!$B$18 -> 0.15869444 | C21: =1-(BOM!$E$34+(($A21-BOM!$E$7)+(42-BOM!$E$21))*(1+假設!$B$25))*假設!$B$6/假設!$B$18 -> 0.13771778 | D21: =1-(BOM!$E$34+(($A21-BOM!$E$7)+(46-BOM!$E$21))*(1+假設!$B$25))*假設!$B$6/假設!$B$18 -> 0.11674111 | E21: =1-(BOM!$E$34+(($A21-BOM!$E$7)+(50-BOM!$E$21))*(1+假設!$B$25))*假設!$B$6/假設!$B$18 -> 0.095764444 | H21: 保固準備金按比例調整；負值 = 無法達標
A22: 42 | B22: =1-(BOM!$E$34+(($A22-BOM!$E$7)+(38-BOM!$E$21))*(1+假設!$B$25))*假設!$B$6/假設!$B$18 -> 0.12722944 | C22: =1-(BOM!$E$34+(($A22-BOM!$E$7)+(42-BOM!$E$21))*(1+假設!$B$25))*假設!$B$6/假設!$B$18 -> 0.10625278 | D22: =1-(BOM!$E$34+(($A22-BOM!$E$7)+(46-BOM!$E$21))*(1+假設!$B$25))*假設!$B$6/假設!$B$18 -> 0.085276111 | E22: =1-(BOM!$E$34+(($A22-BOM!$E$7)+(50-BOM!$E$21))*(1+假設!$B$25))*假設!$B$6/假設!$B$18 -> 0.064299444 | H22: 保固準備金按比例調整；負值 = 無法達標
A23: 47 | B23: =1-(BOM!$E$34+(($A23-BOM!$E$7)+(38-BOM!$E$21))*(1+假設!$B$25))*假設!$B$6/假設!$B$18 -> 0.10100861 | C23: =1-(BOM!$E$34+(($A23-BOM!$E$7)+(42-BOM!$E$21))*(1+假設!$B$25))*假設!$B$6/假設!$B$18 -> 0.080031944 | D23: =1-(BOM!$E$34+(($A23-BOM!$E$7)+(46-BOM!$E$21))*(1+假設!$B$25))*假設!$B$6/假設!$B$18 -> 0.059055278 | E23: =1-(BOM!$E$34+(($A23-BOM!$E$7)+(50-BOM!$E$21))*(1+假設!$B$25))*假設!$B$6/假設!$B$18 -> 0.038078611 | H23: 保固準備金按比例調整；負值 = 無法達標
A24: 55 | B24: =1-(BOM!$E$34+(($A24-BOM!$E$7)+(38-BOM!$E$21))*(1+假設!$B$25))*假設!$B$6/假設!$B$18 -> 0.059055278 | C24: =1-(BOM!$E$34+(($A24-BOM!$E$7)+(42-BOM!$E$21))*(1+假設!$B$25))*假設!$B$6/假設!$B$18 -> 0.038078611 | D24: =1-(BOM!$E$34+(($A24-BOM!$E$7)+(46-BOM!$E$21))*(1+假設!$B$25))*假設!$B$6/假設!$B$18 -> 0.017101944 | E24: =1-(BOM!$E$34+(($A24-BOM!$E$7)+(50-BOM!$E$21))*(1+假設!$B$25))*假設!$B$6/假設!$B$18 -> -0.0038747222 | H24: 保固準備金按比例調整；負值 = 無法達標
A26: D. 出廠價達標所需量級：不同量級下 NT$6,000 隱含毛利
A27: 量級 | B27: BOM 不含電池 US$ | C27: 隱含毛利率 | D27: 含電池 BOM US$ | E27: 含電池隱含毛利率 | H27: 說明
A28: 10k | B28: =BOM!C34 -> 216.46833 | C28: =BOM!C40 -> -0.11841972 | D28: =BOM!C35 -> 281.46833 | E28: =BOM!C41 -> -0.45425306 | H28: 10k 量級不可行；30k 起勉強；100k 才有 ODM 廠可接的毛利
A29: 30k | B29: =BOM!D34 -> 189.21944 | C29: =BOM!D40 -> 0.022366204 | D29: =BOM!D35 -> 246.71944 | E29: =BOM!D41 -> -0.27471713 | H29: 10k 量級不可行；30k 起勉強；100k 才有 ODM 廠可接的毛利
A30: 100k | B30: =BOM!E34 -> 172.98333 | C30: =BOM!E40 -> 0.10625278 | D30: =BOM!E35 -> 225.98333 | E30: =BOM!E41 -> -0.16758056 | H30: 10k 量級不可行；30k 起勉強；100k 才有 ODM 廠可接的毛利

Sheet 結論
A1: 結論與建議
A3: 核心判決
A4: NT$6,000 / RMB 1,300 的出廠價只有在「電池與充電器不計入出廠價、改為訂閱資產」且年量達 3–10 萬台時成立；電池隨車賣斷則任何量級都做不到。
A6: 1. 出廠價：不含電池 100k 量級 BOM ≈ US$172（NT$5,340），NT$6,000 隱含工廠毛利約 11%；30k 量級約 2%；10k 量級為負。含電池 BOM ≈ US$225，NT$6,000 之下毛利 −16%。
A7: 2. 訂閱制降低門檻的機制：車體以 DTC 約 €399 / ¥59,800 賣斷（比最低價合法 e-bike €699 / ¥89,980 低 33–43%），電池 + 充電器 + 失竊補償 + 到期換新以 €9.9 / ¥1,280 月費提供；營運商資產每戶僅 €55 級（TCO 模型三電全訂閱為 €204），回收期 12 個月級、單戶淨值轉正，前版 TCO「消費者上限 €15 vs 營運商下限 €25」的剪刀差消失。
A8: 3. 日本版：法規要求助力比以人力為分母，必須加扭力感測（+US$18–28）與日本規配件（+US$10–12），出廠價升至約 RMB 1,500（+15–20%），屬「適度」；電池規格（252→360Wh）在訂閱側調整，不影響出廠價。
A9: 4. 消費者側：歐洲 5 年 TCO 本案 €9.9/月約 €1,000 vs Action E200 買斷 €1,199；日本 3 年 TCO ¥1,280/月約 ¥106,000，與 NORUDE ¥104,040 相當但車體歸消費者，低於 POS 平均買斷 ¥130,663，但高於 PELTECH ¥89,980 買斷——日本的價值主張須靠「免電池前置費 + 到期換新 + 失竊補償」而非總價。
A11: 前提與風險
A12: • 馬達（US$42）、電池（US$46）、扭力感測（US$18）無供應商書面報價；三項合計佔不含電池 BOM 35%，為最不透明部分。
A13: • 歐洲：中國製整車 AD+CVD 最高約 85–93%，本模型以台灣／越南廠計；越南 EVFTA 優惠稅率與反規避風險待驗證。
A14: • 電池訂閱的逆物流須走經銷點／回收點（UN3480），不能一般包裹寄送；2027/2/18 起歐盟電池法可拆換與電池護照義務適用。
A15: • 踏頻感測 + 單速在坡地體驗有天花板；齒比建議 42/16（26 吋）或 40/16（700c），以起步為優先。
... A18: 本表為策略研究試算，非投資建議。
